{"user":"x_finder3","timestamp":"2024-04-25T11:10:33.902964","nav_name":"yuan_http","action":"事件处理出错","params":"错误跟踪：Traceback (most recent call last):\n  File \"xlink_core.pyx\", line 697, in xlink_core.Main4\n  File \"\/opt\/openfbi\/fbi-bin\/addones\/streams\/yuan_http.py\", line 422, in Events\n    \"account\": re_acc,\n               ^^^^^^\nUnboundLocalError: cannot access local variable 'user_info' where it is not associated with a value\n","operate_result":"错误","failed_reason":"cannot access local variable 'user_info' where it is not associated with a value"}
{"user":"x_finder3","timestamp":"2024-04-25T11:10:33.955098","nav_name":"yuan_http","action":"事件处理出错","params":"错误跟踪：Traceback (most recent call last):\n  File \"xlink_core.pyx\", line 697, in xlink_core.Main4\n  File \"\/opt\/openfbi\/fbi-bin\/addones\/streams\/yuan_http.py\", line 422, in Events\n    \"account\": re_acc,\n               ^^^^^^\nUnboundLocalError: cannot access local variable 'user_info' where it is not associated with a value\n","operate_result":"错误","failed_reason":"cannot access local variable 'user_info' where it is not associated with a value"}
{"user":"x_finder3","timestamp":"2024-04-25T11:10:37.330181","nav_name":"yuan_http","action":"事件处理出错","params":"错误跟踪：Traceback (most recent call last):\n  File \"xlink_core.pyx\", line 697, in xlink_core.Main4\n  File \"\/opt\/openfbi\/fbi-bin\/addones\/streams\/yuan_http.py\", line 422, in Events\n    \"account\": re_acc,\n               ^^^^^^\nUnboundLocalError: cannot access local variable 'user_info' where it is not associated with a value\n","operate_result":"错误","failed_reason":"cannot access local variable 'user_info' where it is not associated with a value"}
{"user":"x_finder3","timestamp":"2024-04-25T11:10:38.131675","nav_name":"yuan_http","action":"事件处理出错","params":"错误跟踪：Traceback (most recent call last):\n  File \"xlink_core.pyx\", line 697, in xlink_core.Main4\n  File \"\/opt\/openfbi\/fbi-bin\/addones\/streams\/yuan_http.py\", line 422, in Events\n    \"account\": re_acc,\n               ^^^^^^\nUnboundLocalError: cannot access local variable 'user_info' where it is not associated with a value\n","operate_result":"错误","failed_reason":"cannot access local variable 'user_info' where it is not associated with a value"}
{"user":"x_finder3","timestamp":"2024-04-25T11:10:38.132641","nav_name":"yuan_http","action":"事件处理出错","params":"错误跟踪：Traceback (most recent call last):\n  File \"xlink_core.pyx\", line 697, in xlink_core.Main4\n  File \"\/opt\/openfbi\/fbi-bin\/addones\/streams\/yuan_http.py\", line 422, in Events\n    \"account\": re_acc,\n               ^^^^^^\nUnboundLocalError: cannot access local variable 'user_info' where it is not associated with a value\n","operate_result":"错误","failed_reason":"cannot access local variable 'user_info' where it is not associated with a value"}
{"user":"x_finder3","timestamp":"2024-04-25T11:10:38.143710","nav_name":"yuan_http","action":"事件处理出错","params":"错误跟踪：Traceback (most recent call last):\n  File \"xlink_core.pyx\", line 697, in xlink_core.Main4\n  File \"\/opt\/openfbi\/fbi-bin\/addones\/streams\/yuan_http.py\", line 422, in Events\n    \"account\": re_acc,\n               ^^^^^^\nUnboundLocalError: cannot access local variable 'user_info' where it is not associated with a value\n","operate_result":"错误","failed_reason":"cannot access local variable 'user_info' where it is not associated with a value"}
{"user":"x_finder3","timestamp":"2024-04-25T11:10:40.809391","nav_name":"yuan_http","action":"事件处理出错","params":"错误跟踪：Traceback (most recent call last):\n  File \"xlink_core.pyx\", line 697, in xlink_core.Main4\n  File \"\/opt\/openfbi\/fbi-bin\/addones\/streams\/yuan_http.py\", line 422, in Events\n    \"account\": re_acc,\n               ^^^^^^\nUnboundLocalError: cannot access local variable 'user_info' where it is not associated with a value\n","operate_result":"错误","failed_reason":"cannot access local variable 'user_info' where it is not associated with a value"}
{"user":"x_finder3","timestamp":"2024-04-25T11:10:40.952719","nav_name":"yuan_http","action":"事件处理出错","params":"错误跟踪：Traceback (most recent call last):\n  File \"xlink_core.pyx\", line 697, in xlink_core.Main4\n  File \"\/opt\/openfbi\/fbi-bin\/addones\/streams\/yuan_http.py\", line 422, in Events\n    \"account\": re_acc,\n               ^^^^^^\nUnboundLocalError: cannot access local variable 'user_info' where it is not associated with a value\n","operate_result":"错误","failed_reason":"cannot access local variable 'user_info' where it is not associated with a value"}
{"user":"x_finder3","timestamp":"2024-04-25T11:10:41.369241","nav_name":"yuan_http","action":"事件处理出错","params":"错误跟踪：Traceback (most recent call last):\n  File \"xlink_core.pyx\", line 697, in xlink_core.Main4\n  File \"\/opt\/openfbi\/fbi-bin\/addones\/streams\/yuan_http.py\", line 422, in Events\n    \"account\": re_acc,\n               ^^^^^^\nUnboundLocalError: cannot access local variable 'user_info' where it is not associated with a value\n","operate_result":"错误","failed_reason":"cannot access local variable 'user_info' where it is not associated with a value"}
{"user":"x_finder3","timestamp":"2024-04-25T11:10:42.271942","nav_name":"yuan_http","action":"事件处理出错","params":"错误跟踪：Traceback (most recent call last):\n  File \"xlink_core.pyx\", line 697, in xlink_core.Main4\n  File \"\/opt\/openfbi\/fbi-bin\/addones\/streams\/yuan_http.py\", line 422, in Events\n    \"account\": re_acc,\n               ^^^^^^\nUnboundLocalError: cannot access local variable 'user_info' where it is not associated with a value\n","operate_result":"错误","failed_reason":"cannot access local variable 'user_info' where it is not associated with a value"}
{"user":"x_finder3","timestamp":"2024-04-25T11:10:42.364299","nav_name":"yuan_http","action":"事件处理出错","params":"错误跟踪：Traceback (most recent call last):\n  File \"xlink_core.pyx\", line 697, in xlink_core.Main4\n  File \"\/opt\/openfbi\/fbi-bin\/addones\/streams\/yuan_http.py\", line 422, in Events\n    \"account\": re_acc,\n               ^^^^^^\nUnboundLocalError: cannot access local variable 'user_info' where it is not associated with a value\n","operate_result":"错误","failed_reason":"cannot access local variable 'user_info' where it is not associated with a value"}
{"user":"x_finder3","timestamp":"2024-04-25T11:10:43.125087","nav_name":"yuan_http","action":"事件处理出错","params":"错误跟踪：Traceback (most recent call last):\n  File \"xlink_core.pyx\", line 697, in xlink_core.Main4\n  File \"\/opt\/openfbi\/fbi-bin\/addones\/streams\/yuan_http.py\", line 422, in Events\n    \"account\": re_acc,\n               ^^^^^^\nUnboundLocalError: cannot access local variable 'user_info' where it is not associated with a value\n","operate_result":"错误","failed_reason":"cannot access local variable 'user_info' where it is not associated with a value"}
{"user":"x_finder3","timestamp":"2024-04-25T11:10:43.126104","nav_name":"yuan_http","action":"事件处理出错","params":"错误跟踪：Traceback (most recent call last):\n  File \"xlink_core.pyx\", line 697, in xlink_core.Main4\n  File \"\/opt\/openfbi\/fbi-bin\/addones\/streams\/yuan_http.py\", line 422, in Events\n    \"account\": re_acc,\n               ^^^^^^\nUnboundLocalError: cannot access local variable 'user_info' where it is not associated with a value\n","operate_result":"错误","failed_reason":"cannot access local variable 'user_info' where it is not associated with a value"}
{"user":"x_finder3","timestamp":"2024-04-25T11:10:43.137114","nav_name":"yuan_http","action":"事件处理出错","params":"错误跟踪：Traceback (most recent call last):\n  File \"xlink_core.pyx\", line 697, in xlink_core.Main4\n  File \"\/opt\/openfbi\/fbi-bin\/addones\/streams\/yuan_http.py\", line 422, in Events\n    \"account\": re_acc,\n               ^^^^^^\nUnboundLocalError: cannot access local variable 'user_info' where it is not associated with a value\n","operate_result":"错误","failed_reason":"cannot access local variable 'user_info' where it is not associated with a value"}
{"user":"x_finder3","timestamp":"2024-04-25T11:10:43.279962","nav_name":"yuan_http","action":"事件处理出错","params":"错误跟踪：Traceback (most recent call last):\n  File \"xlink_core.pyx\", line 697, in xlink_core.Main4\n  File \"\/opt\/openfbi\/fbi-bin\/addones\/streams\/yuan_http.py\", line 422, in Events\n    \"account\": re_acc,\n               ^^^^^^\nUnboundLocalError: cannot access local variable 'user_info' where it is not associated with a value\n","operate_result":"错误","failed_reason":"cannot access local variable 'user_info' where it is not associated with a value"}
{"user":"x_finder3","timestamp":"2024-04-25T11:10:43.280884","nav_name":"yuan_http","action":"事件处理出错","params":"错误跟踪：Traceback (most recent call last):\n  File \"xlink_core.pyx\", line 697, in xlink_core.Main4\n  File \"\/opt\/openfbi\/fbi-bin\/addones\/streams\/yuan_http.py\", line 422, in Events\n    \"account\": re_acc,\n               ^^^^^^\nUnboundLocalError: cannot access local variable 'user_info' where it is not associated with a value\n","operate_result":"错误","failed_reason":"cannot access local variable 'user_info' where it is not associated with a value"}
{"user":"x_finder3","timestamp":"2024-04-25T11:10:44.284447","nav_name":"yuan_http","action":"事件处理出错","params":"错误跟踪：Traceback (most recent call last):\n  File \"xlink_core.pyx\", line 697, in xlink_core.Main4\n  File \"\/opt\/openfbi\/fbi-bin\/addones\/streams\/yuan_http.py\", line 422, in Events\n    \"account\": re_acc,\n               ^^^^^^\nUnboundLocalError: cannot access local variable 'user_info' where it is not associated with a value\n","operate_result":"错误","failed_reason":"cannot access local variable 'user_info' where it is not associated with a value"}
{"user":"x_finder3","timestamp":"2024-04-25T11:10:45.257866","nav_name":"yuan_http","action":"事件处理出错","params":"错误跟踪：Traceback (most recent call last):\n  File \"xlink_core.pyx\", line 697, in xlink_core.Main4\n  File \"\/opt\/openfbi\/fbi-bin\/addones\/streams\/yuan_http.py\", line 422, in Events\n    \"account\": re_acc,\n               ^^^^^^\nUnboundLocalError: cannot access local variable 'user_info' where it is not associated with a value\n","operate_result":"错误","failed_reason":"cannot access local variable 'user_info' where it is not associated with a value"}
{"user":"x_finder3","timestamp":"2024-04-25T11:10:46.413896","nav_name":"yuan_http","action":"事件处理出错","params":"错误跟踪：Traceback (most recent call last):\n  File \"xlink_core.pyx\", line 697, in xlink_core.Main4\n  File \"\/opt\/openfbi\/fbi-bin\/addones\/streams\/yuan_http.py\", line 422, in Events\n    \"account\": re_acc,\n               ^^^^^^\nUnboundLocalError: cannot access local variable 'user_info' where it is not associated with a value\n","operate_result":"错误","failed_reason":"cannot access local variable 'user_info' where it is not associated with a value"}
{"user":"x_finder3","timestamp":"2024-04-25T11:10:47.215822","nav_name":"yuan_http","action":"事件处理出错","params":"错误跟踪：Traceback (most recent call last):\n  File \"xlink_core.pyx\", line 697, in xlink_core.Main4\n  File \"\/opt\/openfbi\/fbi-bin\/addones\/streams\/yuan_http.py\", line 422, in Events\n    \"account\": re_acc,\n               ^^^^^^\nUnboundLocalError: cannot access local variable 'user_info' where it is not associated with a value\n","operate_result":"错误","failed_reason":"cannot access local variable 'user_info' where it is not associated with a value"}
{"user":"x_finder3","timestamp":"2024-04-25T11:10:47.216942","nav_name":"yuan_http","action":"事件处理出错","params":"错误跟踪：Traceback (most recent call last):\n  File \"xlink_core.pyx\", line 697, in xlink_core.Main4\n  File \"\/opt\/openfbi\/fbi-bin\/addones\/streams\/yuan_http.py\", line 422, in Events\n    \"account\": re_acc,\n               ^^^^^^\nUnboundLocalError: cannot access local variable 'user_info' where it is not associated with a value\n","operate_result":"错误","failed_reason":"cannot access local variable 'user_info' where it is not associated with a value"}
{"user":"x_finder3","timestamp":"2024-04-25T11:10:47.268524","nav_name":"yuan_http","action":"事件处理出错","params":"错误跟踪：Traceback (most recent call last):\n  File \"xlink_core.pyx\", line 697, in xlink_core.Main4\n  File \"\/opt\/openfbi\/fbi-bin\/addones\/streams\/yuan_http.py\", line 422, in Events\n    \"account\": re_acc,\n               ^^^^^^\nUnboundLocalError: cannot access local variable 'user_info' where it is not associated with a value\n","operate_result":"错误","failed_reason":"cannot access local variable 'user_info' where it is not associated with a value"}
{"user":"x_finder3","timestamp":"2024-04-25T11:10:47.269457","nav_name":"yuan_http","action":"事件处理出错","params":"错误跟踪：Traceback (most recent call last):\n  File \"xlink_core.pyx\", line 697, in xlink_core.Main4\n  File \"\/opt\/openfbi\/fbi-bin\/addones\/streams\/yuan_http.py\", line 422, in Events\n    \"account\": re_acc,\n               ^^^^^^\nUnboundLocalError: cannot access local variable 'user_info' where it is not associated with a value\n","operate_result":"错误","failed_reason":"cannot access local variable 'user_info' where it is not associated with a value"}
{"user":"x_finder3","timestamp":"2024-04-25T11:10:47.270337","nav_name":"yuan_http","action":"事件处理出错","params":"错误跟踪：Traceback (most recent call last):\n  File \"xlink_core.pyx\", line 697, in xlink_core.Main4\n  File \"\/opt\/openfbi\/fbi-bin\/addones\/streams\/yuan_http.py\", line 422, in Events\n    \"account\": re_acc,\n               ^^^^^^\nUnboundLocalError: cannot access local variable 'user_info' where it is not associated with a value\n","operate_result":"错误","failed_reason":"cannot access local variable 'user_info' where it is not associated with a value"}
{"user":"x_finder3","timestamp":"2024-04-25T11:10:47.271257","nav_name":"yuan_http","action":"事件处理出错","params":"错误跟踪：Traceback (most recent call last):\n  File \"xlink_core.pyx\", line 697, in xlink_core.Main4\n  File \"\/opt\/openfbi\/fbi-bin\/addones\/streams\/yuan_http.py\", line 422, in Events\n    \"account\": re_acc,\n               ^^^^^^\nUnboundLocalError: cannot access local variable 'user_info' where it is not associated with a value\n","operate_result":"错误","failed_reason":"cannot access local variable 'user_info' where it is not associated with a value"}
{"user":"x_finder3","timestamp":"2024-04-25T11:10:47.424289","nav_name":"yuan_http","action":"事件处理出错","params":"错误跟踪：Traceback (most recent call last):\n  File \"xlink_core.pyx\", line 697, in xlink_core.Main4\n  File \"\/opt\/openfbi\/fbi-bin\/addones\/streams\/yuan_http.py\", line 422, in Events\n    \"account\": re_acc,\n               ^^^^^^\nUnboundLocalError: cannot access local variable 'user_info' where it is not associated with a value\n","operate_result":"错误","failed_reason":"cannot access local variable 'user_info' where it is not associated with a value"}
{"user":"x_finder3","timestamp":"2024-04-25T11:10:48.175202","nav_name":"yuan_http","action":"事件处理出错","params":"错误跟踪：Traceback (most recent call last):\n  File \"xlink_core.pyx\", line 697, in xlink_core.Main4\n  File \"\/opt\/openfbi\/fbi-bin\/addones\/streams\/yuan_http.py\", line 422, in Events\n    \"account\": re_acc,\n               ^^^^^^\nUnboundLocalError: cannot access local variable 'user_info' where it is not associated with a value\n","operate_result":"错误","failed_reason":"cannot access local variable 'user_info' where it is not associated with a value"}
{"user":"x_finder3","timestamp":"2024-04-25T11:10:48.176146","nav_name":"yuan_http","action":"事件处理出错","params":"错误跟踪：Traceback (most recent call last):\n  File \"xlink_core.pyx\", line 697, in xlink_core.Main4\n  File \"\/opt\/openfbi\/fbi-bin\/addones\/streams\/yuan_http.py\", line 422, in Events\n    \"account\": re_acc,\n               ^^^^^^\nUnboundLocalError: cannot access local variable 'user_info' where it is not associated with a value\n","operate_result":"错误","failed_reason":"cannot access local variable 'user_info' where it is not associated with a value"}
{"user":"x_finder3","timestamp":"2024-04-25T11:10:48.177169","nav_name":"yuan_http","action":"事件处理出错","params":"错误跟踪：Traceback (most recent call last):\n  File \"xlink_core.pyx\", line 697, in xlink_core.Main4\n  File \"\/opt\/openfbi\/fbi-bin\/addones\/streams\/yuan_http.py\", line 422, in Events\n    \"account\": re_acc,\n               ^^^^^^\nUnboundLocalError: cannot access local variable 'user_info' where it is not associated with a value\n","operate_result":"错误","failed_reason":"cannot access local variable 'user_info' where it is not associated with a value"}
{"user":"x_finder3","timestamp":"2024-04-25T11:10:48.229011","nav_name":"yuan_http","action":"事件处理出错","params":"错误跟踪：Traceback (most recent call last):\n  File \"xlink_core.pyx\", line 697, in xlink_core.Main4\n  File \"\/opt\/openfbi\/fbi-bin\/addones\/streams\/yuan_http.py\", line 422, in Events\n    \"account\": re_acc,\n               ^^^^^^\nUnboundLocalError: cannot access local variable 'user_info' where it is not associated with a value\n","operate_result":"错误","failed_reason":"cannot access local variable 'user_info' where it is not associated with a value"}
{"user":"x_finder3","timestamp":"2024-04-25T11:10:51.229078","nav_name":"yuan_http","action":"事件处理出错","params":"错误跟踪：Traceback (most recent call last):\n  File \"xlink_core.pyx\", line 697, in xlink_core.Main4\n  File \"\/opt\/openfbi\/fbi-bin\/addones\/streams\/yuan_http.py\", line 422, in Events\n    \"account\": re_acc,\n               ^^^^^^\nUnboundLocalError: cannot access local variable 'user_info' where it is not associated with a value\n","operate_result":"错误","failed_reason":"cannot access local variable 'user_info' where it is not associated with a value"}
{"user":"x_finder3","timestamp":"2024-04-25T11:10:51.382533","nav_name":"yuan_http","action":"事件处理出错","params":"错误跟踪：Traceback (most recent call last):\n  File \"xlink_core.pyx\", line 697, in xlink_core.Main4\n  File \"\/opt\/openfbi\/fbi-bin\/addones\/streams\/yuan_http.py\", line 422, in Events\n    \"account\": re_acc,\n               ^^^^^^\nUnboundLocalError: cannot access local variable 'user_info' where it is not associated with a value\n","operate_result":"错误","failed_reason":"cannot access local variable 'user_info' where it is not associated with a value"}
{"user":"x_finder3","timestamp":"2024-04-25T11:10:52.346490","nav_name":"yuan_http","action":"事件处理出错","params":"错误跟踪：Traceback (most recent call last):\n  File \"xlink_core.pyx\", line 697, in xlink_core.Main4\n  File \"\/opt\/openfbi\/fbi-bin\/addones\/streams\/yuan_http.py\", line 422, in Events\n    \"account\": re_acc,\n               ^^^^^^\nUnboundLocalError: cannot access local variable 'user_info' where it is not associated with a value\n","operate_result":"错误","failed_reason":"cannot access local variable 'user_info' where it is not associated with a value"}
{"user":"x_finder3","timestamp":"2024-04-25T11:10:53.137576","nav_name":"yuan_http","action":"事件处理出错","params":"错误跟踪：Traceback (most recent call last):\n  File \"xlink_core.pyx\", line 697, in xlink_core.Main4\n  File \"\/opt\/openfbi\/fbi-bin\/addones\/streams\/yuan_http.py\", line 422, in Events\n    \"account\": re_acc,\n               ^^^^^^\nUnboundLocalError: cannot access local variable 'user_info' where it is not associated with a value\n","operate_result":"错误","failed_reason":"cannot access local variable 'user_info' where it is not associated with a value"}
{"user":"x_finder3","timestamp":"2024-04-25T11:10:53.138555","nav_name":"yuan_http","action":"事件处理出错","params":"错误跟踪：Traceback (most recent call last):\n  File \"xlink_core.pyx\", line 697, in xlink_core.Main4\n  File \"\/opt\/openfbi\/fbi-bin\/addones\/streams\/yuan_http.py\", line 422, in Events\n    \"account\": re_acc,\n               ^^^^^^\nUnboundLocalError: cannot access local variable 'user_info' where it is not associated with a value\n","operate_result":"错误","failed_reason":"cannot access local variable 'user_info' where it is not associated with a value"}
{"user":"x_finder3","timestamp":"2024-04-25T11:10:53.139443","nav_name":"yuan_http","action":"事件处理出错","params":"错误跟踪：Traceback (most recent call last):\n  File \"xlink_core.pyx\", line 697, in xlink_core.Main4\n  File \"\/opt\/openfbi\/fbi-bin\/addones\/streams\/yuan_http.py\", line 422, in Events\n    \"account\": re_acc,\n               ^^^^^^\nUnboundLocalError: cannot access local variable 'user_info' where it is not associated with a value\n","operate_result":"错误","failed_reason":"cannot access local variable 'user_info' where it is not associated with a value"}
{"user":"x_finder3","timestamp":"2024-04-25T11:10:53.292379","nav_name":"yuan_http","action":"事件处理出错","params":"错误跟踪：Traceback (most recent call last):\n  File \"xlink_core.pyx\", line 697, in xlink_core.Main4\n  File \"\/opt\/openfbi\/fbi-bin\/addones\/streams\/yuan_http.py\", line 422, in Events\n    \"account\": re_acc,\n               ^^^^^^\nUnboundLocalError: cannot access local variable 'user_info' where it is not associated with a value\n","operate_result":"错误","failed_reason":"cannot access local variable 'user_info' where it is not associated with a value"}
{"user":"x_finder3","timestamp":"2024-04-25T11:10:53.293350","nav_name":"yuan_http","action":"事件处理出错","params":"错误跟踪：Traceback (most recent call last):\n  File \"xlink_core.pyx\", line 697, in xlink_core.Main4\n  File \"\/opt\/openfbi\/fbi-bin\/addones\/streams\/yuan_http.py\", line 422, in Events\n    \"account\": re_acc,\n               ^^^^^^\nUnboundLocalError: cannot access local variable 'user_info' where it is not associated with a value\n","operate_result":"错误","failed_reason":"cannot access local variable 'user_info' where it is not associated with a value"}
{"user":"x_finder3","timestamp":"2024-04-25T11:10:54.297531","nav_name":"yuan_http","action":"事件处理出错","params":"错误跟踪：Traceback (most recent call last):\n  File \"xlink_core.pyx\", line 697, in xlink_core.Main4\n  File \"\/opt\/openfbi\/fbi-bin\/addones\/streams\/yuan_http.py\", line 422, in Events\n    \"account\": re_acc,\n               ^^^^^^\nUnboundLocalError: cannot access local variable 'user_info' where it is not associated with a value\n","operate_result":"错误","failed_reason":"cannot access local variable 'user_info' where it is not associated with a value"}
{"user":"x_finder3","timestamp":"2024-04-25T11:10:56.324876","nav_name":"yuan_http","action":"事件处理出错","params":"错误跟踪：Traceback (most recent call last):\n  File \"xlink_core.pyx\", line 697, in xlink_core.Main4\n  File \"\/opt\/openfbi\/fbi-bin\/addones\/streams\/yuan_http.py\", line 422, in Events\n    \"account\": re_acc,\n               ^^^^^^\nUnboundLocalError: cannot access local variable 'user_info' where it is not associated with a value\n","operate_result":"错误","failed_reason":"cannot access local variable 'user_info' where it is not associated with a value"}
{"user":"x_finder3","timestamp":"2024-04-25T11:10:57.227730","nav_name":"yuan_http","action":"事件处理出错","params":"错误跟踪：Traceback (most recent call last):\n  File \"xlink_core.pyx\", line 697, in xlink_core.Main4\n  File \"\/opt\/openfbi\/fbi-bin\/addones\/streams\/yuan_http.py\", line 422, in Events\n    \"account\": re_acc,\n               ^^^^^^\nUnboundLocalError: cannot access local variable 'user_info' where it is not associated with a value\n","operate_result":"错误","failed_reason":"cannot access local variable 'user_info' where it is not associated with a value"}
{"user":"x_finder3","timestamp":"2024-04-25T11:10:57.380906","nav_name":"yuan_http","action":"事件处理出错","params":"错误跟踪：Traceback (most recent call last):\n  File \"xlink_core.pyx\", line 697, in xlink_core.Main4\n  File \"\/opt\/openfbi\/fbi-bin\/addones\/streams\/yuan_http.py\", line 422, in Events\n    \"account\": re_acc,\n               ^^^^^^\nUnboundLocalError: cannot access local variable 'user_info' where it is not associated with a value\n","operate_result":"错误","failed_reason":"cannot access local variable 'user_info' where it is not associated with a value"}
{"user":"x_finder3","timestamp":"2024-04-25T11:10:58.131721","nav_name":"yuan_http","action":"事件处理出错","params":"错误跟踪：Traceback (most recent call last):\n  File \"xlink_core.pyx\", line 697, in xlink_core.Main4\n  File \"\/opt\/openfbi\/fbi-bin\/addones\/streams\/yuan_http.py\", line 422, in Events\n    \"account\": re_acc,\n               ^^^^^^\nUnboundLocalError: cannot access local variable 'user_info' where it is not associated with a value\n","operate_result":"错误","failed_reason":"cannot access local variable 'user_info' where it is not associated with a value"}
{"user":"x_finder3","timestamp":"2024-04-25T11:10:58.142833","nav_name":"yuan_http","action":"事件处理出错","params":"错误跟踪：Traceback (most recent call last):\n  File \"xlink_core.pyx\", line 697, in xlink_core.Main4\n  File \"\/opt\/openfbi\/fbi-bin\/addones\/streams\/yuan_http.py\", line 422, in Events\n    \"account\": re_acc,\n               ^^^^^^\nUnboundLocalError: cannot access local variable 'user_info' where it is not associated with a value\n","operate_result":"错误","failed_reason":"cannot access local variable 'user_info' where it is not associated with a value"}
{"user":"x_finder3","timestamp":"2024-04-25T11:10:58.143778","nav_name":"yuan_http","action":"事件处理出错","params":"错误跟踪：Traceback (most recent call last):\n  File \"xlink_core.pyx\", line 697, in xlink_core.Main4\n  File \"\/opt\/openfbi\/fbi-bin\/addones\/streams\/yuan_http.py\", line 422, in Events\n    \"account\": re_acc,\n               ^^^^^^\nUnboundLocalError: cannot access local variable 'user_info' where it is not associated with a value\n","operate_result":"错误","failed_reason":"cannot access local variable 'user_info' where it is not associated with a value"}
{"user":"x_finder3","timestamp":"2024-04-25T11:11:00.276196","nav_name":"yuan_http","action":"事件处理出错","params":"错误跟踪：Traceback (most recent call last):\n  File \"xlink_core.pyx\", line 697, in xlink_core.Main4\n  File \"\/opt\/openfbi\/fbi-bin\/addones\/streams\/yuan_http.py\", line 422, in Events\n    \"account\": re_acc,\n               ^^^^^^\nUnboundLocalError: cannot access local variable 'user_info' where it is not associated with a value\n","operate_result":"错误","failed_reason":"cannot access local variable 'user_info' where it is not associated with a value"}
{"user":"x_finder3","timestamp":"2024-04-25T11:11:01.341611","nav_name":"yuan_http","action":"事件处理出错","params":"错误跟踪：Traceback (most recent call last):\n  File \"xlink_core.pyx\", line 697, in xlink_core.Main4\n  File \"\/opt\/openfbi\/fbi-bin\/addones\/streams\/yuan_http.py\", line 422, in Events\n    \"account\": re_acc,\n               ^^^^^^\nUnboundLocalError: cannot access local variable 'user_info' where it is not associated with a value\n","operate_result":"错误","failed_reason":"cannot access local variable 'user_info' where it is not associated with a value"}
{"user":"x_finder3","timestamp":"2024-04-25T11:11:03.105883","nav_name":"yuan_http","action":"事件处理出错","params":"错误跟踪：Traceback (most recent call last):\n  File \"xlink_core.pyx\", line 697, in xlink_core.Main4\n  File \"\/opt\/openfbi\/fbi-bin\/addones\/streams\/yuan_http.py\", line 422, in Events\n    \"account\": re_acc,\n               ^^^^^^\nUnboundLocalError: cannot access local variable 'user_info' where it is not associated with a value\n","operate_result":"错误","failed_reason":"cannot access local variable 'user_info' where it is not associated with a value"}
{"user":"x_finder3","timestamp":"2024-04-25T11:11:03.106877","nav_name":"yuan_http","action":"事件处理出错","params":"错误跟踪：Traceback (most recent call last):\n  File \"xlink_core.pyx\", line 697, in xlink_core.Main4\n  File \"\/opt\/openfbi\/fbi-bin\/addones\/streams\/yuan_http.py\", line 422, in Events\n    \"account\": re_acc,\n               ^^^^^^\nUnboundLocalError: cannot access local variable 'user_info' where it is not associated with a value\n","operate_result":"错误","failed_reason":"cannot access local variable 'user_info' where it is not associated with a value"}
{"user":"x_finder3","timestamp":"2024-04-25T11:11:03.107767","nav_name":"yuan_http","action":"事件处理出错","params":"错误跟踪：Traceback (most recent call last):\n  File \"xlink_core.pyx\", line 697, in xlink_core.Main4\n  File \"\/opt\/openfbi\/fbi-bin\/addones\/streams\/yuan_http.py\", line 422, in Events\n    \"account\": re_acc,\n               ^^^^^^\nUnboundLocalError: cannot access local variable 'user_info' where it is not associated with a value\n","operate_result":"错误","failed_reason":"cannot access local variable 'user_info' where it is not associated with a value"}
{"user":"x_finder3","timestamp":"2024-04-25T11:11:03.260762","nav_name":"yuan_http","action":"事件处理出错","params":"错误跟踪：Traceback (most recent call last):\n  File \"xlink_core.pyx\", line 697, in xlink_core.Main4\n  File \"\/opt\/openfbi\/fbi-bin\/addones\/streams\/yuan_http.py\", line 422, in Events\n    \"account\": re_acc,\n               ^^^^^^\nUnboundLocalError: cannot access local variable 'user_info' where it is not associated with a value\n","operate_result":"错误","failed_reason":"cannot access local variable 'user_info' where it is not associated with a value"}
{"user":"x_finder3","timestamp":"2024-04-25T11:11:06.281395","nav_name":"yuan_http","action":"事件处理出错","params":"错误跟踪：Traceback (most recent call last):\n  File \"xlink_core.pyx\", line 697, in xlink_core.Main4\n  File \"\/opt\/openfbi\/fbi-bin\/addones\/streams\/yuan_http.py\", line 422, in Events\n    \"account\": re_acc,\n               ^^^^^^\nUnboundLocalError: cannot access local variable 'user_info' where it is not associated with a value\n","operate_result":"错误","failed_reason":"cannot access local variable 'user_info' where it is not associated with a value"}
{"user":"x_finder3","timestamp":"2024-04-25T11:11:06.384026","nav_name":"yuan_http","action":"事件处理出错","params":"错误跟踪：Traceback (most recent call last):\n  File \"xlink_core.pyx\", line 697, in xlink_core.Main4\n  File \"\/opt\/openfbi\/fbi-bin\/addones\/streams\/yuan_http.py\", line 422, in Events\n    \"account\": re_acc,\n               ^^^^^^\nUnboundLocalError: cannot access local variable 'user_info' where it is not associated with a value\n","operate_result":"错误","failed_reason":"cannot access local variable 'user_info' where it is not associated with a value"}
{"user":"x_finder3","timestamp":"2024-04-25T11:11:08.198756","nav_name":"yuan_http","action":"事件处理出错","params":"错误跟踪：Traceback (most recent call last):\n  File \"xlink_core.pyx\", line 697, in xlink_core.Main4\n  File \"\/opt\/openfbi\/fbi-bin\/addones\/streams\/yuan_http.py\", line 422, in Events\n    \"account\": re_acc,\n               ^^^^^^\nUnboundLocalError: cannot access local variable 'user_info' where it is not associated with a value\n","operate_result":"错误","failed_reason":"cannot access local variable 'user_info' where it is not associated with a value"}
{"user":"x_finder3","timestamp":"2024-04-25T11:11:08.199734","nav_name":"yuan_http","action":"事件处理出错","params":"错误跟踪：Traceback (most recent call last):\n  File \"xlink_core.pyx\", line 697, in xlink_core.Main4\n  File \"\/opt\/openfbi\/fbi-bin\/addones\/streams\/yuan_http.py\", line 422, in Events\n    \"account\": re_acc,\n               ^^^^^^\nUnboundLocalError: cannot access local variable 'user_info' where it is not associated with a value\n","operate_result":"错误","failed_reason":"cannot access local variable 'user_info' where it is not associated with a value"}
{"user":"x_finder3","timestamp":"2024-04-25T11:11:08.200650","nav_name":"yuan_http","action":"事件处理出错","params":"错误跟踪：Traceback (most recent call last):\n  File \"xlink_core.pyx\", line 697, in xlink_core.Main4\n  File \"\/opt\/openfbi\/fbi-bin\/addones\/streams\/yuan_http.py\", line 422, in Events\n    \"account\": re_acc,\n               ^^^^^^\nUnboundLocalError: cannot access local variable 'user_info' where it is not associated with a value\n","operate_result":"错误","failed_reason":"cannot access local variable 'user_info' where it is not associated with a value"}
{"user":"x_finder3","timestamp":"2024-04-25T11:11:09.306066","nav_name":"yuan_http","action":"事件处理出错","params":"错误跟踪：Traceback (most recent call last):\n  File \"xlink_core.pyx\", line 697, in xlink_core.Main4\n  File \"\/opt\/openfbi\/fbi-bin\/addones\/streams\/yuan_http.py\", line 422, in Events\n    \"account\": re_acc,\n               ^^^^^^\nUnboundLocalError: cannot access local variable 'user_info' where it is not associated with a value\n","operate_result":"错误","failed_reason":"cannot access local variable 'user_info' where it is not associated with a value"}
{"user":"x_finder3","timestamp":"2024-04-25T11:11:11.324008","nav_name":"yuan_http","action":"事件处理出错","params":"错误跟踪：Traceback (most recent call last):\n  File \"xlink_core.pyx\", line 697, in xlink_core.Main4\n  File \"\/opt\/openfbi\/fbi-bin\/addones\/streams\/yuan_http.py\", line 422, in Events\n    \"account\": re_acc,\n               ^^^^^^\nUnboundLocalError: cannot access local variable 'user_info' where it is not associated with a value\n","operate_result":"错误","failed_reason":"cannot access local variable 'user_info' where it is not associated with a value"}
{"user":"x_finder3","timestamp":"2024-04-25T11:11:12.226939","nav_name":"yuan_http","action":"事件处理出错","params":"错误跟踪：Traceback (most recent call last):\n  File \"xlink_core.pyx\", line 697, in xlink_core.Main4\n  File \"\/opt\/openfbi\/fbi-bin\/addones\/streams\/yuan_http.py\", line 422, in Events\n    \"account\": re_acc,\n               ^^^^^^\nUnboundLocalError: cannot access local variable 'user_info' where it is not associated with a value\n","operate_result":"错误","failed_reason":"cannot access local variable 'user_info' where it is not associated with a value"}
{"user":"x_finder3","timestamp":"2024-04-25T11:11:13.139749","nav_name":"yuan_http","action":"事件处理出错","params":"错误跟踪：Traceback (most recent call last):\n  File \"xlink_core.pyx\", line 697, in xlink_core.Main4\n  File \"\/opt\/openfbi\/fbi-bin\/addones\/streams\/yuan_http.py\", line 422, in Events\n    \"account\": re_acc,\n               ^^^^^^\nUnboundLocalError: cannot access local variable 'user_info' where it is not associated with a value\n","operate_result":"错误","failed_reason":"cannot access local variable 'user_info' where it is not associated with a value"}
{"user":"x_finder3","timestamp":"2024-04-25T11:11:13.140687","nav_name":"yuan_http","action":"事件处理出错","params":"错误跟踪：Traceback (most recent call last):\n  File \"xlink_core.pyx\", line 697, in xlink_core.Main4\n  File \"\/opt\/openfbi\/fbi-bin\/addones\/streams\/yuan_http.py\", line 422, in Events\n    \"account\": re_acc,\n               ^^^^^^\nUnboundLocalError: cannot access local variable 'user_info' where it is not associated with a value\n","operate_result":"错误","failed_reason":"cannot access local variable 'user_info' where it is not associated with a value"}
{"user":"x_finder3","timestamp":"2024-04-25T11:11:13.141707","nav_name":"yuan_http","action":"事件处理出错","params":"错误跟踪：Traceback (most recent call last):\n  File \"xlink_core.pyx\", line 697, in xlink_core.Main4\n  File \"\/opt\/openfbi\/fbi-bin\/addones\/streams\/yuan_http.py\", line 422, in Events\n    \"account\": re_acc,\n               ^^^^^^\nUnboundLocalError: cannot access local variable 'user_info' where it is not associated with a value\n","operate_result":"错误","failed_reason":"cannot access local variable 'user_info' where it is not associated with a value"}
{"user":"x_finder3","timestamp":"2024-04-25T11:11:15.311563","nav_name":"yuan_http","action":"事件处理出错","params":"错误跟踪：Traceback (most recent call last):\n  File \"xlink_core.pyx\", line 697, in xlink_core.Main4\n  File \"\/opt\/openfbi\/fbi-bin\/addones\/streams\/yuan_http.py\", line 422, in Events\n    \"account\": re_acc,\n               ^^^^^^\nUnboundLocalError: cannot access local variable 'user_info' where it is not associated with a value\n","operate_result":"错误","failed_reason":"cannot access local variable 'user_info' where it is not associated with a value"}
{"user":"x_finder3","timestamp":"2024-04-25T11:11:16.315924","nav_name":"yuan_http","action":"事件处理出错","params":"错误跟踪：Traceback (most recent call last):\n  File \"xlink_core.pyx\", line 697, in xlink_core.Main4\n  File \"\/opt\/openfbi\/fbi-bin\/addones\/streams\/yuan_http.py\", line 422, in Events\n    \"account\": re_acc,\n               ^^^^^^\nUnboundLocalError: cannot access local variable 'user_info' where it is not associated with a value\n","operate_result":"错误","failed_reason":"cannot access local variable 'user_info' where it is not associated with a value"}
{"user":"x_finder3","timestamp":"2024-04-25T11:11:18.180935","nav_name":"yuan_http","action":"事件处理出错","params":"错误跟踪：Traceback (most recent call last):\n  File \"xlink_core.pyx\", line 697, in xlink_core.Main4\n  File \"\/opt\/openfbi\/fbi-bin\/addones\/streams\/yuan_http.py\", line 422, in Events\n    \"account\": re_acc,\n               ^^^^^^\nUnboundLocalError: cannot access local variable 'user_info' where it is not associated with a value\n","operate_result":"错误","failed_reason":"cannot access local variable 'user_info' where it is not associated with a value"}
{"user":"x_finder3","timestamp":"2024-04-25T11:11:18.182040","nav_name":"yuan_http","action":"事件处理出错","params":"错误跟踪：Traceback (most recent call last):\n  File \"xlink_core.pyx\", line 697, in xlink_core.Main4\n  File \"\/opt\/openfbi\/fbi-bin\/addones\/streams\/yuan_http.py\", line 422, in Events\n    \"account\": re_acc,\n               ^^^^^^\nUnboundLocalError: cannot access local variable 'user_info' where it is not associated with a value\n","operate_result":"错误","failed_reason":"cannot access local variable 'user_info' where it is not associated with a value"}
{"user":"x_finder3","timestamp":"2024-04-25T11:11:18.183009","nav_name":"yuan_http","action":"事件处理出错","params":"错误跟踪：Traceback (most recent call last):\n  File \"xlink_core.pyx\", line 697, in xlink_core.Main4\n  File \"\/opt\/openfbi\/fbi-bin\/addones\/streams\/yuan_http.py\", line 422, in Events\n    \"account\": re_acc,\n               ^^^^^^\nUnboundLocalError: cannot access local variable 'user_info' where it is not associated with a value\n","operate_result":"错误","failed_reason":"cannot access local variable 'user_info' where it is not associated with a value"}
{"user":"x_finder3","timestamp":"2024-04-25T11:11:18.234681","nav_name":"yuan_http","action":"事件处理出错","params":"错误跟踪：Traceback (most recent call last):\n  File \"xlink_core.pyx\", line 697, in xlink_core.Main4\n  File \"\/opt\/openfbi\/fbi-bin\/addones\/streams\/yuan_http.py\", line 422, in Events\n    \"account\": re_acc,\n               ^^^^^^\nUnboundLocalError: cannot access local variable 'user_info' where it is not associated with a value\n","operate_result":"错误","failed_reason":"cannot access local variable 'user_info' where it is not associated with a value"}
{"user":"x_finder3","timestamp":"2024-04-25T11:11:19.096924","nav_name":"yuan_http","action":"事件处理出错","params":"错误跟踪：Traceback (most recent call last):\n  File \"xlink_core.pyx\", line 697, in xlink_core.Main4\n  File \"\/opt\/openfbi\/fbi-bin\/addones\/streams\/yuan_http.py\", line 422, in Events\n    \"account\": re_acc,\n               ^^^^^^\nUnboundLocalError: cannot access local variable 'user_info' where it is not associated with a value\n","operate_result":"错误","failed_reason":"cannot access local variable 'user_info' where it is not associated with a value"}
{"user":"x_finder3","timestamp":"2024-04-25T11:11:19.098035","nav_name":"yuan_http","action":"事件处理出错","params":"错误跟踪：Traceback (most recent call last):\n  File \"xlink_core.pyx\", line 697, in xlink_core.Main4\n  File \"\/opt\/openfbi\/fbi-bin\/addones\/streams\/yuan_http.py\", line 422, in Events\n    \"account\": re_acc,\n               ^^^^^^\nUnboundLocalError: cannot access local variable 'user_info' where it is not associated with a value\n","operate_result":"错误","failed_reason":"cannot access local variable 'user_info' where it is not associated with a value"}
{"user":"x_finder3","timestamp":"2024-04-25T11:11:19.139581","nav_name":"yuan_http","action":"事件处理出错","params":"错误跟踪：Traceback (most recent call last):\n  File \"xlink_core.pyx\", line 697, in xlink_core.Main4\n  File \"\/opt\/openfbi\/fbi-bin\/addones\/streams\/yuan_http.py\", line 422, in Events\n    \"account\": re_acc,\n               ^^^^^^\nUnboundLocalError: cannot access local variable 'user_info' where it is not associated with a value\n","operate_result":"错误","failed_reason":"cannot access local variable 'user_info' where it is not associated with a value"}
{"user":"x_finder3","timestamp":"2024-04-25T11:11:19.191421","nav_name":"yuan_http","action":"事件处理出错","params":"错误跟踪：Traceback (most recent call last):\n  File \"xlink_core.pyx\", line 697, in xlink_core.Main4\n  File \"\/opt\/openfbi\/fbi-bin\/addones\/streams\/yuan_http.py\", line 422, in Events\n    \"account\": re_acc,\n               ^^^^^^\nUnboundLocalError: cannot access local variable 'user_info' where it is not associated with a value\n","operate_result":"错误","failed_reason":"cannot access local variable 'user_info' where it is not associated with a value"}
{"user":"x_finder3","timestamp":"2024-04-25T11:11:21.268524","nav_name":"yuan_http","action":"事件处理出错","params":"错误跟踪：Traceback (most recent call last):\n  File \"xlink_core.pyx\", line 697, in xlink_core.Main4\n  File \"\/opt\/openfbi\/fbi-bin\/addones\/streams\/yuan_http.py\", line 422, in Events\n    \"account\": re_acc,\n               ^^^^^^\nUnboundLocalError: cannot access local variable 'user_info' where it is not associated with a value\n","operate_result":"错误","failed_reason":"cannot access local variable 'user_info' where it is not associated with a value"}
{"user":"x_finder3","timestamp":"2024-04-25T11:11:21.421730","nav_name":"yuan_http","action":"事件处理出错","params":"错误跟踪：Traceback (most recent call last):\n  File \"xlink_core.pyx\", line 697, in xlink_core.Main4\n  File \"\/opt\/openfbi\/fbi-bin\/addones\/streams\/yuan_http.py\", line 422, in Events\n    \"account\": re_acc,\n               ^^^^^^\nUnboundLocalError: cannot access local variable 'user_info' where it is not associated with a value\n","operate_result":"错误","failed_reason":"cannot access local variable 'user_info' where it is not associated with a value"}
{"user":"x_finder3","timestamp":"2024-04-25T11:11:21.666030","nav_name":"yuan_http","action":"事件处理出错","params":"错误跟踪：Traceback (most recent call last):\n  File \"xlink_core.pyx\", line 697, in xlink_core.Main4\n  File \"\/opt\/openfbi\/fbi-bin\/addones\/streams\/yuan_http.py\", line 422, in Events\n    \"account\": re_acc,\n               ^^^^^^\nUnboundLocalError: cannot access local variable 'user_info' where it is not associated with a value\n","operate_result":"错误","failed_reason":"cannot access local variable 'user_info' where it is not associated with a value"}
{"user":"x_finder3","timestamp":"2024-04-25T11:11:21.667037","nav_name":"yuan_http","action":"事件处理出错","params":"错误跟踪：Traceback (most recent call last):\n  File \"xlink_core.pyx\", line 697, in xlink_core.Main4\n  File \"\/opt\/openfbi\/fbi-bin\/addones\/streams\/yuan_http.py\", line 422, in Events\n    \"account\": re_acc,\n               ^^^^^^\nUnboundLocalError: cannot access local variable 'user_info' where it is not associated with a value\n","operate_result":"错误","failed_reason":"cannot access local variable 'user_info' where it is not associated with a value"}
{"user":"x_finder3","timestamp":"2024-04-25T11:11:23.177744","nav_name":"yuan_http","action":"事件处理出错","params":"错误跟踪：Traceback (most recent call last):\n  File \"xlink_core.pyx\", line 697, in xlink_core.Main4\n  File \"\/opt\/openfbi\/fbi-bin\/addones\/streams\/yuan_http.py\", line 422, in Events\n    \"account\": re_acc,\n               ^^^^^^\nUnboundLocalError: cannot access local variable 'user_info' where it is not associated with a value\n","operate_result":"错误","failed_reason":"cannot access local variable 'user_info' where it is not associated with a value"}
{"user":"x_finder3","timestamp":"2024-04-25T11:11:23.178717","nav_name":"yuan_http","action":"事件处理出错","params":"错误跟踪：Traceback (most recent call last):\n  File \"xlink_core.pyx\", line 697, in xlink_core.Main4\n  File \"\/opt\/openfbi\/fbi-bin\/addones\/streams\/yuan_http.py\", line 422, in Events\n    \"account\": re_acc,\n               ^^^^^^\nUnboundLocalError: cannot access local variable 'user_info' where it is not associated with a value\n","operate_result":"错误","failed_reason":"cannot access local variable 'user_info' where it is not associated with a value"}
{"user":"x_finder3","timestamp":"2024-04-25T11:11:23.179604","nav_name":"yuan_http","action":"事件处理出错","params":"错误跟踪：Traceback (most recent call last):\n  File \"xlink_core.pyx\", line 697, in xlink_core.Main4\n  File \"\/opt\/openfbi\/fbi-bin\/addones\/streams\/yuan_http.py\", line 422, in Events\n    \"account\": re_acc,\n               ^^^^^^\nUnboundLocalError: cannot access local variable 'user_info' where it is not associated with a value\n","operate_result":"错误","failed_reason":"cannot access local variable 'user_info' where it is not associated with a value"}
{"user":"x_finder3","timestamp":"2024-04-25T11:11:24.285523","nav_name":"yuan_http","action":"事件处理出错","params":"错误跟踪：Traceback (most recent call last):\n  File \"xlink_core.pyx\", line 697, in xlink_core.Main4\n  File \"\/opt\/openfbi\/fbi-bin\/addones\/streams\/yuan_http.py\", line 422, in Events\n    \"account\": re_acc,\n               ^^^^^^\nUnboundLocalError: cannot access local variable 'user_info' where it is not associated with a value\n","operate_result":"错误","failed_reason":"cannot access local variable 'user_info' where it is not associated with a value"}
{"user":"x_finder3","timestamp":"2024-04-25T11:11:25.097240","nav_name":"yuan_http","action":"事件处理出错","params":"错误跟踪：Traceback (most recent call last):\n  File \"xlink_core.pyx\", line 697, in xlink_core.Main4\n  File \"\/opt\/openfbi\/fbi-bin\/addones\/streams\/yuan_http.py\", line 422, in Events\n    \"account\": re_acc,\n               ^^^^^^\nUnboundLocalError: cannot access local variable 'user_info' where it is not associated with a value\n","operate_result":"错误","failed_reason":"cannot access local variable 'user_info' where it is not associated with a value"}
{"user":"x_finder3","timestamp":"2024-04-25T11:11:25.098259","nav_name":"yuan_http","action":"事件处理出错","params":"错误跟踪：Traceback (most recent call last):\n  File \"xlink_core.pyx\", line 697, in xlink_core.Main4\n  File \"\/opt\/openfbi\/fbi-bin\/addones\/streams\/yuan_http.py\", line 422, in Events\n    \"account\": re_acc,\n               ^^^^^^\nUnboundLocalError: cannot access local variable 'user_info' where it is not associated with a value\n","operate_result":"错误","failed_reason":"cannot access local variable 'user_info' where it is not associated with a value"}
{"user":"x_finder3","timestamp":"2024-04-25T11:11:26.406537","nav_name":"yuan_http","action":"事件处理出错","params":"错误跟踪：Traceback (most recent call last):\n  File \"xlink_core.pyx\", line 697, in xlink_core.Main4\n  File \"\/opt\/openfbi\/fbi-bin\/addones\/streams\/yuan_http.py\", line 422, in Events\n    \"account\": re_acc,\n               ^^^^^^\nUnboundLocalError: cannot access local variable 'user_info' where it is not associated with a value\n","operate_result":"错误","failed_reason":"cannot access local variable 'user_info' where it is not associated with a value"}
{"user":"x_finder3","timestamp":"2024-04-25T11:11:27.015730","nav_name":"yuan_http","action":"事件处理出错","params":"错误跟踪：Traceback (most recent call last):\n  File \"xlink_core.pyx\", line 697, in xlink_core.Main4\n  File \"\/opt\/openfbi\/fbi-bin\/addones\/streams\/yuan_http.py\", line 422, in Events\n    \"account\": re_acc,\n               ^^^^^^\nUnboundLocalError: cannot access local variable 'user_info' where it is not associated with a value\n","operate_result":"错误","failed_reason":"cannot access local variable 'user_info' where it is not associated with a value"}
{"user":"x_finder3","timestamp":"2024-04-25T11:11:27.016765","nav_name":"yuan_http","action":"事件处理出错","params":"错误跟踪：Traceback (most recent call last):\n  File \"xlink_core.pyx\", line 697, in xlink_core.Main4\n  File \"\/opt\/openfbi\/fbi-bin\/addones\/streams\/yuan_http.py\", line 422, in Events\n    \"account\": re_acc,\n               ^^^^^^\nUnboundLocalError: cannot access local variable 'user_info' where it is not associated with a value\n","operate_result":"错误","failed_reason":"cannot access local variable 'user_info' where it is not associated with a value"}
{"user":"x_finder3","timestamp":"2024-04-25T11:11:27.220480","nav_name":"yuan_http","action":"事件处理出错","params":"错误跟踪：Traceback (most recent call last):\n  File \"xlink_core.pyx\", line 697, in xlink_core.Main4\n  File \"\/opt\/openfbi\/fbi-bin\/addones\/streams\/yuan_http.py\", line 422, in Events\n    \"account\": re_acc,\n               ^^^^^^\nUnboundLocalError: cannot access local variable 'user_info' where it is not associated with a value\n","operate_result":"错误","failed_reason":"cannot access local variable 'user_info' where it is not associated with a value"}
{"user":"x_finder3","timestamp":"2024-04-25T11:11:28.123344","nav_name":"yuan_http","action":"事件处理出错","params":"错误跟踪：Traceback (most recent call last):\n  File \"xlink_core.pyx\", line 697, in xlink_core.Main4\n  File \"\/opt\/openfbi\/fbi-bin\/addones\/streams\/yuan_http.py\", line 422, in Events\n    \"account\": re_acc,\n               ^^^^^^\nUnboundLocalError: cannot access local variable 'user_info' where it is not associated with a value\n","operate_result":"错误","failed_reason":"cannot access local variable 'user_info' where it is not associated with a value"}
{"user":"x_finder3","timestamp":"2024-04-25T11:11:28.124486","nav_name":"yuan_http","action":"事件处理出错","params":"错误跟踪：Traceback (most recent call last):\n  File \"xlink_core.pyx\", line 697, in xlink_core.Main4\n  File \"\/opt\/openfbi\/fbi-bin\/addones\/streams\/yuan_http.py\", line 422, in Events\n    \"account\": re_acc,\n               ^^^^^^\nUnboundLocalError: cannot access local variable 'user_info' where it is not associated with a value\n","operate_result":"错误","failed_reason":"cannot access local variable 'user_info' where it is not associated with a value"}
{"user":"x_finder3","timestamp":"2024-04-25T11:11:28.125394","nav_name":"yuan_http","action":"事件处理出错","params":"错误跟踪：Traceback (most recent call last):\n  File \"xlink_core.pyx\", line 697, in xlink_core.Main4\n  File \"\/opt\/openfbi\/fbi-bin\/addones\/streams\/yuan_http.py\", line 422, in Events\n    \"account\": re_acc,\n               ^^^^^^\nUnboundLocalError: cannot access local variable 'user_info' where it is not associated with a value\n","operate_result":"错误","failed_reason":"cannot access local variable 'user_info' where it is not associated with a value"}
{"user":"x_finder3","timestamp":"2024-04-25T11:11:30.240743","nav_name":"yuan_http","action":"事件处理出错","params":"错误跟踪：Traceback (most recent call last):\n  File \"xlink_core.pyx\", line 697, in xlink_core.Main4\n  File \"\/opt\/openfbi\/fbi-bin\/addones\/streams\/yuan_http.py\", line 422, in Events\n    \"account\": re_acc,\n               ^^^^^^\nUnboundLocalError: cannot access local variable 'user_info' where it is not associated with a value\n","operate_result":"错误","failed_reason":"cannot access local variable 'user_info' where it is not associated with a value"}
{"user":"x_finder3","timestamp":"2024-04-25T11:11:30.444511","nav_name":"yuan_http","action":"事件处理出错","params":"错误跟踪：Traceback (most recent call last):\n  File \"xlink_core.pyx\", line 697, in xlink_core.Main4\n  File \"\/opt\/openfbi\/fbi-bin\/addones\/streams\/yuan_http.py\", line 422, in Events\n    \"account\": re_acc,\n               ^^^^^^\nUnboundLocalError: cannot access local variable 'user_info' where it is not associated with a value\n","operate_result":"错误","failed_reason":"cannot access local variable 'user_info' where it is not associated with a value"}
{"user":"x_finder3","timestamp":"2024-04-25T11:11:30.445530","nav_name":"yuan_http","action":"事件处理出错","params":"错误跟踪：Traceback (most recent call last):\n  File \"xlink_core.pyx\", line 697, in xlink_core.Main4\n  File \"\/opt\/openfbi\/fbi-bin\/addones\/streams\/yuan_http.py\", line 422, in Events\n    \"account\": re_acc,\n               ^^^^^^\nUnboundLocalError: cannot access local variable 'user_info' where it is not associated with a value\n","operate_result":"错误","failed_reason":"cannot access local variable 'user_info' where it is not associated with a value"}
{"user":"x_finder3","timestamp":"2024-04-25T11:11:30.943316","nav_name":"yuan_http","action":"事件处理出错","params":"错误跟踪：Traceback (most recent call last):\n  File \"xlink_core.pyx\", line 697, in xlink_core.Main4\n  File \"\/opt\/openfbi\/fbi-bin\/addones\/streams\/yuan_http.py\", line 422, in Events\n    \"account\": re_acc,\n               ^^^^^^\nUnboundLocalError: cannot access local variable 'user_info' where it is not associated with a value\n","operate_result":"错误","failed_reason":"cannot access local variable 'user_info' where it is not associated with a value"}
{"user":"x_finder3","timestamp":"2024-04-25T11:11:30.954465","nav_name":"yuan_http","action":"事件处理出错","params":"错误跟踪：Traceback (most recent call last):\n  File \"xlink_core.pyx\", line 697, in xlink_core.Main4\n  File \"\/opt\/openfbi\/fbi-bin\/addones\/streams\/yuan_http.py\", line 422, in Events\n    \"account\": re_acc,\n               ^^^^^^\nUnboundLocalError: cannot access local variable 'user_info' where it is not associated with a value\n","operate_result":"错误","failed_reason":"cannot access local variable 'user_info' where it is not associated with a value"}
{"user":"x_finder3","timestamp":"2024-04-25T11:11:31.351408","nav_name":"yuan_http","action":"事件处理出错","params":"错误跟踪：Traceback (most recent call last):\n  File \"xlink_core.pyx\", line 697, in xlink_core.Main4\n  File \"\/opt\/openfbi\/fbi-bin\/addones\/streams\/yuan_http.py\", line 422, in Events\n    \"account\": re_acc,\n               ^^^^^^\nUnboundLocalError: cannot access local variable 'user_info' where it is not associated with a value\n","operate_result":"错误","failed_reason":"cannot access local variable 'user_info' where it is not associated with a value"}
{"user":"x_finder3","timestamp":"2024-04-25T11:11:33.166391","nav_name":"yuan_http","action":"事件处理出错","params":"错误跟踪：Traceback (most recent call last):\n  File \"xlink_core.pyx\", line 697, in xlink_core.Main4\n  File \"\/opt\/openfbi\/fbi-bin\/addones\/streams\/yuan_http.py\", line 422, in Events\n    \"account\": re_acc,\n               ^^^^^^\nUnboundLocalError: cannot access local variable 'user_info' where it is not associated with a value\n","operate_result":"错误","failed_reason":"cannot access local variable 'user_info' where it is not associated with a value"}
{"user":"x_finder3","timestamp":"2024-04-25T11:11:33.167458","nav_name":"yuan_http","action":"事件处理出错","params":"错误跟踪：Traceback (most recent call last):\n  File \"xlink_core.pyx\", line 697, in xlink_core.Main4\n  File \"\/opt\/openfbi\/fbi-bin\/addones\/streams\/yuan_http.py\", line 422, in Events\n    \"account\": re_acc,\n               ^^^^^^\nUnboundLocalError: cannot access local variable 'user_info' where it is not associated with a value\n","operate_result":"错误","failed_reason":"cannot access local variable 'user_info' where it is not associated with a value"}
{"user":"x_finder3","timestamp":"2024-04-25T11:11:33.178494","nav_name":"yuan_http","action":"事件处理出错","params":"错误跟踪：Traceback (most recent call last):\n  File \"xlink_core.pyx\", line 697, in xlink_core.Main4\n  File \"\/opt\/openfbi\/fbi-bin\/addones\/streams\/yuan_http.py\", line 422, in Events\n    \"account\": re_acc,\n               ^^^^^^\nUnboundLocalError: cannot access local variable 'user_info' where it is not associated with a value\n","operate_result":"错误","failed_reason":"cannot access local variable 'user_info' where it is not associated with a value"}
{"user":"x_finder3","timestamp":"2024-04-25T11:11:33.220050","nav_name":"yuan_http","action":"事件处理出错","params":"错误跟踪：Traceback (most recent call last):\n  File \"xlink_core.pyx\", line 697, in xlink_core.Main4\n  File \"\/opt\/openfbi\/fbi-bin\/addones\/streams\/yuan_http.py\", line 422, in Events\n    \"account\": re_acc,\n               ^^^^^^\nUnboundLocalError: cannot access local variable 'user_info' where it is not associated with a value\n","operate_result":"错误","failed_reason":"cannot access local variable 'user_info' where it is not associated with a value"}
{"user":"x_finder3","timestamp":"2024-04-25T11:11:36.240604","nav_name":"yuan_http","action":"事件处理出错","params":"错误跟踪：Traceback (most recent call last):\n  File \"xlink_core.pyx\", line 697, in xlink_core.Main4\n  File \"\/opt\/openfbi\/fbi-bin\/addones\/streams\/yuan_http.py\", line 422, in Events\n    \"account\": re_acc,\n               ^^^^^^\nUnboundLocalError: cannot access local variable 'user_info' where it is not associated with a value\n","operate_result":"错误","failed_reason":"cannot access local variable 'user_info' where it is not associated with a value"}
{"user":"x_finder3","timestamp":"2024-04-25T11:11:36.353245","nav_name":"yuan_http","action":"事件处理出错","params":"错误跟踪：Traceback (most recent call last):\n  File \"xlink_core.pyx\", line 697, in xlink_core.Main4\n  File \"\/opt\/openfbi\/fbi-bin\/addones\/streams\/yuan_http.py\", line 422, in Events\n    \"account\": re_acc,\n               ^^^^^^\nUnboundLocalError: cannot access local variable 'user_info' where it is not associated with a value\n","operate_result":"错误","failed_reason":"cannot access local variable 'user_info' where it is not associated with a value"}
{"user":"x_finder3","timestamp":"2024-04-25T11:11:38.157779","nav_name":"yuan_http","action":"事件处理出错","params":"错误跟踪：Traceback (most recent call last):\n  File \"xlink_core.pyx\", line 697, in xlink_core.Main4\n  File \"\/opt\/openfbi\/fbi-bin\/addones\/streams\/yuan_http.py\", line 422, in Events\n    \"account\": re_acc,\n               ^^^^^^\nUnboundLocalError: cannot access local variable 'user_info' where it is not associated with a value\n","operate_result":"错误","failed_reason":"cannot access local variable 'user_info' where it is not associated with a value"}
{"user":"x_finder3","timestamp":"2024-04-25T11:11:38.158752","nav_name":"yuan_http","action":"事件处理出错","params":"错误跟踪：Traceback (most recent call last):\n  File \"xlink_core.pyx\", line 697, in xlink_core.Main4\n  File \"\/opt\/openfbi\/fbi-bin\/addones\/streams\/yuan_http.py\", line 422, in Events\n    \"account\": re_acc,\n               ^^^^^^\nUnboundLocalError: cannot access local variable 'user_info' where it is not associated with a value\n","operate_result":"错误","failed_reason":"cannot access local variable 'user_info' where it is not associated with a value"}
{"user":"x_finder3","timestamp":"2024-04-25T11:11:38.169781","nav_name":"yuan_http","action":"事件处理出错","params":"错误跟踪：Traceback (most recent call last):\n  File \"xlink_core.pyx\", line 697, in xlink_core.Main4\n  File \"\/opt\/openfbi\/fbi-bin\/addones\/streams\/yuan_http.py\", line 422, in Events\n    \"account\": re_acc,\n               ^^^^^^\nUnboundLocalError: cannot access local variable 'user_info' where it is not associated with a value\n","operate_result":"错误","failed_reason":"cannot access local variable 'user_info' where it is not associated with a value"}
{"user":"x_finder3","timestamp":"2024-04-25T11:11:39.214264","nav_name":"yuan_http","action":"事件处理出错","params":"错误跟踪：Traceback (most recent call last):\n  File \"xlink_core.pyx\", line 697, in xlink_core.Main4\n  File \"\/opt\/openfbi\/fbi-bin\/addones\/streams\/yuan_http.py\", line 422, in Events\n    \"account\": re_acc,\n               ^^^^^^\nUnboundLocalError: cannot access local variable 'user_info' where it is not associated with a value\n","operate_result":"错误","failed_reason":"cannot access local variable 'user_info' where it is not associated with a value"}
{"user":"x_finder3","timestamp":"2024-04-25T11:11:40.329970","nav_name":"yuan_http","action":"事件处理出错","params":"错误跟踪：Traceback (most recent call last):\n  File \"xlink_core.pyx\", line 697, in xlink_core.Main4\n  File \"\/opt\/openfbi\/fbi-bin\/addones\/streams\/yuan_http.py\", line 422, in Events\n    \"account\": re_acc,\n               ^^^^^^\nUnboundLocalError: cannot access local variable 'user_info' where it is not associated with a value\n","operate_result":"错误","failed_reason":"cannot access local variable 'user_info' where it is not associated with a value"}
{"user":"x_finder3","timestamp":"2024-04-25T11:11:40.330995","nav_name":"yuan_http","action":"事件处理出错","params":"错误跟踪：Traceback (most recent call last):\n  File \"xlink_core.pyx\", line 697, in xlink_core.Main4\n  File \"\/opt\/openfbi\/fbi-bin\/addones\/streams\/yuan_http.py\", line 422, in Events\n    \"account\": re_acc,\n               ^^^^^^\nUnboundLocalError: cannot access local variable 'user_info' where it is not associated with a value\n","operate_result":"错误","failed_reason":"cannot access local variable 'user_info' where it is not associated with a value"}
{"user":"x_finder3","timestamp":"2024-04-25T11:11:41.345283","nav_name":"yuan_http","action":"事件处理出错","params":"错误跟踪：Traceback (most recent call last):\n  File \"xlink_core.pyx\", line 697, in xlink_core.Main4\n  File \"\/opt\/openfbi\/fbi-bin\/addones\/streams\/yuan_http.py\", line 422, in Events\n    \"account\": re_acc,\n               ^^^^^^\nUnboundLocalError: cannot access local variable 'user_info' where it is not associated with a value\n","operate_result":"错误","failed_reason":"cannot access local variable 'user_info' where it is not associated with a value"}
{"user":"x_finder3","timestamp":"2024-04-25T11:11:42.247984","nav_name":"yuan_http","action":"事件处理出错","params":"错误跟踪：Traceback (most recent call last):\n  File \"xlink_core.pyx\", line 697, in xlink_core.Main4\n  File \"\/opt\/openfbi\/fbi-bin\/addones\/streams\/yuan_http.py\", line 422, in Events\n    \"account\": re_acc,\n               ^^^^^^\nUnboundLocalError: cannot access local variable 'user_info' where it is not associated with a value\n","operate_result":"错误","failed_reason":"cannot access local variable 'user_info' where it is not associated with a value"}
{"user":"x_finder3","timestamp":"2024-04-25T11:11:43.201243","nav_name":"yuan_http","action":"事件处理出错","params":"错误跟踪：Traceback (most recent call last):\n  File \"xlink_core.pyx\", line 697, in xlink_core.Main4\n  File \"\/opt\/openfbi\/fbi-bin\/addones\/streams\/yuan_http.py\", line 422, in Events\n    \"account\": re_acc,\n               ^^^^^^\nUnboundLocalError: cannot access local variable 'user_info' where it is not associated with a value\n","operate_result":"错误","failed_reason":"cannot access local variable 'user_info' where it is not associated with a value"}
{"user":"x_finder3","timestamp":"2024-04-25T11:11:43.202298","nav_name":"yuan_http","action":"事件处理出错","params":"错误跟踪：Traceback (most recent call last):\n  File \"xlink_core.pyx\", line 697, in xlink_core.Main4\n  File \"\/opt\/openfbi\/fbi-bin\/addones\/streams\/yuan_http.py\", line 422, in Events\n    \"account\": re_acc,\n               ^^^^^^\nUnboundLocalError: cannot access local variable 'user_info' where it is not associated with a value\n","operate_result":"错误","failed_reason":"cannot access local variable 'user_info' where it is not associated with a value"}
{"user":"x_finder3","timestamp":"2024-04-25T11:11:43.213304","nav_name":"yuan_http","action":"事件处理出错","params":"错误跟踪：Traceback (most recent call last):\n  File \"xlink_core.pyx\", line 697, in xlink_core.Main4\n  File \"\/opt\/openfbi\/fbi-bin\/addones\/streams\/yuan_http.py\", line 422, in Events\n    \"account\": re_acc,\n               ^^^^^^\nUnboundLocalError: cannot access local variable 'user_info' where it is not associated with a value\n","operate_result":"错误","failed_reason":"cannot access local variable 'user_info' where it is not associated with a value"}
{"user":"x_finder3","timestamp":"2024-04-25T11:11:43.214264","nav_name":"yuan_http","action":"事件处理出错","params":"错误跟踪：Traceback (most recent call last):\n  File \"xlink_core.pyx\", line 697, in xlink_core.Main4\n  File \"\/opt\/openfbi\/fbi-bin\/addones\/streams\/yuan_http.py\", line 422, in Events\n    \"account\": re_acc,\n               ^^^^^^\nUnboundLocalError: cannot access local variable 'user_info' where it is not associated with a value\n","operate_result":"错误","failed_reason":"cannot access local variable 'user_info' where it is not associated with a value"}
{"user":"x_finder3","timestamp":"2024-04-25T11:11:43.215282","nav_name":"yuan_http","action":"事件处理出错","params":"错误跟踪：Traceback (most recent call last):\n  File \"xlink_core.pyx\", line 697, in xlink_core.Main4\n  File \"\/opt\/openfbi\/fbi-bin\/addones\/streams\/yuan_http.py\", line 422, in Events\n    \"account\": re_acc,\n               ^^^^^^\nUnboundLocalError: cannot access local variable 'user_info' where it is not associated with a value\n","operate_result":"错误","failed_reason":"cannot access local variable 'user_info' where it is not associated with a value"}
{"user":"x_finder3","timestamp":"2024-04-25T11:11:44.310635","nav_name":"yuan_http","action":"事件处理出错","params":"错误跟踪：Traceback (most recent call last):\n  File \"xlink_core.pyx\", line 697, in xlink_core.Main4\n  File \"\/opt\/openfbi\/fbi-bin\/addones\/streams\/yuan_http.py\", line 422, in Events\n    \"account\": re_acc,\n               ^^^^^^\nUnboundLocalError: cannot access local variable 'user_info' where it is not associated with a value\n","operate_result":"错误","failed_reason":"cannot access local variable 'user_info' where it is not associated with a value"}
{"user":"x_finder3","timestamp":"2024-04-25T11:11:45.223407","nav_name":"yuan_http","action":"事件处理出错","params":"错误跟踪：Traceback (most recent call last):\n  File \"xlink_core.pyx\", line 697, in xlink_core.Main4\n  File \"\/opt\/openfbi\/fbi-bin\/addones\/streams\/yuan_http.py\", line 422, in Events\n    \"account\": re_acc,\n               ^^^^^^\nUnboundLocalError: cannot access local variable 'user_info' where it is not associated with a value\n","operate_result":"错误","failed_reason":"cannot access local variable 'user_info' where it is not associated with a value"}
{"user":"x_finder3","timestamp":"2024-04-25T11:11:46.328865","nav_name":"yuan_http","action":"事件处理出错","params":"错误跟踪：Traceback (most recent call last):\n  File \"xlink_core.pyx\", line 697, in xlink_core.Main4\n  File \"\/opt\/openfbi\/fbi-bin\/addones\/streams\/yuan_http.py\", line 422, in Events\n    \"account\": re_acc,\n               ^^^^^^\nUnboundLocalError: cannot access local variable 'user_info' where it is not associated with a value\n","operate_result":"错误","failed_reason":"cannot access local variable 'user_info' where it is not associated with a value"}
{"user":"x_finder3","timestamp":"2024-04-25T11:11:47.241635","nav_name":"yuan_http","action":"事件处理出错","params":"错误跟踪：Traceback (most recent call last):\n  File \"xlink_core.pyx\", line 697, in xlink_core.Main4\n  File \"\/opt\/openfbi\/fbi-bin\/addones\/streams\/yuan_http.py\", line 422, in Events\n    \"account\": re_acc,\n               ^^^^^^\nUnboundLocalError: cannot access local variable 'user_info' where it is not associated with a value\n","operate_result":"错误","failed_reason":"cannot access local variable 'user_info' where it is not associated with a value"}
{"user":"x_finder3","timestamp":"2024-04-25T11:11:47.243196","nav_name":"yuan_http","action":"事件处理出错","params":"错误跟踪：Traceback (most recent call last):\n  File \"xlink_core.pyx\", line 697, in xlink_core.Main4\n  File \"\/opt\/openfbi\/fbi-bin\/addones\/streams\/yuan_http.py\", line 422, in Events\n    \"account\": re_acc,\n               ^^^^^^\nUnboundLocalError: cannot access local variable 'user_info' where it is not associated with a value\n","operate_result":"错误","failed_reason":"cannot access local variable 'user_info' where it is not associated with a value"}
{"user":"x_finder3","timestamp":"2024-04-25T11:11:47.244146","nav_name":"yuan_http","action":"事件处理出错","params":"错误跟踪：Traceback (most recent call last):\n  File \"xlink_core.pyx\", line 697, in xlink_core.Main4\n  File \"\/opt\/openfbi\/fbi-bin\/addones\/streams\/yuan_http.py\", line 422, in Events\n    \"account\": re_acc,\n               ^^^^^^\nUnboundLocalError: cannot access local variable 'user_info' where it is not associated with a value\n","operate_result":"错误","failed_reason":"cannot access local variable 'user_info' where it is not associated with a value"}
{"user":"x_finder3","timestamp":"2024-04-25T11:11:47.245067","nav_name":"yuan_http","action":"事件处理出错","params":"错误跟踪：Traceback (most recent call last):\n  File \"xlink_core.pyx\", line 697, in xlink_core.Main4\n  File \"\/opt\/openfbi\/fbi-bin\/addones\/streams\/yuan_http.py\", line 422, in Events\n    \"account\": re_acc,\n               ^^^^^^\nUnboundLocalError: cannot access local variable 'user_info' where it is not associated with a value\n","operate_result":"错误","failed_reason":"cannot access local variable 'user_info' where it is not associated with a value"}
{"user":"x_finder3","timestamp":"2024-04-25T11:11:47.245976","nav_name":"yuan_http","action":"事件处理出错","params":"错误跟踪：Traceback (most recent call last):\n  File \"xlink_core.pyx\", line 697, in xlink_core.Main4\n  File \"\/opt\/openfbi\/fbi-bin\/addones\/streams\/yuan_http.py\", line 422, in Events\n    \"account\": re_acc,\n               ^^^^^^\nUnboundLocalError: cannot access local variable 'user_info' where it is not associated with a value\n","operate_result":"错误","failed_reason":"cannot access local variable 'user_info' where it is not associated with a value"}
{"user":"x_finder3","timestamp":"2024-04-25T11:11:47.246860","nav_name":"yuan_http","action":"事件处理出错","params":"错误跟踪：Traceback (most recent call last):\n  File \"xlink_core.pyx\", line 697, in xlink_core.Main4\n  File \"\/opt\/openfbi\/fbi-bin\/addones\/streams\/yuan_http.py\", line 422, in Events\n    \"account\": re_acc,\n               ^^^^^^\nUnboundLocalError: cannot access local variable 'user_info' where it is not associated with a value\n","operate_result":"错误","failed_reason":"cannot access local variable 'user_info' where it is not associated with a value"}
{"user":"x_finder3","timestamp":"2024-04-25T11:11:47.247748","nav_name":"yuan_http","action":"事件处理出错","params":"错误跟踪：Traceback (most recent call last):\n  File \"xlink_core.pyx\", line 697, in xlink_core.Main4\n  File \"\/opt\/openfbi\/fbi-bin\/addones\/streams\/yuan_http.py\", line 422, in Events\n    \"account\": re_acc,\n               ^^^^^^\nUnboundLocalError: cannot access local variable 'user_info' where it is not associated with a value\n","operate_result":"错误","failed_reason":"cannot access local variable 'user_info' where it is not associated with a value"}
{"user":"x_finder3","timestamp":"2024-04-25T11:11:47.248767","nav_name":"yuan_http","action":"事件处理出错","params":"错误跟踪：Traceback (most recent call last):\n  File \"xlink_core.pyx\", line 697, in xlink_core.Main4\n  File \"\/opt\/openfbi\/fbi-bin\/addones\/streams\/yuan_http.py\", line 422, in Events\n    \"account\": re_acc,\n               ^^^^^^\nUnboundLocalError: cannot access local variable 'user_info' where it is not associated with a value\n","operate_result":"错误","failed_reason":"cannot access local variable 'user_info' where it is not associated with a value"}
{"user":"x_finder3","timestamp":"2024-04-25T11:11:47.249662","nav_name":"yuan_http","action":"事件处理出错","params":"错误跟踪：Traceback (most recent call last):\n  File \"xlink_core.pyx\", line 697, in xlink_core.Main4\n  File \"\/opt\/openfbi\/fbi-bin\/addones\/streams\/yuan_http.py\", line 422, in Events\n    \"account\": re_acc,\n               ^^^^^^\nUnboundLocalError: cannot access local variable 'user_info' where it is not associated with a value\n","operate_result":"错误","failed_reason":"cannot access local variable 'user_info' where it is not associated with a value"}
{"user":"x_finder3","timestamp":"2024-04-25T11:11:47.392731","nav_name":"yuan_http","action":"事件处理出错","params":"错误跟踪：Traceback (most recent call last):\n  File \"xlink_core.pyx\", line 697, in xlink_core.Main4\n  File \"\/opt\/openfbi\/fbi-bin\/addones\/streams\/yuan_http.py\", line 422, in Events\n    \"account\": re_acc,\n               ^^^^^^\nUnboundLocalError: cannot access local variable 'user_info' where it is not associated with a value\n","operate_result":"错误","failed_reason":"cannot access local variable 'user_info' where it is not associated with a value"}
{"user":"x_finder3","timestamp":"2024-04-25T11:11:48.193777","nav_name":"yuan_http","action":"事件处理出错","params":"错误跟踪：Traceback (most recent call last):\n  File \"xlink_core.pyx\", line 697, in xlink_core.Main4\n  File \"\/opt\/openfbi\/fbi-bin\/addones\/streams\/yuan_http.py\", line 422, in Events\n    \"account\": re_acc,\n               ^^^^^^\nUnboundLocalError: cannot access local variable 'user_info' where it is not associated with a value\n","operate_result":"错误","failed_reason":"cannot access local variable 'user_info' where it is not associated with a value"}
{"user":"x_finder3","timestamp":"2024-04-25T11:11:48.205010","nav_name":"yuan_http","action":"事件处理出错","params":"错误跟踪：Traceback (most recent call last):\n  File \"xlink_core.pyx\", line 697, in xlink_core.Main4\n  File \"\/opt\/openfbi\/fbi-bin\/addones\/streams\/yuan_http.py\", line 422, in Events\n    \"account\": re_acc,\n               ^^^^^^\nUnboundLocalError: cannot access local variable 'user_info' where it is not associated with a value\n","operate_result":"错误","failed_reason":"cannot access local variable 'user_info' where it is not associated with a value"}
{"user":"x_finder3","timestamp":"2024-04-25T11:11:48.205954","nav_name":"yuan_http","action":"事件处理出错","params":"错误跟踪：Traceback (most recent call last):\n  File \"xlink_core.pyx\", line 697, in xlink_core.Main4\n  File \"\/opt\/openfbi\/fbi-bin\/addones\/streams\/yuan_http.py\", line 422, in Events\n    \"account\": re_acc,\n               ^^^^^^\nUnboundLocalError: cannot access local variable 'user_info' where it is not associated with a value\n","operate_result":"错误","failed_reason":"cannot access local variable 'user_info' where it is not associated with a value"}
{"user":"x_finder3","timestamp":"2024-04-25T11:11:48.247574","nav_name":"yuan_http","action":"事件处理出错","params":"错误跟踪：Traceback (most recent call last):\n  File \"xlink_core.pyx\", line 697, in xlink_core.Main4\n  File \"\/opt\/openfbi\/fbi-bin\/addones\/streams\/yuan_http.py\", line 422, in Events\n    \"account\": re_acc,\n               ^^^^^^\nUnboundLocalError: cannot access local variable 'user_info' where it is not associated with a value\n","operate_result":"错误","failed_reason":"cannot access local variable 'user_info' where it is not associated with a value"}
{"user":"x_finder3","timestamp":"2024-04-25T11:11:51.218372","nav_name":"yuan_http","action":"事件处理出错","params":"错误跟踪：Traceback (most recent call last):\n  File \"xlink_core.pyx\", line 697, in xlink_core.Main4\n  File \"\/opt\/openfbi\/fbi-bin\/addones\/streams\/yuan_http.py\", line 422, in Events\n    \"account\": re_acc,\n               ^^^^^^\nUnboundLocalError: cannot access local variable 'user_info' where it is not associated with a value\n","operate_result":"错误","failed_reason":"cannot access local variable 'user_info' where it is not associated with a value"}
{"user":"x_finder3","timestamp":"2024-04-25T11:11:51.381704","nav_name":"yuan_http","action":"事件处理出错","params":"错误跟踪：Traceback (most recent call last):\n  File \"xlink_core.pyx\", line 697, in xlink_core.Main4\n  File \"\/opt\/openfbi\/fbi-bin\/addones\/streams\/yuan_http.py\", line 422, in Events\n    \"account\": re_acc,\n               ^^^^^^\nUnboundLocalError: cannot access local variable 'user_info' where it is not associated with a value\n","operate_result":"错误","failed_reason":"cannot access local variable 'user_info' where it is not associated with a value"}
{"user":"x_finder3","timestamp":"2024-04-25T11:11:53.185353","nav_name":"yuan_http","action":"事件处理出错","params":"错误跟踪：Traceback (most recent call last):\n  File \"xlink_core.pyx\", line 697, in xlink_core.Main4\n  File \"\/opt\/openfbi\/fbi-bin\/addones\/streams\/yuan_http.py\", line 422, in Events\n    \"account\": re_acc,\n               ^^^^^^\nUnboundLocalError: cannot access local variable 'user_info' where it is not associated with a value\n","operate_result":"错误","failed_reason":"cannot access local variable 'user_info' where it is not associated with a value"}
{"user":"x_finder3","timestamp":"2024-04-25T11:11:53.186424","nav_name":"yuan_http","action":"事件处理出错","params":"错误跟踪：Traceback (most recent call last):\n  File \"xlink_core.pyx\", line 697, in xlink_core.Main4\n  File \"\/opt\/openfbi\/fbi-bin\/addones\/streams\/yuan_http.py\", line 422, in Events\n    \"account\": re_acc,\n               ^^^^^^\nUnboundLocalError: cannot access local variable 'user_info' where it is not associated with a value\n","operate_result":"错误","failed_reason":"cannot access local variable 'user_info' where it is not associated with a value"}
{"user":"x_finder3","timestamp":"2024-04-25T11:11:53.197505","nav_name":"yuan_http","action":"事件处理出错","params":"错误跟踪：Traceback (most recent call last):\n  File \"xlink_core.pyx\", line 697, in xlink_core.Main4\n  File \"\/opt\/openfbi\/fbi-bin\/addones\/streams\/yuan_http.py\", line 422, in Events\n    \"account\": re_acc,\n               ^^^^^^\nUnboundLocalError: cannot access local variable 'user_info' where it is not associated with a value\n","operate_result":"错误","failed_reason":"cannot access local variable 'user_info' where it is not associated with a value"}
{"user":"x_finder3","timestamp":"2024-04-25T11:11:54.303295","nav_name":"yuan_http","action":"事件处理出错","params":"错误跟踪：Traceback (most recent call last):\n  File \"xlink_core.pyx\", line 697, in xlink_core.Main4\n  File \"\/opt\/openfbi\/fbi-bin\/addones\/streams\/yuan_http.py\", line 422, in Events\n    \"account\": re_acc,\n               ^^^^^^\nUnboundLocalError: cannot access local variable 'user_info' where it is not associated with a value\n","operate_result":"错误","failed_reason":"cannot access local variable 'user_info' where it is not associated with a value"}
{"user":"x_finder3","timestamp":"2024-04-25T11:11:56.371003","nav_name":"yuan_http","action":"事件处理出错","params":"错误跟踪：Traceback (most recent call last):\n  File \"xlink_core.pyx\", line 697, in xlink_core.Main4\n  File \"\/opt\/openfbi\/fbi-bin\/addones\/streams\/yuan_http.py\", line 422, in Events\n    \"account\": re_acc,\n               ^^^^^^\nUnboundLocalError: cannot access local variable 'user_info' where it is not associated with a value\n","operate_result":"错误","failed_reason":"cannot access local variable 'user_info' where it is not associated with a value"}
{"user":"x_finder3","timestamp":"2024-04-25T11:11:57.223108","nav_name":"yuan_http","action":"事件处理出错","params":"错误跟踪：Traceback (most recent call last):\n  File \"xlink_core.pyx\", line 697, in xlink_core.Main4\n  File \"\/opt\/openfbi\/fbi-bin\/addones\/streams\/yuan_http.py\", line 422, in Events\n    \"account\": re_acc,\n               ^^^^^^\nUnboundLocalError: cannot access local variable 'user_info' where it is not associated with a value\n","operate_result":"错误","failed_reason":"cannot access local variable 'user_info' where it is not associated with a value"}
{"user":"x_finder3","timestamp":"2024-04-25T11:11:58.136413","nav_name":"yuan_http","action":"事件处理出错","params":"错误跟踪：Traceback (most recent call last):\n  File \"xlink_core.pyx\", line 697, in xlink_core.Main4\n  File \"\/opt\/openfbi\/fbi-bin\/addones\/streams\/yuan_http.py\", line 422, in Events\n    \"account\": re_acc,\n               ^^^^^^\nUnboundLocalError: cannot access local variable 'user_info' where it is not associated with a value\n","operate_result":"错误","failed_reason":"cannot access local variable 'user_info' where it is not associated with a value"}
{"user":"x_finder3","timestamp":"2024-04-25T11:11:58.137490","nav_name":"yuan_http","action":"事件处理出错","params":"错误跟踪：Traceback (most recent call last):\n  File \"xlink_core.pyx\", line 697, in xlink_core.Main4\n  File \"\/opt\/openfbi\/fbi-bin\/addones\/streams\/yuan_http.py\", line 422, in Events\n    \"account\": re_acc,\n               ^^^^^^\nUnboundLocalError: cannot access local variable 'user_info' where it is not associated with a value\n","operate_result":"错误","failed_reason":"cannot access local variable 'user_info' where it is not associated with a value"}
{"user":"x_finder3","timestamp":"2024-04-25T11:11:58.138435","nav_name":"yuan_http","action":"事件处理出错","params":"错误跟踪：Traceback (most recent call last):\n  File \"xlink_core.pyx\", line 697, in xlink_core.Main4\n  File \"\/opt\/openfbi\/fbi-bin\/addones\/streams\/yuan_http.py\", line 422, in Events\n    \"account\": re_acc,\n               ^^^^^^\nUnboundLocalError: cannot access local variable 'user_info' where it is not associated with a value\n","operate_result":"错误","failed_reason":"cannot access local variable 'user_info' where it is not associated with a value"}
{"user":"x_finder3","timestamp":"2024-04-25T11:12:00.300310","nav_name":"yuan_http","action":"事件处理出错","params":"错误跟踪：Traceback (most recent call last):\n  File \"xlink_core.pyx\", line 697, in xlink_core.Main4\n  File \"\/opt\/openfbi\/fbi-bin\/addones\/streams\/yuan_http.py\", line 422, in Events\n    \"account\": re_acc,\n               ^^^^^^\nUnboundLocalError: cannot access local variable 'user_info' where it is not associated with a value\n","operate_result":"错误","failed_reason":"cannot access local variable 'user_info' where it is not associated with a value"}
{"user":"x_finder3","timestamp":"2024-04-25T11:12:01.338925","nav_name":"yuan_http","action":"事件处理出错","params":"错误跟踪：Traceback (most recent call last):\n  File \"xlink_core.pyx\", line 697, in xlink_core.Main4\n  File \"\/opt\/openfbi\/fbi-bin\/addones\/streams\/yuan_http.py\", line 422, in Events\n    \"account\": re_acc,\n               ^^^^^^\nUnboundLocalError: cannot access local variable 'user_info' where it is not associated with a value\n","operate_result":"错误","failed_reason":"cannot access local variable 'user_info' where it is not associated with a value"}
{"user":"x_finder3","timestamp":"2024-04-25T11:12:03.164468","nav_name":"yuan_http","action":"事件处理出错","params":"错误跟踪：Traceback (most recent call last):\n  File \"xlink_core.pyx\", line 697, in xlink_core.Main4\n  File \"\/opt\/openfbi\/fbi-bin\/addones\/streams\/yuan_http.py\", line 422, in Events\n    \"account\": re_acc,\n               ^^^^^^\nUnboundLocalError: cannot access local variable 'user_info' where it is not associated with a value\n","operate_result":"错误","failed_reason":"cannot access local variable 'user_info' where it is not associated with a value"}
{"user":"x_finder3","timestamp":"2024-04-25T11:12:03.165420","nav_name":"yuan_http","action":"事件处理出错","params":"错误跟踪：Traceback (most recent call last):\n  File \"xlink_core.pyx\", line 697, in xlink_core.Main4\n  File \"\/opt\/openfbi\/fbi-bin\/addones\/streams\/yuan_http.py\", line 422, in Events\n    \"account\": re_acc,\n               ^^^^^^\nUnboundLocalError: cannot access local variable 'user_info' where it is not associated with a value\n","operate_result":"错误","failed_reason":"cannot access local variable 'user_info' where it is not associated with a value"}
{"user":"x_finder3","timestamp":"2024-04-25T11:12:03.166337","nav_name":"yuan_http","action":"事件处理出错","params":"错误跟踪：Traceback (most recent call last):\n  File \"xlink_core.pyx\", line 697, in xlink_core.Main4\n  File \"\/opt\/openfbi\/fbi-bin\/addones\/streams\/yuan_http.py\", line 422, in Events\n    \"account\": re_acc,\n               ^^^^^^\nUnboundLocalError: cannot access local variable 'user_info' where it is not associated with a value\n","operate_result":"错误","failed_reason":"cannot access local variable 'user_info' where it is not associated with a value"}
{"user":"x_finder3","timestamp":"2024-04-25T11:12:08.101440","nav_name":"yuan_http","action":"事件处理出错","params":"错误跟踪：Traceback (most recent call last):\n  File \"xlink_core.pyx\", line 697, in xlink_core.Main4\n  File \"\/opt\/openfbi\/fbi-bin\/addones\/streams\/yuan_http.py\", line 422, in Events\n    \"account\": re_acc,\n               ^^^^^^\nUnboundLocalError: cannot access local variable 'user_info' where it is not associated with a value\n","operate_result":"错误","failed_reason":"cannot access local variable 'user_info' where it is not associated with a value"}
{"user":"x_finder3","timestamp":"2024-04-25T11:12:08.153118","nav_name":"yuan_http","action":"事件处理出错","params":"错误跟踪：Traceback (most recent call last):\n  File \"xlink_core.pyx\", line 697, in xlink_core.Main4\n  File \"\/opt\/openfbi\/fbi-bin\/addones\/streams\/yuan_http.py\", line 422, in Events\n    \"account\": re_acc,\n               ^^^^^^\nUnboundLocalError: cannot access local variable 'user_info' where it is not associated with a value\n","operate_result":"错误","failed_reason":"cannot access local variable 'user_info' where it is not associated with a value"}
{"user":"x_finder3","timestamp":"2024-04-25T11:12:08.154034","nav_name":"yuan_http","action":"事件处理出错","params":"错误跟踪：Traceback (most recent call last):\n  File \"xlink_core.pyx\", line 697, in xlink_core.Main4\n  File \"\/opt\/openfbi\/fbi-bin\/addones\/streams\/yuan_http.py\", line 422, in Events\n    \"account\": re_acc,\n               ^^^^^^\nUnboundLocalError: cannot access local variable 'user_info' where it is not associated with a value\n","operate_result":"错误","failed_reason":"cannot access local variable 'user_info' where it is not associated with a value"}
{"user":"x_finder3","timestamp":"2024-04-25T11:12:13.139373","nav_name":"yuan_http","action":"事件处理出错","params":"错误跟踪：Traceback (most recent call last):\n  File \"xlink_core.pyx\", line 697, in xlink_core.Main4\n  File \"\/opt\/openfbi\/fbi-bin\/addones\/streams\/yuan_http.py\", line 422, in Events\n    \"account\": re_acc,\n               ^^^^^^\nUnboundLocalError: cannot access local variable 'user_info' where it is not associated with a value\n","operate_result":"错误","failed_reason":"cannot access local variable 'user_info' where it is not associated with a value"}
{"user":"x_finder3","timestamp":"2024-04-25T11:12:13.150604","nav_name":"yuan_http","action":"事件处理出错","params":"错误跟踪：Traceback (most recent call last):\n  File \"xlink_core.pyx\", line 697, in xlink_core.Main4\n  File \"\/opt\/openfbi\/fbi-bin\/addones\/streams\/yuan_http.py\", line 422, in Events\n    \"account\": re_acc,\n               ^^^^^^\nUnboundLocalError: cannot access local variable 'user_info' where it is not associated with a value\n","operate_result":"错误","failed_reason":"cannot access local variable 'user_info' where it is not associated with a value"}
{"user":"x_finder3","timestamp":"2024-04-25T11:12:13.151543","nav_name":"yuan_http","action":"事件处理出错","params":"错误跟踪：Traceback (most recent call last):\n  File \"xlink_core.pyx\", line 697, in xlink_core.Main4\n  File \"\/opt\/openfbi\/fbi-bin\/addones\/streams\/yuan_http.py\", line 422, in Events\n    \"account\": re_acc,\n               ^^^^^^\nUnboundLocalError: cannot access local variable 'user_info' where it is not associated with a value\n","operate_result":"错误","failed_reason":"cannot access local variable 'user_info' where it is not associated with a value"}
{"user":"x_finder3","timestamp":"2024-04-25T11:12:14.115397","nav_name":"yuan_http","action":"事件处理出错","params":"错误跟踪：Traceback (most recent call last):\n  File \"xlink_core.pyx\", line 697, in xlink_core.Main4\n  File \"\/opt\/openfbi\/fbi-bin\/addones\/streams\/yuan_http.py\", line 422, in Events\n    \"account\": re_acc,\n               ^^^^^^\nUnboundLocalError: cannot access local variable 'user_info' where it is not associated with a value\n","operate_result":"错误","failed_reason":"cannot access local variable 'user_info' where it is not associated with a value"}
{"user":"x_finder3","timestamp":"2024-04-25T11:12:14.118276","nav_name":"yuan_http","action":"事件处理出错","params":"错误跟踪：Traceback (most recent call last):\n  File \"xlink_core.pyx\", line 697, in xlink_core.Main4\n  File \"\/opt\/openfbi\/fbi-bin\/addones\/streams\/yuan_http.py\", line 422, in Events\n    \"account\": re_acc,\n               ^^^^^^\nUnboundLocalError: cannot access local variable 'user_info' where it is not associated with a value\n","operate_result":"错误","failed_reason":"cannot access local variable 'user_info' where it is not associated with a value"}
{"user":"x_finder3","timestamp":"2024-04-25T11:12:14.121843","nav_name":"yuan_http","action":"事件处理出错","params":"错误跟踪：Traceback (most recent call last):\n  File \"xlink_core.pyx\", line 697, in xlink_core.Main4\n  File \"\/opt\/openfbi\/fbi-bin\/addones\/streams\/yuan_http.py\", line 422, in Events\n    \"account\": re_acc,\n               ^^^^^^\nUnboundLocalError: cannot access local variable 'user_info' where it is not associated with a value\n","operate_result":"错误","failed_reason":"cannot access local variable 'user_info' where it is not associated with a value"}
{"user":"x_finder3","timestamp":"2024-04-25T11:12:14.122807","nav_name":"yuan_http","action":"事件处理出错","params":"错误跟踪：Traceback (most recent call last):\n  File \"xlink_core.pyx\", line 697, in xlink_core.Main4\n  File \"\/opt\/openfbi\/fbi-bin\/addones\/streams\/yuan_http.py\", line 422, in Events\n    \"account\": re_acc,\n               ^^^^^^\nUnboundLocalError: cannot access local variable 'user_info' where it is not associated with a value\n","operate_result":"错误","failed_reason":"cannot access local variable 'user_info' where it is not associated with a value"}
{"user":"x_finder3","timestamp":"2024-04-25T11:12:14.124709","nav_name":"yuan_http","action":"事件处理出错","params":"错误跟踪：Traceback (most recent call last):\n  File \"xlink_core.pyx\", line 697, in xlink_core.Main4\n  File \"\/opt\/openfbi\/fbi-bin\/addones\/streams\/yuan_http.py\", line 422, in Events\n    \"account\": re_acc,\n               ^^^^^^\nUnboundLocalError: cannot access local variable 'user_info' where it is not associated with a value\n","operate_result":"错误","failed_reason":"cannot access local variable 'user_info' where it is not associated with a value"}
{"user":"x_finder3","timestamp":"2024-04-25T11:12:14.125576","nav_name":"yuan_http","action":"事件处理出错","params":"错误跟踪：Traceback (most recent call last):\n  File \"xlink_core.pyx\", line 697, in xlink_core.Main4\n  File \"\/opt\/openfbi\/fbi-bin\/addones\/streams\/yuan_http.py\", line 422, in Events\n    \"account\": re_acc,\n               ^^^^^^\nUnboundLocalError: cannot access local variable 'user_info' where it is not associated with a value\n","operate_result":"错误","failed_reason":"cannot access local variable 'user_info' where it is not associated with a value"}
{"user":"x_finder3","timestamp":"2024-04-25T11:12:14.128061","nav_name":"yuan_http","action":"事件处理出错","params":"错误跟踪：Traceback (most recent call last):\n  File \"xlink_core.pyx\", line 697, in xlink_core.Main4\n  File \"\/opt\/openfbi\/fbi-bin\/addones\/streams\/yuan_http.py\", line 422, in Events\n    \"account\": re_acc,\n               ^^^^^^\nUnboundLocalError: cannot access local variable 'user_info' where it is not associated with a value\n","operate_result":"错误","failed_reason":"cannot access local variable 'user_info' where it is not associated with a value"}
{"user":"x_finder3","timestamp":"2024-04-25T11:12:14.129169","nav_name":"yuan_http","action":"事件处理出错","params":"错误跟踪：Traceback (most recent call last):\n  File \"xlink_core.pyx\", line 697, in xlink_core.Main4\n  File \"\/opt\/openfbi\/fbi-bin\/addones\/streams\/yuan_http.py\", line 422, in Events\n    \"account\": re_acc,\n               ^^^^^^\nUnboundLocalError: cannot access local variable 'user_info' where it is not associated with a value\n","operate_result":"错误","failed_reason":"cannot access local variable 'user_info' where it is not associated with a value"}
{"user":"x_finder3","timestamp":"2024-04-25T11:12:14.130633","nav_name":"yuan_http","action":"事件处理出错","params":"错误跟踪：Traceback (most recent call last):\n  File \"xlink_core.pyx\", line 697, in xlink_core.Main4\n  File \"\/opt\/openfbi\/fbi-bin\/addones\/streams\/yuan_http.py\", line 422, in Events\n    \"account\": re_acc,\n               ^^^^^^\nUnboundLocalError: cannot access local variable 'user_info' where it is not associated with a value\n","operate_result":"错误","failed_reason":"cannot access local variable 'user_info' where it is not associated with a value"}
{"user":"x_finder3","timestamp":"2024-04-25T11:12:14.131661","nav_name":"yuan_http","action":"事件处理出错","params":"错误跟踪：Traceback (most recent call last):\n  File \"xlink_core.pyx\", line 697, in xlink_core.Main4\n  File \"\/opt\/openfbi\/fbi-bin\/addones\/streams\/yuan_http.py\", line 422, in Events\n    \"account\": re_acc,\n               ^^^^^^\nUnboundLocalError: cannot access local variable 'user_info' where it is not associated with a value\n","operate_result":"错误","failed_reason":"cannot access local variable 'user_info' where it is not associated with a value"}
{"user":"x_finder3","timestamp":"2024-04-25T11:12:14.134739","nav_name":"yuan_http","action":"事件处理出错","params":"错误跟踪：Traceback (most recent call last):\n  File \"xlink_core.pyx\", line 697, in xlink_core.Main4\n  File \"\/opt\/openfbi\/fbi-bin\/addones\/streams\/yuan_http.py\", line 422, in Events\n    \"account\": re_acc,\n               ^^^^^^\nUnboundLocalError: cannot access local variable 'user_info' where it is not associated with a value\n","operate_result":"错误","failed_reason":"cannot access local variable 'user_info' where it is not associated with a value"}
{"user":"x_finder3","timestamp":"2024-04-25T11:12:14.137926","nav_name":"yuan_http","action":"事件处理出错","params":"错误跟踪：Traceback (most recent call last):\n  File \"xlink_core.pyx\", line 697, in xlink_core.Main4\n  File \"\/opt\/openfbi\/fbi-bin\/addones\/streams\/yuan_http.py\", line 422, in Events\n    \"account\": re_acc,\n               ^^^^^^\nUnboundLocalError: cannot access local variable 'user_info' where it is not associated with a value\n","operate_result":"错误","failed_reason":"cannot access local variable 'user_info' where it is not associated with a value"}
{"user":"x_finder3","timestamp":"2024-04-25T11:12:14.138749","nav_name":"yuan_http","action":"事件处理出错","params":"错误跟踪：Traceback (most recent call last):\n  File \"xlink_core.pyx\", line 697, in xlink_core.Main4\n  File \"\/opt\/openfbi\/fbi-bin\/addones\/streams\/yuan_http.py\", line 422, in Events\n    \"account\": re_acc,\n               ^^^^^^\nUnboundLocalError: cannot access local variable 'user_info' where it is not associated with a value\n","operate_result":"错误","failed_reason":"cannot access local variable 'user_info' where it is not associated with a value"}
{"user":"x_finder3","timestamp":"2024-04-25T11:12:14.139853","nav_name":"yuan_http","action":"事件处理出错","params":"错误跟踪：Traceback (most recent call last):\n  File \"xlink_core.pyx\", line 697, in xlink_core.Main4\n  File \"\/opt\/openfbi\/fbi-bin\/addones\/streams\/yuan_http.py\", line 422, in Events\n    \"account\": re_acc,\n               ^^^^^^\nUnboundLocalError: cannot access local variable 'user_info' where it is not associated with a value\n","operate_result":"错误","failed_reason":"cannot access local variable 'user_info' where it is not associated with a value"}
{"user":"x_finder3","timestamp":"2024-04-25T11:12:14.141385","nav_name":"yuan_http","action":"事件处理出错","params":"错误跟踪：Traceback (most recent call last):\n  File \"xlink_core.pyx\", line 697, in xlink_core.Main4\n  File \"\/opt\/openfbi\/fbi-bin\/addones\/streams\/yuan_http.py\", line 422, in Events\n    \"account\": re_acc,\n               ^^^^^^\nUnboundLocalError: cannot access local variable 'user_info' where it is not associated with a value\n","operate_result":"错误","failed_reason":"cannot access local variable 'user_info' where it is not associated with a value"}
{"user":"x_finder3","timestamp":"2024-04-25T11:12:14.143003","nav_name":"yuan_http","action":"事件处理出错","params":"错误跟踪：Traceback (most recent call last):\n  File \"xlink_core.pyx\", line 697, in xlink_core.Main4\n  File \"\/opt\/openfbi\/fbi-bin\/addones\/streams\/yuan_http.py\", line 422, in Events\n    \"account\": re_acc,\n               ^^^^^^\nUnboundLocalError: cannot access local variable 'user_info' where it is not associated with a value\n","operate_result":"错误","failed_reason":"cannot access local variable 'user_info' where it is not associated with a value"}
{"user":"x_finder3","timestamp":"2024-04-25T11:12:14.145434","nav_name":"yuan_http","action":"事件处理出错","params":"错误跟踪：Traceback (most recent call last):\n  File \"xlink_core.pyx\", line 697, in xlink_core.Main4\n  File \"\/opt\/openfbi\/fbi-bin\/addones\/streams\/yuan_http.py\", line 422, in Events\n    \"account\": re_acc,\n               ^^^^^^\nUnboundLocalError: cannot access local variable 'user_info' where it is not associated with a value\n","operate_result":"错误","failed_reason":"cannot access local variable 'user_info' where it is not associated with a value"}
