{"user":"x_finder3","timestamp":"2024-04-25T11:12:14.146234","nav_name":"yuan_http","action":"事件处理出错","params":"错误跟踪：Traceback (most recent call last):\n  File \"xlink_core.pyx\", line 697, in xlink_core.Main4\n  File \"\/opt\/openfbi\/fbi-bin\/addones\/streams\/yuan_http.py\", line 422, in Events\n    \"account\": re_acc,\n               ^^^^^^\nUnboundLocalError: cannot access local variable 'user_info' where it is not associated with a value\n","operate_result":"错误","failed_reason":"cannot access local variable 'user_info' where it is not associated with a value"}
{"user":"x_finder3","timestamp":"2024-04-25T11:12:14.147572","nav_name":"yuan_http","action":"事件处理出错","params":"错误跟踪：Traceback (most recent call last):\n  File \"xlink_core.pyx\", line 697, in xlink_core.Main4\n  File \"\/opt\/openfbi\/fbi-bin\/addones\/streams\/yuan_http.py\", line 422, in Events\n    \"account\": re_acc,\n               ^^^^^^\nUnboundLocalError: cannot access local variable 'user_info' where it is not associated with a value\n","operate_result":"错误","failed_reason":"cannot access local variable 'user_info' where it is not associated with a value"}
{"user":"x_finder3","timestamp":"2024-04-25T11:12:14.148412","nav_name":"yuan_http","action":"事件处理出错","params":"错误跟踪：Traceback (most recent call last):\n  File \"xlink_core.pyx\", line 697, in xlink_core.Main4\n  File \"\/opt\/openfbi\/fbi-bin\/addones\/streams\/yuan_http.py\", line 422, in Events\n    \"account\": re_acc,\n               ^^^^^^\nUnboundLocalError: cannot access local variable 'user_info' where it is not associated with a value\n","operate_result":"错误","failed_reason":"cannot access local variable 'user_info' where it is not associated with a value"}
{"user":"x_finder3","timestamp":"2024-04-25T11:12:14.149421","nav_name":"yuan_http","action":"事件处理出错","params":"错误跟踪：Traceback (most recent call last):\n  File \"xlink_core.pyx\", line 697, in xlink_core.Main4\n  File \"\/opt\/openfbi\/fbi-bin\/addones\/streams\/yuan_http.py\", line 422, in Events\n    \"account\": re_acc,\n               ^^^^^^\nUnboundLocalError: cannot access local variable 'user_info' where it is not associated with a value\n","operate_result":"错误","failed_reason":"cannot access local variable 'user_info' where it is not associated with a value"}
{"user":"x_finder3","timestamp":"2024-04-25T11:12:14.151663","nav_name":"yuan_http","action":"事件处理出错","params":"错误跟踪：Traceback (most recent call last):\n  File \"xlink_core.pyx\", line 697, in xlink_core.Main4\n  File \"\/opt\/openfbi\/fbi-bin\/addones\/streams\/yuan_http.py\", line 422, in Events\n    \"account\": re_acc,\n               ^^^^^^\nUnboundLocalError: cannot access local variable 'user_info' where it is not associated with a value\n","operate_result":"错误","failed_reason":"cannot access local variable 'user_info' where it is not associated with a value"}
{"user":"x_finder3","timestamp":"2024-04-25T11:12:14.152521","nav_name":"yuan_http","action":"事件处理出错","params":"错误跟踪：Traceback (most recent call last):\n  File \"xlink_core.pyx\", line 697, in xlink_core.Main4\n  File \"\/opt\/openfbi\/fbi-bin\/addones\/streams\/yuan_http.py\", line 422, in Events\n    \"account\": re_acc,\n               ^^^^^^\nUnboundLocalError: cannot access local variable 'user_info' where it is not associated with a value\n","operate_result":"错误","failed_reason":"cannot access local variable 'user_info' where it is not associated with a value"}
{"user":"x_finder3","timestamp":"2024-04-25T11:12:14.154418","nav_name":"yuan_http","action":"事件处理出错","params":"错误跟踪：Traceback (most recent call last):\n  File \"xlink_core.pyx\", line 697, in xlink_core.Main4\n  File \"\/opt\/openfbi\/fbi-bin\/addones\/streams\/yuan_http.py\", line 422, in Events\n    \"account\": re_acc,\n               ^^^^^^\nUnboundLocalError: cannot access local variable 'user_info' where it is not associated with a value\n","operate_result":"错误","failed_reason":"cannot access local variable 'user_info' where it is not associated with a value"}
{"user":"x_finder3","timestamp":"2024-04-25T11:12:14.157840","nav_name":"yuan_http","action":"事件处理出错","params":"错误跟踪：Traceback (most recent call last):\n  File \"xlink_core.pyx\", line 697, in xlink_core.Main4\n  File \"\/opt\/openfbi\/fbi-bin\/addones\/streams\/yuan_http.py\", line 422, in Events\n    \"account\": re_acc,\n               ^^^^^^\nUnboundLocalError: cannot access local variable 'user_info' where it is not associated with a value\n","operate_result":"错误","failed_reason":"cannot access local variable 'user_info' where it is not associated with a value"}
{"user":"x_finder3","timestamp":"2024-04-25T11:12:14.159651","nav_name":"yuan_http","action":"事件处理出错","params":"错误跟踪：Traceback (most recent call last):\n  File \"xlink_core.pyx\", line 697, in xlink_core.Main4\n  File \"\/opt\/openfbi\/fbi-bin\/addones\/streams\/yuan_http.py\", line 422, in Events\n    \"account\": re_acc,\n               ^^^^^^\nUnboundLocalError: cannot access local variable 'user_info' where it is not associated with a value\n","operate_result":"错误","failed_reason":"cannot access local variable 'user_info' where it is not associated with a value"}
{"user":"x_finder3","timestamp":"2024-04-25T11:12:14.161539","nav_name":"yuan_http","action":"事件处理出错","params":"错误跟踪：Traceback (most recent call last):\n  File \"xlink_core.pyx\", line 697, in xlink_core.Main4\n  File \"\/opt\/openfbi\/fbi-bin\/addones\/streams\/yuan_http.py\", line 422, in Events\n    \"account\": re_acc,\n               ^^^^^^\nUnboundLocalError: cannot access local variable 'user_info' where it is not associated with a value\n","operate_result":"错误","failed_reason":"cannot access local variable 'user_info' where it is not associated with a value"}
{"user":"x_finder3","timestamp":"2024-04-25T11:12:14.164415","nav_name":"yuan_http","action":"事件处理出错","params":"错误跟踪：Traceback (most recent call last):\n  File \"xlink_core.pyx\", line 697, in xlink_core.Main4\n  File \"\/opt\/openfbi\/fbi-bin\/addones\/streams\/yuan_http.py\", line 422, in Events\n    \"account\": re_acc,\n               ^^^^^^\nUnboundLocalError: cannot access local variable 'user_info' where it is not associated with a value\n","operate_result":"错误","failed_reason":"cannot access local variable 'user_info' where it is not associated with a value"}
{"user":"x_finder3","timestamp":"2024-04-25T11:12:14.165887","nav_name":"yuan_http","action":"事件处理出错","params":"错误跟踪：Traceback (most recent call last):\n  File \"xlink_core.pyx\", line 697, in xlink_core.Main4\n  File \"\/opt\/openfbi\/fbi-bin\/addones\/streams\/yuan_http.py\", line 422, in Events\n    \"account\": re_acc,\n               ^^^^^^\nUnboundLocalError: cannot access local variable 'user_info' where it is not associated with a value\n","operate_result":"错误","failed_reason":"cannot access local variable 'user_info' where it is not associated with a value"}
{"user":"x_finder3","timestamp":"2024-04-25T11:12:14.170183","nav_name":"yuan_http","action":"事件处理出错","params":"错误跟踪：Traceback (most recent call last):\n  File \"xlink_core.pyx\", line 697, in xlink_core.Main4\n  File \"\/opt\/openfbi\/fbi-bin\/addones\/streams\/yuan_http.py\", line 422, in Events\n    \"account\": re_acc,\n               ^^^^^^\nUnboundLocalError: cannot access local variable 'user_info' where it is not associated with a value\n","operate_result":"错误","failed_reason":"cannot access local variable 'user_info' where it is not associated with a value"}
{"user":"x_finder3","timestamp":"2024-04-25T11:12:18.115896","nav_name":"yuan_http","action":"事件处理出错","params":"错误跟踪：Traceback (most recent call last):\n  File \"xlink_core.pyx\", line 697, in xlink_core.Main4\n  File \"\/opt\/openfbi\/fbi-bin\/addones\/streams\/yuan_http.py\", line 422, in Events\n    \"account\": re_acc,\n               ^^^^^^\nUnboundLocalError: cannot access local variable 'user_info' where it is not associated with a value\n","operate_result":"错误","failed_reason":"cannot access local variable 'user_info' where it is not associated with a value"}
{"user":"x_finder3","timestamp":"2024-04-25T11:12:18.116903","nav_name":"yuan_http","action":"事件处理出错","params":"错误跟踪：Traceback (most recent call last):\n  File \"xlink_core.pyx\", line 697, in xlink_core.Main4\n  File \"\/opt\/openfbi\/fbi-bin\/addones\/streams\/yuan_http.py\", line 422, in Events\n    \"account\": re_acc,\n               ^^^^^^\nUnboundLocalError: cannot access local variable 'user_info' where it is not associated with a value\n","operate_result":"错误","failed_reason":"cannot access local variable 'user_info' where it is not associated with a value"}
{"user":"x_finder3","timestamp":"2024-04-25T11:12:18.117832","nav_name":"yuan_http","action":"事件处理出错","params":"错误跟踪：Traceback (most recent call last):\n  File \"xlink_core.pyx\", line 697, in xlink_core.Main4\n  File \"\/opt\/openfbi\/fbi-bin\/addones\/streams\/yuan_http.py\", line 422, in Events\n    \"account\": re_acc,\n               ^^^^^^\nUnboundLocalError: cannot access local variable 'user_info' where it is not associated with a value\n","operate_result":"错误","failed_reason":"cannot access local variable 'user_info' where it is not associated with a value"}
{"user":"x_finder3","timestamp":"2024-04-25T11:12:23.102695","nav_name":"yuan_http","action":"事件处理出错","params":"错误跟踪：Traceback (most recent call last):\n  File \"xlink_core.pyx\", line 697, in xlink_core.Main4\n  File \"\/opt\/openfbi\/fbi-bin\/addones\/streams\/yuan_http.py\", line 422, in Events\n    \"account\": re_acc,\n               ^^^^^^\nUnboundLocalError: cannot access local variable 'user_info' where it is not associated with a value\n","operate_result":"错误","failed_reason":"cannot access local variable 'user_info' where it is not associated with a value"}
{"user":"x_finder3","timestamp":"2024-04-25T11:12:23.154415","nav_name":"yuan_http","action":"事件处理出错","params":"错误跟踪：Traceback (most recent call last):\n  File \"xlink_core.pyx\", line 697, in xlink_core.Main4\n  File \"\/opt\/openfbi\/fbi-bin\/addones\/streams\/yuan_http.py\", line 422, in Events\n    \"account\": re_acc,\n               ^^^^^^\nUnboundLocalError: cannot access local variable 'user_info' where it is not associated with a value\n","operate_result":"错误","failed_reason":"cannot access local variable 'user_info' where it is not associated with a value"}
{"user":"x_finder3","timestamp":"2024-04-25T11:12:23.155329","nav_name":"yuan_http","action":"事件处理出错","params":"错误跟踪：Traceback (most recent call last):\n  File \"xlink_core.pyx\", line 697, in xlink_core.Main4\n  File \"\/opt\/openfbi\/fbi-bin\/addones\/streams\/yuan_http.py\", line 422, in Events\n    \"account\": re_acc,\n               ^^^^^^\nUnboundLocalError: cannot access local variable 'user_info' where it is not associated with a value\n","operate_result":"错误","failed_reason":"cannot access local variable 'user_info' where it is not associated with a value"}
{"user":"x_finder3","timestamp":"2024-04-25T11:12:25.272761","nav_name":"yuan_http","action":"事件处理出错","params":"错误跟踪：Traceback (most recent call last):\n  File \"xlink_core.pyx\", line 697, in xlink_core.Main4\n  File \"\/opt\/openfbi\/fbi-bin\/addones\/streams\/yuan_http.py\", line 422, in Events\n    \"account\": re_acc,\n               ^^^^^^\nUnboundLocalError: cannot access local variable 'user_info' where it is not associated with a value\n","operate_result":"错误","failed_reason":"cannot access local variable 'user_info' where it is not associated with a value"}
{"user":"x_finder3","timestamp":"2024-04-25T11:12:28.140761","nav_name":"yuan_http","action":"事件处理出错","params":"错误跟踪：Traceback (most recent call last):\n  File \"xlink_core.pyx\", line 697, in xlink_core.Main4\n  File \"\/opt\/openfbi\/fbi-bin\/addones\/streams\/yuan_http.py\", line 422, in Events\n    \"account\": re_acc,\n               ^^^^^^\nUnboundLocalError: cannot access local variable 'user_info' where it is not associated with a value\n","operate_result":"错误","failed_reason":"cannot access local variable 'user_info' where it is not associated with a value"}
{"user":"x_finder3","timestamp":"2024-04-25T11:12:28.151835","nav_name":"yuan_http","action":"事件处理出错","params":"错误跟踪：Traceback (most recent call last):\n  File \"xlink_core.pyx\", line 697, in xlink_core.Main4\n  File \"\/opt\/openfbi\/fbi-bin\/addones\/streams\/yuan_http.py\", line 422, in Events\n    \"account\": re_acc,\n               ^^^^^^\nUnboundLocalError: cannot access local variable 'user_info' where it is not associated with a value\n","operate_result":"错误","failed_reason":"cannot access local variable 'user_info' where it is not associated with a value"}
{"user":"x_finder3","timestamp":"2024-04-25T11:12:28.152788","nav_name":"yuan_http","action":"事件处理出错","params":"错误跟踪：Traceback (most recent call last):\n  File \"xlink_core.pyx\", line 697, in xlink_core.Main4\n  File \"\/opt\/openfbi\/fbi-bin\/addones\/streams\/yuan_http.py\", line 422, in Events\n    \"account\": re_acc,\n               ^^^^^^\nUnboundLocalError: cannot access local variable 'user_info' where it is not associated with a value\n","operate_result":"错误","failed_reason":"cannot access local variable 'user_info' where it is not associated with a value"}
{"user":"x_finder3","timestamp":"2024-04-25T11:12:33.193188","nav_name":"yuan_http","action":"事件处理出错","params":"错误跟踪：Traceback (most recent call last):\n  File \"xlink_core.pyx\", line 697, in xlink_core.Main4\n  File \"\/opt\/openfbi\/fbi-bin\/addones\/streams\/yuan_http.py\", line 422, in Events\n    \"account\": re_acc,\n               ^^^^^^\nUnboundLocalError: cannot access local variable 'user_info' where it is not associated with a value\n","operate_result":"错误","failed_reason":"cannot access local variable 'user_info' where it is not associated with a value"}
{"user":"x_finder3","timestamp":"2024-04-25T11:12:33.194286","nav_name":"yuan_http","action":"事件处理出错","params":"错误跟踪：Traceback (most recent call last):\n  File \"xlink_core.pyx\", line 697, in xlink_core.Main4\n  File \"\/opt\/openfbi\/fbi-bin\/addones\/streams\/yuan_http.py\", line 422, in Events\n    \"account\": re_acc,\n               ^^^^^^\nUnboundLocalError: cannot access local variable 'user_info' where it is not associated with a value\n","operate_result":"错误","failed_reason":"cannot access local variable 'user_info' where it is not associated with a value"}
{"user":"x_finder3","timestamp":"2024-04-25T11:12:33.195236","nav_name":"yuan_http","action":"事件处理出错","params":"错误跟踪：Traceback (most recent call last):\n  File \"xlink_core.pyx\", line 697, in xlink_core.Main4\n  File \"\/opt\/openfbi\/fbi-bin\/addones\/streams\/yuan_http.py\", line 422, in Events\n    \"account\": re_acc,\n               ^^^^^^\nUnboundLocalError: cannot access local variable 'user_info' where it is not associated with a value\n","operate_result":"错误","failed_reason":"cannot access local variable 'user_info' where it is not associated with a value"}
{"user":"x_finder3","timestamp":"2024-04-25T11:12:38.129093","nav_name":"yuan_http","action":"事件处理出错","params":"错误跟踪：Traceback (most recent call last):\n  File \"xlink_core.pyx\", line 697, in xlink_core.Main4\n  File \"\/opt\/openfbi\/fbi-bin\/addones\/streams\/yuan_http.py\", line 422, in Events\n    \"account\": re_acc,\n               ^^^^^^\nUnboundLocalError: cannot access local variable 'user_info' where it is not associated with a value\n","operate_result":"错误","failed_reason":"cannot access local variable 'user_info' where it is not associated with a value"}
{"user":"x_finder3","timestamp":"2024-04-25T11:12:38.130084","nav_name":"yuan_http","action":"事件处理出错","params":"错误跟踪：Traceback (most recent call last):\n  File \"xlink_core.pyx\", line 697, in xlink_core.Main4\n  File \"\/opt\/openfbi\/fbi-bin\/addones\/streams\/yuan_http.py\", line 422, in Events\n    \"account\": re_acc,\n               ^^^^^^\nUnboundLocalError: cannot access local variable 'user_info' where it is not associated with a value\n","operate_result":"错误","failed_reason":"cannot access local variable 'user_info' where it is not associated with a value"}
{"user":"x_finder3","timestamp":"2024-04-25T11:12:38.130986","nav_name":"yuan_http","action":"事件处理出错","params":"错误跟踪：Traceback (most recent call last):\n  File \"xlink_core.pyx\", line 697, in xlink_core.Main4\n  File \"\/opt\/openfbi\/fbi-bin\/addones\/streams\/yuan_http.py\", line 422, in Events\n    \"account\": re_acc,\n               ^^^^^^\nUnboundLocalError: cannot access local variable 'user_info' where it is not associated with a value\n","operate_result":"错误","failed_reason":"cannot access local variable 'user_info' where it is not associated with a value"}
{"user":"x_finder3","timestamp":"2024-04-25T11:12:43.126582","nav_name":"yuan_http","action":"事件处理出错","params":"错误跟踪：Traceback (most recent call last):\n  File \"xlink_core.pyx\", line 697, in xlink_core.Main4\n  File \"\/opt\/openfbi\/fbi-bin\/addones\/streams\/yuan_http.py\", line 422, in Events\n    \"account\": re_acc,\n               ^^^^^^\nUnboundLocalError: cannot access local variable 'user_info' where it is not associated with a value\n","operate_result":"错误","failed_reason":"cannot access local variable 'user_info' where it is not associated with a value"}
{"user":"x_finder3","timestamp":"2024-04-25T11:12:43.127588","nav_name":"yuan_http","action":"事件处理出错","params":"错误跟踪：Traceback (most recent call last):\n  File \"xlink_core.pyx\", line 697, in xlink_core.Main4\n  File \"\/opt\/openfbi\/fbi-bin\/addones\/streams\/yuan_http.py\", line 422, in Events\n    \"account\": re_acc,\n               ^^^^^^\nUnboundLocalError: cannot access local variable 'user_info' where it is not associated with a value\n","operate_result":"错误","failed_reason":"cannot access local variable 'user_info' where it is not associated with a value"}
{"user":"x_finder3","timestamp":"2024-04-25T11:12:43.128489","nav_name":"yuan_http","action":"事件处理出错","params":"错误跟踪：Traceback (most recent call last):\n  File \"xlink_core.pyx\", line 697, in xlink_core.Main4\n  File \"\/opt\/openfbi\/fbi-bin\/addones\/streams\/yuan_http.py\", line 422, in Events\n    \"account\": re_acc,\n               ^^^^^^\nUnboundLocalError: cannot access local variable 'user_info' where it is not associated with a value\n","operate_result":"错误","failed_reason":"cannot access local variable 'user_info' where it is not associated with a value"}
{"user":"x_finder3","timestamp":"2024-04-25T11:12:47.262479","nav_name":"yuan_http","action":"事件处理出错","params":"错误跟踪：Traceback (most recent call last):\n  File \"xlink_core.pyx\", line 697, in xlink_core.Main4\n  File \"\/opt\/openfbi\/fbi-bin\/addones\/streams\/yuan_http.py\", line 422, in Events\n    \"account\": re_acc,\n               ^^^^^^\nUnboundLocalError: cannot access local variable 'user_info' where it is not associated with a value\n","operate_result":"错误","failed_reason":"cannot access local variable 'user_info' where it is not associated with a value"}
{"user":"x_finder3","timestamp":"2024-04-25T11:12:47.263457","nav_name":"yuan_http","action":"事件处理出错","params":"错误跟踪：Traceback (most recent call last):\n  File \"xlink_core.pyx\", line 697, in xlink_core.Main4\n  File \"\/opt\/openfbi\/fbi-bin\/addones\/streams\/yuan_http.py\", line 422, in Events\n    \"account\": re_acc,\n               ^^^^^^\nUnboundLocalError: cannot access local variable 'user_info' where it is not associated with a value\n","operate_result":"错误","failed_reason":"cannot access local variable 'user_info' where it is not associated with a value"}
{"user":"x_finder3","timestamp":"2024-04-25T11:12:47.264391","nav_name":"yuan_http","action":"事件处理出错","params":"错误跟踪：Traceback (most recent call last):\n  File \"xlink_core.pyx\", line 697, in xlink_core.Main4\n  File \"\/opt\/openfbi\/fbi-bin\/addones\/streams\/yuan_http.py\", line 422, in Events\n    \"account\": re_acc,\n               ^^^^^^\nUnboundLocalError: cannot access local variable 'user_info' where it is not associated with a value\n","operate_result":"错误","failed_reason":"cannot access local variable 'user_info' where it is not associated with a value"}
{"user":"x_finder3","timestamp":"2024-04-25T11:12:47.265275","nav_name":"yuan_http","action":"事件处理出错","params":"错误跟踪：Traceback (most recent call last):\n  File \"xlink_core.pyx\", line 697, in xlink_core.Main4\n  File \"\/opt\/openfbi\/fbi-bin\/addones\/streams\/yuan_http.py\", line 422, in Events\n    \"account\": re_acc,\n               ^^^^^^\nUnboundLocalError: cannot access local variable 'user_info' where it is not associated with a value\n","operate_result":"错误","failed_reason":"cannot access local variable 'user_info' where it is not associated with a value"}
{"user":"x_finder3","timestamp":"2024-04-25T11:12:47.266208","nav_name":"yuan_http","action":"事件处理出错","params":"错误跟踪：Traceback (most recent call last):\n  File \"xlink_core.pyx\", line 697, in xlink_core.Main4\n  File \"\/opt\/openfbi\/fbi-bin\/addones\/streams\/yuan_http.py\", line 422, in Events\n    \"account\": re_acc,\n               ^^^^^^\nUnboundLocalError: cannot access local variable 'user_info' where it is not associated with a value\n","operate_result":"错误","failed_reason":"cannot access local variable 'user_info' where it is not associated with a value"}
{"user":"x_finder3","timestamp":"2024-04-25T11:12:47.267090","nav_name":"yuan_http","action":"事件处理出错","params":"错误跟踪：Traceback (most recent call last):\n  File \"xlink_core.pyx\", line 697, in xlink_core.Main4\n  File \"\/opt\/openfbi\/fbi-bin\/addones\/streams\/yuan_http.py\", line 422, in Events\n    \"account\": re_acc,\n               ^^^^^^\nUnboundLocalError: cannot access local variable 'user_info' where it is not associated with a value\n","operate_result":"错误","failed_reason":"cannot access local variable 'user_info' where it is not associated with a value"}
{"user":"x_finder3","timestamp":"2024-04-25T11:12:47.267954","nav_name":"yuan_http","action":"事件处理出错","params":"错误跟踪：Traceback (most recent call last):\n  File \"xlink_core.pyx\", line 697, in xlink_core.Main4\n  File \"\/opt\/openfbi\/fbi-bin\/addones\/streams\/yuan_http.py\", line 422, in Events\n    \"account\": re_acc,\n               ^^^^^^\nUnboundLocalError: cannot access local variable 'user_info' where it is not associated with a value\n","operate_result":"错误","failed_reason":"cannot access local variable 'user_info' where it is not associated with a value"}
{"user":"x_finder3","timestamp":"2024-04-25T11:12:47.269455","nav_name":"yuan_http","action":"事件处理出错","params":"错误跟踪：Traceback (most recent call last):\n  File \"xlink_core.pyx\", line 697, in xlink_core.Main4\n  File \"\/opt\/openfbi\/fbi-bin\/addones\/streams\/yuan_http.py\", line 422, in Events\n    \"account\": re_acc,\n               ^^^^^^\nUnboundLocalError: cannot access local variable 'user_info' where it is not associated with a value\n","operate_result":"错误","failed_reason":"cannot access local variable 'user_info' where it is not associated with a value"}
{"user":"x_finder3","timestamp":"2024-04-25T11:12:47.270337","nav_name":"yuan_http","action":"事件处理出错","params":"错误跟踪：Traceback (most recent call last):\n  File \"xlink_core.pyx\", line 697, in xlink_core.Main4\n  File \"\/opt\/openfbi\/fbi-bin\/addones\/streams\/yuan_http.py\", line 422, in Events\n    \"account\": re_acc,\n               ^^^^^^\nUnboundLocalError: cannot access local variable 'user_info' where it is not associated with a value\n","operate_result":"错误","failed_reason":"cannot access local variable 'user_info' where it is not associated with a value"}
{"user":"x_finder3","timestamp":"2024-04-25T11:12:47.312007","nav_name":"yuan_http","action":"事件处理出错","params":"错误跟踪：Traceback (most recent call last):\n  File \"xlink_core.pyx\", line 697, in xlink_core.Main4\n  File \"\/opt\/openfbi\/fbi-bin\/addones\/streams\/yuan_http.py\", line 422, in Events\n    \"account\": re_acc,\n               ^^^^^^\nUnboundLocalError: cannot access local variable 'user_info' where it is not associated with a value\n","operate_result":"错误","failed_reason":"cannot access local variable 'user_info' where it is not associated with a value"}
{"user":"x_finder3","timestamp":"2024-04-25T11:12:48.123189","nav_name":"yuan_http","action":"事件处理出错","params":"错误跟踪：Traceback (most recent call last):\n  File \"xlink_core.pyx\", line 697, in xlink_core.Main4\n  File \"\/opt\/openfbi\/fbi-bin\/addones\/streams\/yuan_http.py\", line 422, in Events\n    \"account\": re_acc,\n               ^^^^^^\nUnboundLocalError: cannot access local variable 'user_info' where it is not associated with a value\n","operate_result":"错误","failed_reason":"cannot access local variable 'user_info' where it is not associated with a value"}
{"user":"x_finder3","timestamp":"2024-04-25T11:12:48.124173","nav_name":"yuan_http","action":"事件处理出错","params":"错误跟踪：Traceback (most recent call last):\n  File \"xlink_core.pyx\", line 697, in xlink_core.Main4\n  File \"\/opt\/openfbi\/fbi-bin\/addones\/streams\/yuan_http.py\", line 422, in Events\n    \"account\": re_acc,\n               ^^^^^^\nUnboundLocalError: cannot access local variable 'user_info' where it is not associated with a value\n","operate_result":"错误","failed_reason":"cannot access local variable 'user_info' where it is not associated with a value"}
{"user":"x_finder3","timestamp":"2024-04-25T11:12:48.125076","nav_name":"yuan_http","action":"事件处理出错","params":"错误跟踪：Traceback (most recent call last):\n  File \"xlink_core.pyx\", line 697, in xlink_core.Main4\n  File \"\/opt\/openfbi\/fbi-bin\/addones\/streams\/yuan_http.py\", line 422, in Events\n    \"account\": re_acc,\n               ^^^^^^\nUnboundLocalError: cannot access local variable 'user_info' where it is not associated with a value\n","operate_result":"错误","failed_reason":"cannot access local variable 'user_info' where it is not associated with a value"}
{"user":"x_finder3","timestamp":"2024-04-25T11:12:53.125300","nav_name":"yuan_http","action":"事件处理出错","params":"错误跟踪：Traceback (most recent call last):\n  File \"xlink_core.pyx\", line 697, in xlink_core.Main4\n  File \"\/opt\/openfbi\/fbi-bin\/addones\/streams\/yuan_http.py\", line 422, in Events\n    \"account\": re_acc,\n               ^^^^^^\nUnboundLocalError: cannot access local variable 'user_info' where it is not associated with a value\n","operate_result":"错误","failed_reason":"cannot access local variable 'user_info' where it is not associated with a value"}
{"user":"x_finder3","timestamp":"2024-04-25T11:12:53.126278","nav_name":"yuan_http","action":"事件处理出错","params":"错误跟踪：Traceback (most recent call last):\n  File \"xlink_core.pyx\", line 697, in xlink_core.Main4\n  File \"\/opt\/openfbi\/fbi-bin\/addones\/streams\/yuan_http.py\", line 422, in Events\n    \"account\": re_acc,\n               ^^^^^^\nUnboundLocalError: cannot access local variable 'user_info' where it is not associated with a value\n","operate_result":"错误","failed_reason":"cannot access local variable 'user_info' where it is not associated with a value"}
{"user":"x_finder3","timestamp":"2024-04-25T11:12:53.127262","nav_name":"yuan_http","action":"事件处理出错","params":"错误跟踪：Traceback (most recent call last):\n  File \"xlink_core.pyx\", line 697, in xlink_core.Main4\n  File \"\/opt\/openfbi\/fbi-bin\/addones\/streams\/yuan_http.py\", line 422, in Events\n    \"account\": re_acc,\n               ^^^^^^\nUnboundLocalError: cannot access local variable 'user_info' where it is not associated with a value\n","operate_result":"错误","failed_reason":"cannot access local variable 'user_info' where it is not associated with a value"}
{"user":"x_finder3","timestamp":"2024-04-25T11:12:58.163010","nav_name":"yuan_http","action":"事件处理出错","params":"错误跟踪：Traceback (most recent call last):\n  File \"xlink_core.pyx\", line 697, in xlink_core.Main4\n  File \"\/opt\/openfbi\/fbi-bin\/addones\/streams\/yuan_http.py\", line 422, in Events\n    \"account\": re_acc,\n               ^^^^^^\nUnboundLocalError: cannot access local variable 'user_info' where it is not associated with a value\n","operate_result":"错误","failed_reason":"cannot access local variable 'user_info' where it is not associated with a value"}
{"user":"x_finder3","timestamp":"2024-04-25T11:12:58.163997","nav_name":"yuan_http","action":"事件处理出错","params":"错误跟踪：Traceback (most recent call last):\n  File \"xlink_core.pyx\", line 697, in xlink_core.Main4\n  File \"\/opt\/openfbi\/fbi-bin\/addones\/streams\/yuan_http.py\", line 422, in Events\n    \"account\": re_acc,\n               ^^^^^^\nUnboundLocalError: cannot access local variable 'user_info' where it is not associated with a value\n","operate_result":"错误","failed_reason":"cannot access local variable 'user_info' where it is not associated with a value"}
{"user":"x_finder3","timestamp":"2024-04-25T11:12:58.164996","nav_name":"yuan_http","action":"事件处理出错","params":"错误跟踪：Traceback (most recent call last):\n  File \"xlink_core.pyx\", line 697, in xlink_core.Main4\n  File \"\/opt\/openfbi\/fbi-bin\/addones\/streams\/yuan_http.py\", line 422, in Events\n    \"account\": re_acc,\n               ^^^^^^\nUnboundLocalError: cannot access local variable 'user_info' where it is not associated with a value\n","operate_result":"错误","failed_reason":"cannot access local variable 'user_info' where it is not associated with a value"}
{"user":"x_finder3","timestamp":"2024-04-25T11:13:00.245341","nav_name":"yuan_http","action":"事件处理出错","params":"错误跟踪：Traceback (most recent call last):\n  File \"xlink_core.pyx\", line 697, in xlink_core.Main4\n  File \"\/opt\/openfbi\/fbi-bin\/addones\/streams\/yuan_http.py\", line 422, in Events\n    \"account\": re_acc,\n               ^^^^^^\nUnboundLocalError: cannot access local variable 'user_info' where it is not associated with a value\n","operate_result":"错误","failed_reason":"cannot access local variable 'user_info' where it is not associated with a value"}
{"user":"x_finder3","timestamp":"2024-04-25T11:13:00.246395","nav_name":"yuan_http","action":"事件处理出错","params":"错误跟踪：Traceback (most recent call last):\n  File \"xlink_core.pyx\", line 697, in xlink_core.Main4\n  File \"\/opt\/openfbi\/fbi-bin\/addones\/streams\/yuan_http.py\", line 422, in Events\n    \"account\": re_acc,\n               ^^^^^^\nUnboundLocalError: cannot access local variable 'user_info' where it is not associated with a value\n","operate_result":"错误","failed_reason":"cannot access local variable 'user_info' where it is not associated with a value"}
{"user":"x_finder3","timestamp":"2024-04-25T11:13:00.399638","nav_name":"yuan_http","action":"事件处理出错","params":"错误跟踪：Traceback (most recent call last):\n  File \"xlink_core.pyx\", line 697, in xlink_core.Main4\n  File \"\/opt\/openfbi\/fbi-bin\/addones\/streams\/yuan_http.py\", line 422, in Events\n    \"account\": re_acc,\n               ^^^^^^\nUnboundLocalError: cannot access local variable 'user_info' where it is not associated with a value\n","operate_result":"错误","failed_reason":"cannot access local variable 'user_info' where it is not associated with a value"}
{"user":"x_finder3","timestamp":"2024-04-25T11:13:03.125665","nav_name":"yuan_http","action":"事件处理出错","params":"错误跟踪：Traceback (most recent call last):\n  File \"xlink_core.pyx\", line 697, in xlink_core.Main4\n  File \"\/opt\/openfbi\/fbi-bin\/addones\/streams\/yuan_http.py\", line 422, in Events\n    \"account\": re_acc,\n               ^^^^^^\nUnboundLocalError: cannot access local variable 'user_info' where it is not associated with a value\n","operate_result":"错误","failed_reason":"cannot access local variable 'user_info' where it is not associated with a value"}
{"user":"x_finder3","timestamp":"2024-04-25T11:13:03.126645","nav_name":"yuan_http","action":"事件处理出错","params":"错误跟踪：Traceback (most recent call last):\n  File \"xlink_core.pyx\", line 697, in xlink_core.Main4\n  File \"\/opt\/openfbi\/fbi-bin\/addones\/streams\/yuan_http.py\", line 422, in Events\n    \"account\": re_acc,\n               ^^^^^^\nUnboundLocalError: cannot access local variable 'user_info' where it is not associated with a value\n","operate_result":"错误","failed_reason":"cannot access local variable 'user_info' where it is not associated with a value"}
{"user":"x_finder3","timestamp":"2024-04-25T11:13:03.127634","nav_name":"yuan_http","action":"事件处理出错","params":"错误跟踪：Traceback (most recent call last):\n  File \"xlink_core.pyx\", line 697, in xlink_core.Main4\n  File \"\/opt\/openfbi\/fbi-bin\/addones\/streams\/yuan_http.py\", line 422, in Events\n    \"account\": re_acc,\n               ^^^^^^\nUnboundLocalError: cannot access local variable 'user_info' where it is not associated with a value\n","operate_result":"错误","failed_reason":"cannot access local variable 'user_info' where it is not associated with a value"}
{"user":"x_finder3","timestamp":"2024-04-25T11:13:08.164599","nav_name":"yuan_http","action":"事件处理出错","params":"错误跟踪：Traceback (most recent call last):\n  File \"xlink_core.pyx\", line 697, in xlink_core.Main4\n  File \"\/opt\/openfbi\/fbi-bin\/addones\/streams\/yuan_http.py\", line 422, in Events\n    \"account\": re_acc,\n               ^^^^^^\nUnboundLocalError: cannot access local variable 'user_info' where it is not associated with a value\n","operate_result":"错误","failed_reason":"cannot access local variable 'user_info' where it is not associated with a value"}
{"user":"x_finder3","timestamp":"2024-04-25T11:13:08.165579","nav_name":"yuan_http","action":"事件处理出错","params":"错误跟踪：Traceback (most recent call last):\n  File \"xlink_core.pyx\", line 697, in xlink_core.Main4\n  File \"\/opt\/openfbi\/fbi-bin\/addones\/streams\/yuan_http.py\", line 422, in Events\n    \"account\": re_acc,\n               ^^^^^^\nUnboundLocalError: cannot access local variable 'user_info' where it is not associated with a value\n","operate_result":"错误","failed_reason":"cannot access local variable 'user_info' where it is not associated with a value"}
{"user":"x_finder3","timestamp":"2024-04-25T11:13:08.166532","nav_name":"yuan_http","action":"事件处理出错","params":"错误跟踪：Traceback (most recent call last):\n  File \"xlink_core.pyx\", line 697, in xlink_core.Main4\n  File \"\/opt\/openfbi\/fbi-bin\/addones\/streams\/yuan_http.py\", line 422, in Events\n    \"account\": re_acc,\n               ^^^^^^\nUnboundLocalError: cannot access local variable 'user_info' where it is not associated with a value\n","operate_result":"错误","failed_reason":"cannot access local variable 'user_info' where it is not associated with a value"}
{"user":"x_finder3","timestamp":"2024-04-25T11:13:13.143233","nav_name":"yuan_http","action":"事件处理出错","params":"错误跟踪：Traceback (most recent call last):\n  File \"xlink_core.pyx\", line 697, in xlink_core.Main4\n  File \"\/opt\/openfbi\/fbi-bin\/addones\/streams\/yuan_http.py\", line 422, in Events\n    \"account\": re_acc,\n               ^^^^^^\nUnboundLocalError: cannot access local variable 'user_info' where it is not associated with a value\n","operate_result":"错误","failed_reason":"cannot access local variable 'user_info' where it is not associated with a value"}
{"user":"x_finder3","timestamp":"2024-04-25T11:13:13.144217","nav_name":"yuan_http","action":"事件处理出错","params":"错误跟踪：Traceback (most recent call last):\n  File \"xlink_core.pyx\", line 697, in xlink_core.Main4\n  File \"\/opt\/openfbi\/fbi-bin\/addones\/streams\/yuan_http.py\", line 422, in Events\n    \"account\": re_acc,\n               ^^^^^^\nUnboundLocalError: cannot access local variable 'user_info' where it is not associated with a value\n","operate_result":"错误","failed_reason":"cannot access local variable 'user_info' where it is not associated with a value"}
{"user":"x_finder3","timestamp":"2024-04-25T11:13:13.145095","nav_name":"yuan_http","action":"事件处理出错","params":"错误跟踪：Traceback (most recent call last):\n  File \"xlink_core.pyx\", line 697, in xlink_core.Main4\n  File \"\/opt\/openfbi\/fbi-bin\/addones\/streams\/yuan_http.py\", line 422, in Events\n    \"account\": re_acc,\n               ^^^^^^\nUnboundLocalError: cannot access local variable 'user_info' where it is not associated with a value\n","operate_result":"错误","failed_reason":"cannot access local variable 'user_info' where it is not associated with a value"}
{"user":"x_finder3","timestamp":"2024-04-25T11:13:17.533508","nav_name":"yuan_http","action":"事件处理出错","params":"错误跟踪：Traceback (most recent call last):\n  File \"xlink_core.pyx\", line 697, in xlink_core.Main4\n  File \"\/opt\/openfbi\/fbi-bin\/addones\/streams\/yuan_http.py\", line 422, in Events\n    \"account\": re_acc,\n               ^^^^^^\nUnboundLocalError: cannot access local variable 'user_info' where it is not associated with a value\n","operate_result":"错误","failed_reason":"cannot access local variable 'user_info' where it is not associated with a value"}
{"user":"x_finder3","timestamp":"2024-04-25T11:13:17.585316","nav_name":"yuan_http","action":"事件处理出错","params":"错误跟踪：Traceback (most recent call last):\n  File \"xlink_core.pyx\", line 697, in xlink_core.Main4\n  File \"\/opt\/openfbi\/fbi-bin\/addones\/streams\/yuan_http.py\", line 422, in Events\n    \"account\": re_acc,\n               ^^^^^^\nUnboundLocalError: cannot access local variable 'user_info' where it is not associated with a value\n","operate_result":"错误","failed_reason":"cannot access local variable 'user_info' where it is not associated with a value"}
{"user":"x_finder3","timestamp":"2024-04-25T11:13:18.184278","nav_name":"yuan_http","action":"事件处理出错","params":"错误跟踪：Traceback (most recent call last):\n  File \"xlink_core.pyx\", line 697, in xlink_core.Main4\n  File \"\/opt\/openfbi\/fbi-bin\/addones\/streams\/yuan_http.py\", line 422, in Events\n    \"account\": re_acc,\n               ^^^^^^\nUnboundLocalError: cannot access local variable 'user_info' where it is not associated with a value\n","operate_result":"错误","failed_reason":"cannot access local variable 'user_info' where it is not associated with a value"}
{"user":"x_finder3","timestamp":"2024-04-25T11:13:18.185232","nav_name":"yuan_http","action":"事件处理出错","params":"错误跟踪：Traceback (most recent call last):\n  File \"xlink_core.pyx\", line 697, in xlink_core.Main4\n  File \"\/opt\/openfbi\/fbi-bin\/addones\/streams\/yuan_http.py\", line 422, in Events\n    \"account\": re_acc,\n               ^^^^^^\nUnboundLocalError: cannot access local variable 'user_info' where it is not associated with a value\n","operate_result":"错误","failed_reason":"cannot access local variable 'user_info' where it is not associated with a value"}
{"user":"x_finder3","timestamp":"2024-04-25T11:13:18.186158","nav_name":"yuan_http","action":"事件处理出错","params":"错误跟踪：Traceback (most recent call last):\n  File \"xlink_core.pyx\", line 697, in xlink_core.Main4\n  File \"\/opt\/openfbi\/fbi-bin\/addones\/streams\/yuan_http.py\", line 422, in Events\n    \"account\": re_acc,\n               ^^^^^^\nUnboundLocalError: cannot access local variable 'user_info' where it is not associated with a value\n","operate_result":"错误","failed_reason":"cannot access local variable 'user_info' where it is not associated with a value"}
{"user":"x_finder3","timestamp":"2024-04-25T11:13:21.267690","nav_name":"yuan_http","action":"事件处理出错","params":"错误跟踪：Traceback (most recent call last):\n  File \"xlink_core.pyx\", line 697, in xlink_core.Main4\n  File \"\/opt\/openfbi\/fbi-bin\/addones\/streams\/yuan_http.py\", line 422, in Events\n    \"account\": re_acc,\n               ^^^^^^\nUnboundLocalError: cannot access local variable 'user_info' where it is not associated with a value\n","operate_result":"错误","failed_reason":"cannot access local variable 'user_info' where it is not associated with a value"}
{"user":"x_finder3","timestamp":"2024-04-25T11:13:21.309406","nav_name":"yuan_http","action":"事件处理出错","params":"错误跟踪：Traceback (most recent call last):\n  File \"xlink_core.pyx\", line 697, in xlink_core.Main4\n  File \"\/opt\/openfbi\/fbi-bin\/addones\/streams\/yuan_http.py\", line 422, in Events\n    \"account\": re_acc,\n               ^^^^^^\nUnboundLocalError: cannot access local variable 'user_info' where it is not associated with a value\n","operate_result":"错误","failed_reason":"cannot access local variable 'user_info' where it is not associated with a value"}
{"user":"x_finder3","timestamp":"2024-04-25T11:13:23.134536","nav_name":"yuan_http","action":"事件处理出错","params":"错误跟踪：Traceback (most recent call last):\n  File \"xlink_core.pyx\", line 697, in xlink_core.Main4\n  File \"\/opt\/openfbi\/fbi-bin\/addones\/streams\/yuan_http.py\", line 422, in Events\n    \"account\": re_acc,\n               ^^^^^^\nUnboundLocalError: cannot access local variable 'user_info' where it is not associated with a value\n","operate_result":"错误","failed_reason":"cannot access local variable 'user_info' where it is not associated with a value"}
{"user":"x_finder3","timestamp":"2024-04-25T11:13:23.135534","nav_name":"yuan_http","action":"事件处理出错","params":"错误跟踪：Traceback (most recent call last):\n  File \"xlink_core.pyx\", line 697, in xlink_core.Main4\n  File \"\/opt\/openfbi\/fbi-bin\/addones\/streams\/yuan_http.py\", line 422, in Events\n    \"account\": re_acc,\n               ^^^^^^\nUnboundLocalError: cannot access local variable 'user_info' where it is not associated with a value\n","operate_result":"错误","failed_reason":"cannot access local variable 'user_info' where it is not associated with a value"}
{"user":"x_finder3","timestamp":"2024-04-25T11:13:23.136492","nav_name":"yuan_http","action":"事件处理出错","params":"错误跟踪：Traceback (most recent call last):\n  File \"xlink_core.pyx\", line 697, in xlink_core.Main4\n  File \"\/opt\/openfbi\/fbi-bin\/addones\/streams\/yuan_http.py\", line 422, in Events\n    \"account\": re_acc,\n               ^^^^^^\nUnboundLocalError: cannot access local variable 'user_info' where it is not associated with a value\n","operate_result":"错误","failed_reason":"cannot access local variable 'user_info' where it is not associated with a value"}
{"user":"x_finder3","timestamp":"2024-04-25T11:13:24.292234","nav_name":"yuan_http","action":"事件处理出错","params":"错误跟踪：Traceback (most recent call last):\n  File \"xlink_core.pyx\", line 697, in xlink_core.Main4\n  File \"\/opt\/openfbi\/fbi-bin\/addones\/streams\/yuan_http.py\", line 422, in Events\n    \"account\": re_acc,\n               ^^^^^^\nUnboundLocalError: cannot access local variable 'user_info' where it is not associated with a value\n","operate_result":"错误","failed_reason":"cannot access local variable 'user_info' where it is not associated with a value"}
{"user":"x_finder3","timestamp":"2024-04-25T11:13:26.360526","nav_name":"yuan_http","action":"事件处理出错","params":"错误跟踪：Traceback (most recent call last):\n  File \"xlink_core.pyx\", line 697, in xlink_core.Main4\n  File \"\/opt\/openfbi\/fbi-bin\/addones\/streams\/yuan_http.py\", line 422, in Events\n    \"account\": re_acc,\n               ^^^^^^\nUnboundLocalError: cannot access local variable 'user_info' where it is not associated with a value\n","operate_result":"错误","failed_reason":"cannot access local variable 'user_info' where it is not associated with a value"}
{"user":"x_finder3","timestamp":"2024-04-25T11:13:27.222248","nav_name":"yuan_http","action":"事件处理出错","params":"错误跟踪：Traceback (most recent call last):\n  File \"xlink_core.pyx\", line 697, in xlink_core.Main4\n  File \"\/opt\/openfbi\/fbi-bin\/addones\/streams\/yuan_http.py\", line 422, in Events\n    \"account\": re_acc,\n               ^^^^^^\nUnboundLocalError: cannot access local variable 'user_info' where it is not associated with a value\n","operate_result":"错误","failed_reason":"cannot access local variable 'user_info' where it is not associated with a value"}
{"user":"x_finder3","timestamp":"2024-04-25T11:13:28.165247","nav_name":"yuan_http","action":"事件处理出错","params":"错误跟踪：Traceback (most recent call last):\n  File \"xlink_core.pyx\", line 697, in xlink_core.Main4\n  File \"\/opt\/openfbi\/fbi-bin\/addones\/streams\/yuan_http.py\", line 422, in Events\n    \"account\": re_acc,\n               ^^^^^^\nUnboundLocalError: cannot access local variable 'user_info' where it is not associated with a value\n","operate_result":"错误","failed_reason":"cannot access local variable 'user_info' where it is not associated with a value"}
{"user":"x_finder3","timestamp":"2024-04-25T11:13:28.166253","nav_name":"yuan_http","action":"事件处理出错","params":"错误跟踪：Traceback (most recent call last):\n  File \"xlink_core.pyx\", line 697, in xlink_core.Main4\n  File \"\/opt\/openfbi\/fbi-bin\/addones\/streams\/yuan_http.py\", line 422, in Events\n    \"account\": re_acc,\n               ^^^^^^\nUnboundLocalError: cannot access local variable 'user_info' where it is not associated with a value\n","operate_result":"错误","failed_reason":"cannot access local variable 'user_info' where it is not associated with a value"}
{"user":"x_finder3","timestamp":"2024-04-25T11:13:28.167179","nav_name":"yuan_http","action":"事件处理出错","params":"错误跟踪：Traceback (most recent call last):\n  File \"xlink_core.pyx\", line 697, in xlink_core.Main4\n  File \"\/opt\/openfbi\/fbi-bin\/addones\/streams\/yuan_http.py\", line 422, in Events\n    \"account\": re_acc,\n               ^^^^^^\nUnboundLocalError: cannot access local variable 'user_info' where it is not associated with a value\n","operate_result":"错误","failed_reason":"cannot access local variable 'user_info' where it is not associated with a value"}
{"user":"x_finder3","timestamp":"2024-04-25T11:13:30.297174","nav_name":"yuan_http","action":"事件处理出错","params":"错误跟踪：Traceback (most recent call last):\n  File \"xlink_core.pyx\", line 697, in xlink_core.Main4\n  File \"\/opt\/openfbi\/fbi-bin\/addones\/streams\/yuan_http.py\", line 422, in Events\n    \"account\": re_acc,\n               ^^^^^^\nUnboundLocalError: cannot access local variable 'user_info' where it is not associated with a value\n","operate_result":"错误","failed_reason":"cannot access local variable 'user_info' where it is not associated with a value"}
{"user":"x_finder3","timestamp":"2024-04-25T11:13:30.906519","nav_name":"yuan_http","action":"事件处理出错","params":"错误跟踪：Traceback (most recent call last):\n  File \"xlink_core.pyx\", line 697, in xlink_core.Main4\n  File \"\/opt\/openfbi\/fbi-bin\/addones\/streams\/yuan_http.py\", line 422, in Events\n    \"account\": re_acc,\n               ^^^^^^\nUnboundLocalError: cannot access local variable 'user_info' where it is not associated with a value\n","operate_result":"错误","failed_reason":"cannot access local variable 'user_info' where it is not associated with a value"}
{"user":"x_finder3","timestamp":"2024-04-25T11:13:30.958215","nav_name":"yuan_http","action":"事件处理出错","params":"错误跟踪：Traceback (most recent call last):\n  File \"xlink_core.pyx\", line 697, in xlink_core.Main4\n  File \"\/opt\/openfbi\/fbi-bin\/addones\/streams\/yuan_http.py\", line 422, in Events\n    \"account\": re_acc,\n               ^^^^^^\nUnboundLocalError: cannot access local variable 'user_info' where it is not associated with a value\n","operate_result":"错误","failed_reason":"cannot access local variable 'user_info' where it is not associated with a value"}
{"user":"x_finder3","timestamp":"2024-04-25T11:13:31.009882","nav_name":"yuan_http","action":"事件处理出错","params":"错误跟踪：Traceback (most recent call last):\n  File \"xlink_core.pyx\", line 697, in xlink_core.Main4\n  File \"\/opt\/openfbi\/fbi-bin\/addones\/streams\/yuan_http.py\", line 422, in Events\n    \"account\": re_acc,\n               ^^^^^^\nUnboundLocalError: cannot access local variable 'user_info' where it is not associated with a value\n","operate_result":"错误","failed_reason":"cannot access local variable 'user_info' where it is not associated with a value"}
{"user":"x_finder3","timestamp":"2024-04-25T11:13:31.010934","nav_name":"yuan_http","action":"事件处理出错","params":"错误跟踪：Traceback (most recent call last):\n  File \"xlink_core.pyx\", line 697, in xlink_core.Main4\n  File \"\/opt\/openfbi\/fbi-bin\/addones\/streams\/yuan_http.py\", line 422, in Events\n    \"account\": re_acc,\n               ^^^^^^\nUnboundLocalError: cannot access local variable 'user_info' where it is not associated with a value\n","operate_result":"错误","failed_reason":"cannot access local variable 'user_info' where it is not associated with a value"}
{"user":"x_finder3","timestamp":"2024-04-25T11:13:31.367018","nav_name":"yuan_http","action":"事件处理出错","params":"错误跟踪：Traceback (most recent call last):\n  File \"xlink_core.pyx\", line 697, in xlink_core.Main4\n  File \"\/opt\/openfbi\/fbi-bin\/addones\/streams\/yuan_http.py\", line 422, in Events\n    \"account\": re_acc,\n               ^^^^^^\nUnboundLocalError: cannot access local variable 'user_info' where it is not associated with a value\n","operate_result":"错误","failed_reason":"cannot access local variable 'user_info' where it is not associated with a value"}
{"user":"x_finder3","timestamp":"2024-04-25T11:13:31.864844","nav_name":"yuan_http","action":"事件处理出错","params":"错误跟踪：Traceback (most recent call last):\n  File \"xlink_core.pyx\", line 697, in xlink_core.Main4\n  File \"\/opt\/openfbi\/fbi-bin\/addones\/streams\/yuan_http.py\", line 422, in Events\n    \"account\": re_acc,\n               ^^^^^^\nUnboundLocalError: cannot access local variable 'user_info' where it is not associated with a value\n","operate_result":"错误","failed_reason":"cannot access local variable 'user_info' where it is not associated with a value"}
{"user":"x_finder3","timestamp":"2024-04-25T11:13:31.865900","nav_name":"yuan_http","action":"事件处理出错","params":"错误跟踪：Traceback (most recent call last):\n  File \"xlink_core.pyx\", line 697, in xlink_core.Main4\n  File \"\/opt\/openfbi\/fbi-bin\/addones\/streams\/yuan_http.py\", line 422, in Events\n    \"account\": re_acc,\n               ^^^^^^\nUnboundLocalError: cannot access local variable 'user_info' where it is not associated with a value\n","operate_result":"错误","failed_reason":"cannot access local variable 'user_info' where it is not associated with a value"}
{"user":"x_finder3","timestamp":"2024-04-25T11:13:31.866811","nav_name":"yuan_http","action":"事件处理出错","params":"错误跟踪：Traceback (most recent call last):\n  File \"xlink_core.pyx\", line 697, in xlink_core.Main4\n  File \"\/opt\/openfbi\/fbi-bin\/addones\/streams\/yuan_http.py\", line 422, in Events\n    \"account\": re_acc,\n               ^^^^^^\nUnboundLocalError: cannot access local variable 'user_info' where it is not associated with a value\n","operate_result":"错误","failed_reason":"cannot access local variable 'user_info' where it is not associated with a value"}
{"user":"x_finder3","timestamp":"2024-04-25T11:13:32.019857","nav_name":"yuan_http","action":"事件处理出错","params":"错误跟踪：Traceback (most recent call last):\n  File \"xlink_core.pyx\", line 697, in xlink_core.Main4\n  File \"\/opt\/openfbi\/fbi-bin\/addones\/streams\/yuan_http.py\", line 422, in Events\n    \"account\": re_acc,\n               ^^^^^^\nUnboundLocalError: cannot access local variable 'user_info' where it is not associated with a value\n","operate_result":"错误","failed_reason":"cannot access local variable 'user_info' where it is not associated with a value"}
{"user":"x_finder3","timestamp":"2024-04-25T11:13:32.578223","nav_name":"yuan_http","action":"事件处理出错","params":"错误跟踪：Traceback (most recent call last):\n  File \"xlink_core.pyx\", line 697, in xlink_core.Main4\n  File \"\/opt\/openfbi\/fbi-bin\/addones\/streams\/yuan_http.py\", line 422, in Events\n    \"account\": re_acc,\n               ^^^^^^\nUnboundLocalError: cannot access local variable 'user_info' where it is not associated with a value\n","operate_result":"错误","failed_reason":"cannot access local variable 'user_info' where it is not associated with a value"}
{"user":"x_finder3","timestamp":"2024-04-25T11:13:32.731475","nav_name":"yuan_http","action":"事件处理出错","params":"错误跟踪：Traceback (most recent call last):\n  File \"xlink_core.pyx\", line 697, in xlink_core.Main4\n  File \"\/opt\/openfbi\/fbi-bin\/addones\/streams\/yuan_http.py\", line 422, in Events\n    \"account\": re_acc,\n               ^^^^^^\nUnboundLocalError: cannot access local variable 'user_info' where it is not associated with a value\n","operate_result":"错误","failed_reason":"cannot access local variable 'user_info' where it is not associated with a value"}
{"user":"x_finder3","timestamp":"2024-04-25T11:13:32.732444","nav_name":"yuan_http","action":"事件处理出错","params":"错误跟踪：Traceback (most recent call last):\n  File \"xlink_core.pyx\", line 697, in xlink_core.Main4\n  File \"\/opt\/openfbi\/fbi-bin\/addones\/streams\/yuan_http.py\", line 422, in Events\n    \"account\": re_acc,\n               ^^^^^^\nUnboundLocalError: cannot access local variable 'user_info' where it is not associated with a value\n","operate_result":"错误","failed_reason":"cannot access local variable 'user_info' where it is not associated with a value"}
{"user":"x_finder3","timestamp":"2024-04-25T11:13:32.733429","nav_name":"yuan_http","action":"事件处理出错","params":"错误跟踪：Traceback (most recent call last):\n  File \"xlink_core.pyx\", line 697, in xlink_core.Main4\n  File \"\/opt\/openfbi\/fbi-bin\/addones\/streams\/yuan_http.py\", line 422, in Events\n    \"account\": re_acc,\n               ^^^^^^\nUnboundLocalError: cannot access local variable 'user_info' where it is not associated with a value\n","operate_result":"错误","failed_reason":"cannot access local variable 'user_info' where it is not associated with a value"}
{"user":"x_finder3","timestamp":"2024-04-25T11:13:32.775089","nav_name":"yuan_http","action":"事件处理出错","params":"错误跟踪：Traceback (most recent call last):\n  File \"xlink_core.pyx\", line 697, in xlink_core.Main4\n  File \"\/opt\/openfbi\/fbi-bin\/addones\/streams\/yuan_http.py\", line 422, in Events\n    \"account\": re_acc,\n               ^^^^^^\nUnboundLocalError: cannot access local variable 'user_info' where it is not associated with a value\n","operate_result":"错误","failed_reason":"cannot access local variable 'user_info' where it is not associated with a value"}
{"user":"x_finder3","timestamp":"2024-04-25T11:13:33.131079","nav_name":"yuan_http","action":"事件处理出错","params":"错误跟踪：Traceback (most recent call last):\n  File \"xlink_core.pyx\", line 697, in xlink_core.Main4\n  File \"\/opt\/openfbi\/fbi-bin\/addones\/streams\/yuan_http.py\", line 422, in Events\n    \"account\": re_acc,\n               ^^^^^^\nUnboundLocalError: cannot access local variable 'user_info' where it is not associated with a value\n","operate_result":"错误","failed_reason":"cannot access local variable 'user_info' where it is not associated with a value"}
{"user":"x_finder3","timestamp":"2024-04-25T11:13:33.132063","nav_name":"yuan_http","action":"事件处理出错","params":"错误跟踪：Traceback (most recent call last):\n  File \"xlink_core.pyx\", line 697, in xlink_core.Main4\n  File \"\/opt\/openfbi\/fbi-bin\/addones\/streams\/yuan_http.py\", line 422, in Events\n    \"account\": re_acc,\n               ^^^^^^\nUnboundLocalError: cannot access local variable 'user_info' where it is not associated with a value\n","operate_result":"错误","failed_reason":"cannot access local variable 'user_info' where it is not associated with a value"}
{"user":"x_finder3","timestamp":"2024-04-25T11:13:33.133022","nav_name":"yuan_http","action":"事件处理出错","params":"错误跟踪：Traceback (most recent call last):\n  File \"xlink_core.pyx\", line 697, in xlink_core.Main4\n  File \"\/opt\/openfbi\/fbi-bin\/addones\/streams\/yuan_http.py\", line 422, in Events\n    \"account\": re_acc,\n               ^^^^^^\nUnboundLocalError: cannot access local variable 'user_info' where it is not associated with a value\n","operate_result":"错误","failed_reason":"cannot access local variable 'user_info' where it is not associated with a value"}
{"user":"x_finder3","timestamp":"2024-04-25T11:13:33.286279","nav_name":"yuan_http","action":"事件处理出错","params":"错误跟踪：Traceback (most recent call last):\n  File \"xlink_core.pyx\", line 697, in xlink_core.Main4\n  File \"\/opt\/openfbi\/fbi-bin\/addones\/streams\/yuan_http.py\", line 422, in Events\n    \"account\": re_acc,\n               ^^^^^^\nUnboundLocalError: cannot access local variable 'user_info' where it is not associated with a value\n","operate_result":"错误","failed_reason":"cannot access local variable 'user_info' where it is not associated with a value"}
{"user":"x_finder3","timestamp":"2024-04-25T11:13:36.306251","nav_name":"yuan_http","action":"事件处理出错","params":"错误跟踪：Traceback (most recent call last):\n  File \"xlink_core.pyx\", line 697, in xlink_core.Main4\n  File \"\/opt\/openfbi\/fbi-bin\/addones\/streams\/yuan_http.py\", line 422, in Events\n    \"account\": re_acc,\n               ^^^^^^\nUnboundLocalError: cannot access local variable 'user_info' where it is not associated with a value\n","operate_result":"错误","failed_reason":"cannot access local variable 'user_info' where it is not associated with a value"}
{"user":"x_finder3","timestamp":"2024-04-25T11:13:36.358058","nav_name":"yuan_http","action":"事件处理出错","params":"错误跟踪：Traceback (most recent call last):\n  File \"xlink_core.pyx\", line 697, in xlink_core.Main4\n  File \"\/opt\/openfbi\/fbi-bin\/addones\/streams\/yuan_http.py\", line 422, in Events\n    \"account\": re_acc,\n               ^^^^^^\nUnboundLocalError: cannot access local variable 'user_info' where it is not associated with a value\n","operate_result":"错误","failed_reason":"cannot access local variable 'user_info' where it is not associated with a value"}
{"user":"x_finder3","timestamp":"2024-04-25T11:13:38.172902","nav_name":"yuan_http","action":"事件处理出错","params":"错误跟踪：Traceback (most recent call last):\n  File \"xlink_core.pyx\", line 697, in xlink_core.Main4\n  File \"\/opt\/openfbi\/fbi-bin\/addones\/streams\/yuan_http.py\", line 422, in Events\n    \"account\": re_acc,\n               ^^^^^^\nUnboundLocalError: cannot access local variable 'user_info' where it is not associated with a value\n","operate_result":"错误","failed_reason":"cannot access local variable 'user_info' where it is not associated with a value"}
{"user":"x_finder3","timestamp":"2024-04-25T11:13:38.173876","nav_name":"yuan_http","action":"事件处理出错","params":"错误跟踪：Traceback (most recent call last):\n  File \"xlink_core.pyx\", line 697, in xlink_core.Main4\n  File \"\/opt\/openfbi\/fbi-bin\/addones\/streams\/yuan_http.py\", line 422, in Events\n    \"account\": re_acc,\n               ^^^^^^\nUnboundLocalError: cannot access local variable 'user_info' where it is not associated with a value\n","operate_result":"错误","failed_reason":"cannot access local variable 'user_info' where it is not associated with a value"}
{"user":"x_finder3","timestamp":"2024-04-25T11:13:38.174865","nav_name":"yuan_http","action":"事件处理出错","params":"错误跟踪：Traceback (most recent call last):\n  File \"xlink_core.pyx\", line 697, in xlink_core.Main4\n  File \"\/opt\/openfbi\/fbi-bin\/addones\/streams\/yuan_http.py\", line 422, in Events\n    \"account\": re_acc,\n               ^^^^^^\nUnboundLocalError: cannot access local variable 'user_info' where it is not associated with a value\n","operate_result":"错误","failed_reason":"cannot access local variable 'user_info' where it is not associated with a value"}
{"user":"x_finder3","timestamp":"2024-04-25T11:13:39.229460","nav_name":"yuan_http","action":"事件处理出错","params":"错误跟踪：Traceback (most recent call last):\n  File \"xlink_core.pyx\", line 697, in xlink_core.Main4\n  File \"\/opt\/openfbi\/fbi-bin\/addones\/streams\/yuan_http.py\", line 422, in Events\n    \"account\": re_acc,\n               ^^^^^^\nUnboundLocalError: cannot access local variable 'user_info' where it is not associated with a value\n","operate_result":"错误","failed_reason":"cannot access local variable 'user_info' where it is not associated with a value"}
{"user":"x_finder3","timestamp":"2024-04-25T11:13:40.081876","nav_name":"yuan_http","action":"事件处理出错","params":"错误跟踪：Traceback (most recent call last):\n  File \"xlink_core.pyx\", line 697, in xlink_core.Main4\n  File \"\/opt\/openfbi\/fbi-bin\/addones\/streams\/yuan_http.py\", line 422, in Events\n    \"account\": re_acc,\n               ^^^^^^\nUnboundLocalError: cannot access local variable 'user_info' where it is not associated with a value\n","operate_result":"错误","failed_reason":"cannot access local variable 'user_info' where it is not associated with a value"}
{"user":"x_finder3","timestamp":"2024-04-25T11:13:40.184468","nav_name":"yuan_http","action":"事件处理出错","params":"错误跟踪：Traceback (most recent call last):\n  File \"xlink_core.pyx\", line 697, in xlink_core.Main4\n  File \"\/opt\/openfbi\/fbi-bin\/addones\/streams\/yuan_http.py\", line 422, in Events\n    \"account\": re_acc,\n               ^^^^^^\nUnboundLocalError: cannot access local variable 'user_info' where it is not associated with a value\n","operate_result":"错误","failed_reason":"cannot access local variable 'user_info' where it is not associated with a value"}
{"user":"x_finder3","timestamp":"2024-04-25T11:13:40.185474","nav_name":"yuan_http","action":"事件处理出错","params":"错误跟踪：Traceback (most recent call last):\n  File \"xlink_core.pyx\", line 697, in xlink_core.Main4\n  File \"\/opt\/openfbi\/fbi-bin\/addones\/streams\/yuan_http.py\", line 422, in Events\n    \"account\": re_acc,\n               ^^^^^^\nUnboundLocalError: cannot access local variable 'user_info' where it is not associated with a value\n","operate_result":"错误","failed_reason":"cannot access local variable 'user_info' where it is not associated with a value"}
{"user":"x_finder3","timestamp":"2024-04-25T11:13:40.247630","nav_name":"yuan_http","action":"事件处理出错","params":"错误跟踪：Traceback (most recent call last):\n  File \"xlink_core.pyx\", line 697, in xlink_core.Main4\n  File \"\/opt\/openfbi\/fbi-bin\/addones\/streams\/yuan_http.py\", line 422, in Events\n    \"account\": re_acc,\n               ^^^^^^\nUnboundLocalError: cannot access local variable 'user_info' where it is not associated with a value\n","operate_result":"错误","failed_reason":"cannot access local variable 'user_info' where it is not associated with a value"}
{"user":"x_finder3","timestamp":"2024-04-25T11:13:41.394159","nav_name":"yuan_http","action":"事件处理出错","params":"错误跟踪：Traceback (most recent call last):\n  File \"xlink_core.pyx\", line 697, in xlink_core.Main4\n  File \"\/opt\/openfbi\/fbi-bin\/addones\/streams\/yuan_http.py\", line 422, in Events\n    \"account\": re_acc,\n               ^^^^^^\nUnboundLocalError: cannot access local variable 'user_info' where it is not associated with a value\n","operate_result":"错误","failed_reason":"cannot access local variable 'user_info' where it is not associated with a value"}
{"user":"x_finder3","timestamp":"2024-04-25T11:13:42.256419","nav_name":"yuan_http","action":"事件处理出错","params":"错误跟踪：Traceback (most recent call last):\n  File \"xlink_core.pyx\", line 697, in xlink_core.Main4\n  File \"\/opt\/openfbi\/fbi-bin\/addones\/streams\/yuan_http.py\", line 422, in Events\n    \"account\": re_acc,\n               ^^^^^^\nUnboundLocalError: cannot access local variable 'user_info' where it is not associated with a value\n","operate_result":"错误","failed_reason":"cannot access local variable 'user_info' where it is not associated with a value"}
{"user":"x_finder3","timestamp":"2024-04-25T11:13:43.169592","nav_name":"yuan_http","action":"事件处理出错","params":"错误跟踪：Traceback (most recent call last):\n  File \"xlink_core.pyx\", line 697, in xlink_core.Main4\n  File \"\/opt\/openfbi\/fbi-bin\/addones\/streams\/yuan_http.py\", line 422, in Events\n    \"account\": re_acc,\n               ^^^^^^\nUnboundLocalError: cannot access local variable 'user_info' where it is not associated with a value\n","operate_result":"错误","failed_reason":"cannot access local variable 'user_info' where it is not associated with a value"}
{"user":"x_finder3","timestamp":"2024-04-25T11:13:43.170585","nav_name":"yuan_http","action":"事件处理出错","params":"错误跟踪：Traceback (most recent call last):\n  File \"xlink_core.pyx\", line 697, in xlink_core.Main4\n  File \"\/opt\/openfbi\/fbi-bin\/addones\/streams\/yuan_http.py\", line 422, in Events\n    \"account\": re_acc,\n               ^^^^^^\nUnboundLocalError: cannot access local variable 'user_info' where it is not associated with a value\n","operate_result":"错误","failed_reason":"cannot access local variable 'user_info' where it is not associated with a value"}
{"user":"x_finder3","timestamp":"2024-04-25T11:13:43.171560","nav_name":"yuan_http","action":"事件处理出错","params":"错误跟踪：Traceback (most recent call last):\n  File \"xlink_core.pyx\", line 697, in xlink_core.Main4\n  File \"\/opt\/openfbi\/fbi-bin\/addones\/streams\/yuan_http.py\", line 422, in Events\n    \"account\": re_acc,\n               ^^^^^^\nUnboundLocalError: cannot access local variable 'user_info' where it is not associated with a value\n","operate_result":"错误","failed_reason":"cannot access local variable 'user_info' where it is not associated with a value"}
{"user":"x_finder3","timestamp":"2024-04-25T11:13:44.115160","nav_name":"yuan_http","action":"事件处理出错","params":"错误跟踪：Traceback (most recent call last):\n  File \"xlink_core.pyx\", line 697, in xlink_core.Main4\n  File \"\/opt\/openfbi\/fbi-bin\/addones\/streams\/yuan_http.py\", line 422, in Events\n    \"account\": re_acc,\n               ^^^^^^\nUnboundLocalError: cannot access local variable 'user_info' where it is not associated with a value\n","operate_result":"错误","failed_reason":"cannot access local variable 'user_info' where it is not associated with a value"}
{"user":"x_finder3","timestamp":"2024-04-25T11:13:44.116136","nav_name":"yuan_http","action":"事件处理出错","params":"错误跟踪：Traceback (most recent call last):\n  File \"xlink_core.pyx\", line 697, in xlink_core.Main4\n  File \"\/opt\/openfbi\/fbi-bin\/addones\/streams\/yuan_http.py\", line 422, in Events\n    \"account\": re_acc,\n               ^^^^^^\nUnboundLocalError: cannot access local variable 'user_info' where it is not associated with a value\n","operate_result":"错误","failed_reason":"cannot access local variable 'user_info' where it is not associated with a value"}
{"user":"x_finder3","timestamp":"2024-04-25T11:13:44.269265","nav_name":"yuan_http","action":"事件处理出错","params":"错误跟踪：Traceback (most recent call last):\n  File \"xlink_core.pyx\", line 697, in xlink_core.Main4\n  File \"\/opt\/openfbi\/fbi-bin\/addones\/streams\/yuan_http.py\", line 422, in Events\n    \"account\": re_acc,\n               ^^^^^^\nUnboundLocalError: cannot access local variable 'user_info' where it is not associated with a value\n","operate_result":"错误","failed_reason":"cannot access local variable 'user_info' where it is not associated with a value"}
{"user":"x_finder3","timestamp":"2024-04-25T11:13:45.283953","nav_name":"yuan_http","action":"事件处理出错","params":"错误跟踪：Traceback (most recent call last):\n  File \"xlink_core.pyx\", line 697, in xlink_core.Main4\n  File \"\/opt\/openfbi\/fbi-bin\/addones\/streams\/yuan_http.py\", line 422, in Events\n    \"account\": re_acc,\n               ^^^^^^\nUnboundLocalError: cannot access local variable 'user_info' where it is not associated with a value\n","operate_result":"错误","failed_reason":"cannot access local variable 'user_info' where it is not associated with a value"}
{"user":"x_finder3","timestamp":"2024-04-25T11:13:46.399473","nav_name":"yuan_http","action":"事件处理出错","params":"错误跟踪：Traceback (most recent call last):\n  File \"xlink_core.pyx\", line 697, in xlink_core.Main4\n  File \"\/opt\/openfbi\/fbi-bin\/addones\/streams\/yuan_http.py\", line 422, in Events\n    \"account\": re_acc,\n               ^^^^^^\nUnboundLocalError: cannot access local variable 'user_info' where it is not associated with a value\n","operate_result":"错误","failed_reason":"cannot access local variable 'user_info' where it is not associated with a value"}
{"user":"x_finder3","timestamp":"2024-04-25T11:13:47.291975","nav_name":"yuan_http","action":"事件处理出错","params":"错误跟踪：Traceback (most recent call last):\n  File \"xlink_core.pyx\", line 697, in xlink_core.Main4\n  File \"\/opt\/openfbi\/fbi-bin\/addones\/streams\/yuan_http.py\", line 422, in Events\n    \"account\": re_acc,\n               ^^^^^^\nUnboundLocalError: cannot access local variable 'user_info' where it is not associated with a value\n","operate_result":"错误","failed_reason":"cannot access local variable 'user_info' where it is not associated with a value"}
{"user":"x_finder3","timestamp":"2024-04-25T11:13:47.292921","nav_name":"yuan_http","action":"事件处理出错","params":"错误跟踪：Traceback (most recent call last):\n  File \"xlink_core.pyx\", line 697, in xlink_core.Main4\n  File \"\/opt\/openfbi\/fbi-bin\/addones\/streams\/yuan_http.py\", line 422, in Events\n    \"account\": re_acc,\n               ^^^^^^\nUnboundLocalError: cannot access local variable 'user_info' where it is not associated with a value\n","operate_result":"错误","failed_reason":"cannot access local variable 'user_info' where it is not associated with a value"}
{"user":"x_finder3","timestamp":"2024-04-25T11:13:47.293833","nav_name":"yuan_http","action":"事件处理出错","params":"错误跟踪：Traceback (most recent call last):\n  File \"xlink_core.pyx\", line 697, in xlink_core.Main4\n  File \"\/opt\/openfbi\/fbi-bin\/addones\/streams\/yuan_http.py\", line 422, in Events\n    \"account\": re_acc,\n               ^^^^^^\nUnboundLocalError: cannot access local variable 'user_info' where it is not associated with a value\n","operate_result":"错误","failed_reason":"cannot access local variable 'user_info' where it is not associated with a value"}
{"user":"x_finder3","timestamp":"2024-04-25T11:13:47.294761","nav_name":"yuan_http","action":"事件处理出错","params":"错误跟踪：Traceback (most recent call last):\n  File \"xlink_core.pyx\", line 697, in xlink_core.Main4\n  File \"\/opt\/openfbi\/fbi-bin\/addones\/streams\/yuan_http.py\", line 422, in Events\n    \"account\": re_acc,\n               ^^^^^^\nUnboundLocalError: cannot access local variable 'user_info' where it is not associated with a value\n","operate_result":"错误","failed_reason":"cannot access local variable 'user_info' where it is not associated with a value"}
{"user":"x_finder3","timestamp":"2024-04-25T11:13:47.295650","nav_name":"yuan_http","action":"事件处理出错","params":"错误跟踪：Traceback (most recent call last):\n  File \"xlink_core.pyx\", line 697, in xlink_core.Main4\n  File \"\/opt\/openfbi\/fbi-bin\/addones\/streams\/yuan_http.py\", line 422, in Events\n    \"account\": re_acc,\n               ^^^^^^\nUnboundLocalError: cannot access local variable 'user_info' where it is not associated with a value\n","operate_result":"错误","failed_reason":"cannot access local variable 'user_info' where it is not associated with a value"}
{"user":"x_finder3","timestamp":"2024-04-25T11:13:47.296605","nav_name":"yuan_http","action":"事件处理出错","params":"错误跟踪：Traceback (most recent call last):\n  File \"xlink_core.pyx\", line 697, in xlink_core.Main4\n  File \"\/opt\/openfbi\/fbi-bin\/addones\/streams\/yuan_http.py\", line 422, in Events\n    \"account\": re_acc,\n               ^^^^^^\nUnboundLocalError: cannot access local variable 'user_info' where it is not associated with a value\n","operate_result":"错误","failed_reason":"cannot access local variable 'user_info' where it is not associated with a value"}
{"user":"x_finder3","timestamp":"2024-04-25T11:13:47.297489","nav_name":"yuan_http","action":"事件处理出错","params":"错误跟踪：Traceback (most recent call last):\n  File \"xlink_core.pyx\", line 697, in xlink_core.Main4\n  File \"\/opt\/openfbi\/fbi-bin\/addones\/streams\/yuan_http.py\", line 422, in Events\n    \"account\": re_acc,\n               ^^^^^^\nUnboundLocalError: cannot access local variable 'user_info' where it is not associated with a value\n","operate_result":"错误","failed_reason":"cannot access local variable 'user_info' where it is not associated with a value"}
{"user":"x_finder3","timestamp":"2024-04-25T11:13:47.298983","nav_name":"yuan_http","action":"事件处理出错","params":"错误跟踪：Traceback (most recent call last):\n  File \"xlink_core.pyx\", line 697, in xlink_core.Main4\n  File \"\/opt\/openfbi\/fbi-bin\/addones\/streams\/yuan_http.py\", line 422, in Events\n    \"account\": re_acc,\n               ^^^^^^\nUnboundLocalError: cannot access local variable 'user_info' where it is not associated with a value\n","operate_result":"错误","failed_reason":"cannot access local variable 'user_info' where it is not associated with a value"}
{"user":"x_finder3","timestamp":"2024-04-25T11:13:47.299855","nav_name":"yuan_http","action":"事件处理出错","params":"错误跟踪：Traceback (most recent call last):\n  File \"xlink_core.pyx\", line 697, in xlink_core.Main4\n  File \"\/opt\/openfbi\/fbi-bin\/addones\/streams\/yuan_http.py\", line 422, in Events\n    \"account\": re_acc,\n               ^^^^^^\nUnboundLocalError: cannot access local variable 'user_info' where it is not associated with a value\n","operate_result":"错误","failed_reason":"cannot access local variable 'user_info' where it is not associated with a value"}
{"user":"x_finder3","timestamp":"2024-04-25T11:13:47.351588","nav_name":"yuan_http","action":"事件处理出错","params":"错误跟踪：Traceback (most recent call last):\n  File \"xlink_core.pyx\", line 697, in xlink_core.Main4\n  File \"\/opt\/openfbi\/fbi-bin\/addones\/streams\/yuan_http.py\", line 422, in Events\n    \"account\": re_acc,\n               ^^^^^^\nUnboundLocalError: cannot access local variable 'user_info' where it is not associated with a value\n","operate_result":"错误","failed_reason":"cannot access local variable 'user_info' where it is not associated with a value"}
{"user":"x_finder3","timestamp":"2024-04-25T11:13:48.153272","nav_name":"yuan_http","action":"事件处理出错","params":"错误跟踪：Traceback (most recent call last):\n  File \"xlink_core.pyx\", line 697, in xlink_core.Main4\n  File \"\/opt\/openfbi\/fbi-bin\/addones\/streams\/yuan_http.py\", line 422, in Events\n    \"account\": re_acc,\n               ^^^^^^\nUnboundLocalError: cannot access local variable 'user_info' where it is not associated with a value\n","operate_result":"错误","failed_reason":"cannot access local variable 'user_info' where it is not associated with a value"}
{"user":"x_finder3","timestamp":"2024-04-25T11:13:48.154298","nav_name":"yuan_http","action":"事件处理出错","params":"错误跟踪：Traceback (most recent call last):\n  File \"xlink_core.pyx\", line 697, in xlink_core.Main4\n  File \"\/opt\/openfbi\/fbi-bin\/addones\/streams\/yuan_http.py\", line 422, in Events\n    \"account\": re_acc,\n               ^^^^^^\nUnboundLocalError: cannot access local variable 'user_info' where it is not associated with a value\n","operate_result":"错误","failed_reason":"cannot access local variable 'user_info' where it is not associated with a value"}
{"user":"x_finder3","timestamp":"2024-04-25T11:13:48.165344","nav_name":"yuan_http","action":"事件处理出错","params":"错误跟踪：Traceback (most recent call last):\n  File \"xlink_core.pyx\", line 697, in xlink_core.Main4\n  File \"\/opt\/openfbi\/fbi-bin\/addones\/streams\/yuan_http.py\", line 422, in Events\n    \"account\": re_acc,\n               ^^^^^^\nUnboundLocalError: cannot access local variable 'user_info' where it is not associated with a value\n","operate_result":"错误","failed_reason":"cannot access local variable 'user_info' where it is not associated with a value"}
{"user":"x_finder3","timestamp":"2024-04-25T11:13:48.206942","nav_name":"yuan_http","action":"事件处理出错","params":"错误跟踪：Traceback (most recent call last):\n  File \"xlink_core.pyx\", line 697, in xlink_core.Main4\n  File \"\/opt\/openfbi\/fbi-bin\/addones\/streams\/yuan_http.py\", line 422, in Events\n    \"account\": re_acc,\n               ^^^^^^\nUnboundLocalError: cannot access local variable 'user_info' where it is not associated with a value\n","operate_result":"错误","failed_reason":"cannot access local variable 'user_info' where it is not associated with a value"}
{"user":"x_finder3","timestamp":"2024-04-25T11:13:50.177514","nav_name":"yuan_http","action":"事件处理出错","params":"错误跟踪：Traceback (most recent call last):\n  File \"xlink_core.pyx\", line 697, in xlink_core.Main4\n  File \"\/opt\/openfbi\/fbi-bin\/addones\/streams\/yuan_http.py\", line 422, in Events\n    \"account\": re_acc,\n               ^^^^^^\nUnboundLocalError: cannot access local variable 'user_info' where it is not associated with a value\n","operate_result":"错误","failed_reason":"cannot access local variable 'user_info' where it is not associated with a value"}
{"user":"x_finder3","timestamp":"2024-04-25T11:13:50.178504","nav_name":"yuan_http","action":"事件处理出错","params":"错误跟踪：Traceback (most recent call last):\n  File \"xlink_core.pyx\", line 697, in xlink_core.Main4\n  File \"\/opt\/openfbi\/fbi-bin\/addones\/streams\/yuan_http.py\", line 422, in Events\n    \"account\": re_acc,\n               ^^^^^^\nUnboundLocalError: cannot access local variable 'user_info' where it is not associated with a value\n","operate_result":"错误","failed_reason":"cannot access local variable 'user_info' where it is not associated with a value"}
{"user":"x_finder3","timestamp":"2024-04-25T11:13:51.233140","nav_name":"yuan_http","action":"事件处理出错","params":"错误跟踪：Traceback (most recent call last):\n  File \"xlink_core.pyx\", line 697, in xlink_core.Main4\n  File \"\/opt\/openfbi\/fbi-bin\/addones\/streams\/yuan_http.py\", line 422, in Events\n    \"account\": re_acc,\n               ^^^^^^\nUnboundLocalError: cannot access local variable 'user_info' where it is not associated with a value\n","operate_result":"错误","failed_reason":"cannot access local variable 'user_info' where it is not associated with a value"}
{"user":"x_finder3","timestamp":"2024-04-25T11:13:51.335886","nav_name":"yuan_http","action":"事件处理出错","params":"错误跟踪：Traceback (most recent call last):\n  File \"xlink_core.pyx\", line 697, in xlink_core.Main4\n  File \"\/opt\/openfbi\/fbi-bin\/addones\/streams\/yuan_http.py\", line 422, in Events\n    \"account\": re_acc,\n               ^^^^^^\nUnboundLocalError: cannot access local variable 'user_info' where it is not associated with a value\n","operate_result":"错误","failed_reason":"cannot access local variable 'user_info' where it is not associated with a value"}
{"user":"x_finder3","timestamp":"2024-04-25T11:13:53.150773","nav_name":"yuan_http","action":"事件处理出错","params":"错误跟踪：Traceback (most recent call last):\n  File \"xlink_core.pyx\", line 697, in xlink_core.Main4\n  File \"\/opt\/openfbi\/fbi-bin\/addones\/streams\/yuan_http.py\", line 422, in Events\n    \"account\": re_acc,\n               ^^^^^^\nUnboundLocalError: cannot access local variable 'user_info' where it is not associated with a value\n","operate_result":"错误","failed_reason":"cannot access local variable 'user_info' where it is not associated with a value"}
{"user":"x_finder3","timestamp":"2024-04-25T11:13:53.151764","nav_name":"yuan_http","action":"事件处理出错","params":"错误跟踪：Traceback (most recent call last):\n  File \"xlink_core.pyx\", line 697, in xlink_core.Main4\n  File \"\/opt\/openfbi\/fbi-bin\/addones\/streams\/yuan_http.py\", line 422, in Events\n    \"account\": re_acc,\n               ^^^^^^\nUnboundLocalError: cannot access local variable 'user_info' where it is not associated with a value\n","operate_result":"错误","failed_reason":"cannot access local variable 'user_info' where it is not associated with a value"}
{"user":"x_finder3","timestamp":"2024-04-25T11:13:53.152667","nav_name":"yuan_http","action":"事件处理出错","params":"错误跟踪：Traceback (most recent call last):\n  File \"xlink_core.pyx\", line 697, in xlink_core.Main4\n  File \"\/opt\/openfbi\/fbi-bin\/addones\/streams\/yuan_http.py\", line 422, in Events\n    \"account\": re_acc,\n               ^^^^^^\nUnboundLocalError: cannot access local variable 'user_info' where it is not associated with a value\n","operate_result":"错误","failed_reason":"cannot access local variable 'user_info' where it is not associated with a value"}
{"user":"x_finder3","timestamp":"2024-04-25T11:13:54.258014","nav_name":"yuan_http","action":"事件处理出错","params":"错误跟踪：Traceback (most recent call last):\n  File \"xlink_core.pyx\", line 697, in xlink_core.Main4\n  File \"\/opt\/openfbi\/fbi-bin\/addones\/streams\/yuan_http.py\", line 422, in Events\n    \"account\": re_acc,\n               ^^^^^^\nUnboundLocalError: cannot access local variable 'user_info' where it is not associated with a value\n","operate_result":"错误","failed_reason":"cannot access local variable 'user_info' where it is not associated with a value"}
{"user":"x_finder3","timestamp":"2024-04-25T11:13:56.325528","nav_name":"yuan_http","action":"事件处理出错","params":"错误跟踪：Traceback (most recent call last):\n  File \"xlink_core.pyx\", line 697, in xlink_core.Main4\n  File \"\/opt\/openfbi\/fbi-bin\/addones\/streams\/yuan_http.py\", line 422, in Events\n    \"account\": re_acc,\n               ^^^^^^\nUnboundLocalError: cannot access local variable 'user_info' where it is not associated with a value\n","operate_result":"错误","failed_reason":"cannot access local variable 'user_info' where it is not associated with a value"}
{"user":"x_finder3","timestamp":"2024-04-25T11:13:57.288827","nav_name":"yuan_http","action":"事件处理出错","params":"错误跟踪：Traceback (most recent call last):\n  File \"xlink_core.pyx\", line 697, in xlink_core.Main4\n  File \"\/opt\/openfbi\/fbi-bin\/addones\/streams\/yuan_http.py\", line 422, in Events\n    \"account\": re_acc,\n               ^^^^^^\nUnboundLocalError: cannot access local variable 'user_info' where it is not associated with a value\n","operate_result":"错误","failed_reason":"cannot access local variable 'user_info' where it is not associated with a value"}
{"user":"x_finder3","timestamp":"2024-04-25T11:13:58.140934","nav_name":"yuan_http","action":"事件处理出错","params":"错误跟踪：Traceback (most recent call last):\n  File \"xlink_core.pyx\", line 697, in xlink_core.Main4\n  File \"\/opt\/openfbi\/fbi-bin\/addones\/streams\/yuan_http.py\", line 422, in Events\n    \"account\": re_acc,\n               ^^^^^^\nUnboundLocalError: cannot access local variable 'user_info' where it is not associated with a value\n","operate_result":"错误","failed_reason":"cannot access local variable 'user_info' where it is not associated with a value"}
{"user":"x_finder3","timestamp":"2024-04-25T11:13:58.141910","nav_name":"yuan_http","action":"事件处理出错","params":"错误跟踪：Traceback (most recent call last):\n  File \"xlink_core.pyx\", line 697, in xlink_core.Main4\n  File \"\/opt\/openfbi\/fbi-bin\/addones\/streams\/yuan_http.py\", line 422, in Events\n    \"account\": re_acc,\n               ^^^^^^\nUnboundLocalError: cannot access local variable 'user_info' where it is not associated with a value\n","operate_result":"错误","failed_reason":"cannot access local variable 'user_info' where it is not associated with a value"}
{"user":"x_finder3","timestamp":"2024-04-25T11:13:58.142813","nav_name":"yuan_http","action":"事件处理出错","params":"错误跟踪：Traceback (most recent call last):\n  File \"xlink_core.pyx\", line 697, in xlink_core.Main4\n  File \"\/opt\/openfbi\/fbi-bin\/addones\/streams\/yuan_http.py\", line 422, in Events\n    \"account\": re_acc,\n               ^^^^^^\nUnboundLocalError: cannot access local variable 'user_info' where it is not associated with a value\n","operate_result":"错误","failed_reason":"cannot access local variable 'user_info' where it is not associated with a value"}
{"user":"x_finder3","timestamp":"2024-04-25T11:13:58.894578","nav_name":"yuan_http","action":"事件处理出错","params":"错误跟踪：Traceback (most recent call last):\n  File \"xlink_core.pyx\", line 697, in xlink_core.Main4\n  File \"\/opt\/openfbi\/fbi-bin\/addones\/streams\/yuan_http.py\", line 422, in Events\n    \"parameter\": parameter,\n               ^^^^^^\nUnboundLocalError: cannot access local variable 'user_info' where it is not associated with a value\n","operate_result":"错误","failed_reason":"cannot access local variable 'user_info' where it is not associated with a value"}
{"user":"x_finder3","timestamp":"2024-04-25T11:14:00.060919","nav_name":"yuan_http","action":"事件处理出错","params":"错误跟踪：Traceback (most recent call last):\n  File \"xlink_core.pyx\", line 697, in xlink_core.Main4\n  File \"\/opt\/openfbi\/fbi-bin\/addones\/streams\/yuan_http.py\", line 422, in Events\n    \"parameter\": parameter,\n               ^^^^^^\nUnboundLocalError: cannot access local variable 'user_info' where it is not associated with a value\n","operate_result":"错误","failed_reason":"cannot access local variable 'user_info' where it is not associated with a value"}
{"user":"x_finder3","timestamp":"2024-04-25T11:14:00.061921","nav_name":"yuan_http","action":"事件处理出错","params":"错误跟踪：Traceback (most recent call last):\n  File \"xlink_core.pyx\", line 697, in xlink_core.Main4\n  File \"\/opt\/openfbi\/fbi-bin\/addones\/streams\/yuan_http.py\", line 422, in Events\n    \"parameter\": parameter,\n               ^^^^^^\nUnboundLocalError: cannot access local variable 'user_info' where it is not associated with a value\n","operate_result":"错误","failed_reason":"cannot access local variable 'user_info' where it is not associated with a value"}
{"user":"x_finder3","timestamp":"2024-04-25T11:14:00.195528","nav_name":"yuan_http","action":"事件处理出错","params":"错误跟踪：Traceback (most recent call last):\n  File \"xlink_core.pyx\", line 697, in xlink_core.Main4\n  File \"\/opt\/openfbi\/fbi-bin\/addones\/streams\/yuan_http.py\", line 422, in Events\n    \"parameter\": parameter,\n               ^^^^^^\nUnboundLocalError: cannot access local variable 'user_info' where it is not associated with a value\n","operate_result":"错误","failed_reason":"cannot access local variable 'user_info' where it is not associated with a value"}
{"user":"x_finder3","timestamp":"2024-04-25T11:14:00.296015","nav_name":"yuan_http","action":"事件处理出错","params":"错误跟踪：Traceback (most recent call last):\n  File \"xlink_core.pyx\", line 697, in xlink_core.Main4\n  File \"\/opt\/openfbi\/fbi-bin\/addones\/streams\/yuan_http.py\", line 422, in Events\n    \"parameter\": parameter,\n               ^^^^^^\nUnboundLocalError: cannot access local variable 'user_info' where it is not associated with a value\n","operate_result":"错误","failed_reason":"cannot access local variable 'user_info' where it is not associated with a value"}
{"user":"x_finder3","timestamp":"2024-04-25T11:14:01.351447","nav_name":"yuan_http","action":"事件处理出错","params":"错误跟踪：Traceback (most recent call last):\n  File \"xlink_core.pyx\", line 697, in xlink_core.Main4\n  File \"\/opt\/openfbi\/fbi-bin\/addones\/streams\/yuan_http.py\", line 422, in Events\n    \"parameter\": parameter,\n               ^^^^^^\nUnboundLocalError: cannot access local variable 'user_info' where it is not associated with a value\n","operate_result":"错误","failed_reason":"cannot access local variable 'user_info' where it is not associated with a value"}
{"user":"x_finder3","timestamp":"2024-04-25T11:14:02.298933","nav_name":"yuan_http","action":"退出","params":"收到退出消息!","operate_result":"信息","failed_reason":""}
{"user":"x_finder3","timestamp":"2024-04-25T11:14:02.304299","nav_name":"yuan_http","action":"停止","params":"退出消息循环,一阶段结束!","operate_result":"信息","failed_reason":""}
{"user":"x_finder3","timestamp":"2024-04-25T11:14:02.304404","nav_name":"yuan_http","action":"停止","params":"二阶段开始停止!","operate_result":"信息","failed_reason":""}
{"user":"x_finder3","timestamp":"2024-04-25T11:14:02.304467","nav_name":"yuan_http","action":"停止","params":"三阶段开始停止!","operate_result":"信息","failed_reason":""}
{"user":"x_finder3","timestamp":"2024-04-25T11:14:02.509615","nav_name":"yuan_http","action":"停止","params":"系统定时任务st_10s停止完毕!","operate_result":"信息","failed_reason":""}
{"user":"x_finder3","timestamp":"2024-04-25T11:14:02.509827","nav_name":"yuan_http","action":"停止","params":"系统定时任务st_60s停止完毕!","operate_result":"信息","failed_reason":""}
{"user":"x_finder3","timestamp":"2024-04-25T11:14:07.974891","nav_name":"yuan_http","action":"监控程序","params":"printf::收到消息退出","operate_result":"信息","failed_reason":""}
{"user":"x_finder3","timestamp":"2024-04-25T11:14:07.975269","nav_name":"yuan_http","action":"停止","params":"全部停止完毕!","operate_result":"信息","failed_reason":""}
{"user":"x_finder3","timestamp":"2024-04-25T11:14:15.215394","nav_name":"yuan_http","action":"启动参数","params":"unix_udp: \/tmp\/yuan_http,","operate_result":"信息","failed_reason":""}
{"user":"x_finder3","timestamp":"2024-04-25T11:14:15.221266","nav_name":"yuan_http","action":"组件启动","params":"开始验证授权....","operate_result":"信息","failed_reason":""}
{"user":"x_finder3","timestamp":"2024-04-25T11:14:15.221645","nav_name":"yuan_http","action":"组件启动","params":"授权验证完成!","operate_result":"信息","failed_reason":""}
{"user":"x_finder3","timestamp":"2024-04-25T11:14:15.222544","nav_name":"yuan_http","action":"组件启动","params":"数据窗口函数-0, 定时任务函数-1","operate_result":"信息","failed_reason":""}
{"user":"x_finder3","timestamp":"2024-04-25T11:14:15.222699","nav_name":"yuan_http","action":"事件主循环","params":"Unix_UDP 建立中","operate_result":"信息","failed_reason":""}
{"user":"x_finder3","timestamp":"2024-04-25T11:14:15.222865","nav_name":"yuan_http","action":"启动完成","params":"Unix_UDP 准备完毕,开始接收消息!","operate_result":"信息","failed_reason":""}
{"user":"x_finder3","timestamp":"2024-04-25T11:16:49.111619","nav_name":"yuan_http","action":"启动参数","params":"unix_udp: \/tmp\/yuan_http,","operate_result":"信息","failed_reason":""}
{"user":"x_finder3","timestamp":"2024-04-25T11:16:49.129138","nav_name":"yuan_http","action":"组件启动","params":"开始验证授权....","operate_result":"信息","failed_reason":""}
{"user":"x_finder3","timestamp":"2024-04-25T11:16:49.129562","nav_name":"yuan_http","action":"组件启动","params":"授权验证完成!","operate_result":"信息","failed_reason":""}
{"user":"x_finder3","timestamp":"2024-04-25T11:16:49.130997","nav_name":"yuan_http","action":"组件启动","params":"数据窗口函数-0, 定时任务函数-1","operate_result":"信息","failed_reason":""}
{"user":"x_finder3","timestamp":"2024-04-25T11:16:49.131246","nav_name":"yuan_http","action":"事件主循环","params":"Unix_UDP 建立中","operate_result":"信息","failed_reason":""}
{"user":"x_finder3","timestamp":"2024-04-25T11:16:49.131443","nav_name":"yuan_http","action":"启动完成","params":"Unix_UDP 准备完毕,开始接收消息!","operate_result":"信息","failed_reason":""}
{"user":"x_finder3","timestamp":"2024-04-25T11:25:59.389750","nav_name":"yuan_http","action":"启动参数","params":"unix_udp: \/tmp\/yuan_http,","operate_result":"信息","failed_reason":""}
{"user":"x_finder3","timestamp":"2024-04-25T11:25:59.399300","nav_name":"yuan_http","action":"组件启动","params":"开始验证授权....","operate_result":"信息","failed_reason":""}
{"user":"x_finder3","timestamp":"2024-04-25T11:25:59.399675","nav_name":"yuan_http","action":"组件启动","params":"授权验证完成!","operate_result":"信息","failed_reason":""}
{"user":"x_finder3","timestamp":"2024-04-25T11:25:59.400584","nav_name":"yuan_http","action":"组件启动","params":"数据窗口函数-0, 定时任务函数-1","operate_result":"信息","failed_reason":""}
{"user":"x_finder3","timestamp":"2024-04-25T11:25:59.400741","nav_name":"yuan_http","action":"事件主循环","params":"Unix_UDP 建立中","operate_result":"信息","failed_reason":""}
{"user":"x_finder3","timestamp":"2024-04-25T11:25:59.400882","nav_name":"yuan_http","action":"启动完成","params":"Unix_UDP 准备完毕,开始接收消息!","operate_result":"信息","failed_reason":""}
{"user":"x_finder3","timestamp":"2024-04-25T11:28:38.918184","nav_name":"yuan_http","action":"启动参数","params":"unix_udp: \/tmp\/yuan_http,","operate_result":"信息","failed_reason":""}
{"user":"x_finder3","timestamp":"2024-04-25T11:28:38.923098","nav_name":"yuan_http","action":"组件启动","params":"开始验证授权....","operate_result":"信息","failed_reason":""}
{"user":"x_finder3","timestamp":"2024-04-25T11:28:38.923442","nav_name":"yuan_http","action":"组件启动","params":"授权验证完成!","operate_result":"信息","failed_reason":""}
{"user":"x_finder3","timestamp":"2024-04-25T11:28:38.924232","nav_name":"yuan_http","action":"组件启动","params":"数据窗口函数-0, 定时任务函数-1","operate_result":"信息","failed_reason":""}
{"user":"x_finder3","timestamp":"2024-04-25T11:28:38.924373","nav_name":"yuan_http","action":"事件主循环","params":"Unix_UDP 建立中","operate_result":"信息","failed_reason":""}
{"user":"x_finder3","timestamp":"2024-04-25T11:28:38.924514","nav_name":"yuan_http","action":"启动完成","params":"Unix_UDP 准备完毕,开始接收消息!","operate_result":"信息","failed_reason":""}
